Workbook

Sheet Referring domains - no comparis
A1: Domain | B1: Is spam | C1: DR | D1: Dofollow ref. domains | E1: Dofollow linked domains | F1: Traffic | G1: Keywords | H1: Links to target | I1: Dofollow links | J1: First seen | K1: Lost
A2: bbb.org | B2: FALSE | C2: 93 | D2: 193230 | E2: 9960 | F2: 3593412 | G2: 741789 | H2: 1 | I2: 0 | J2: 45935.997
A3: datanyze.com | B3: FALSE | C3: 77 | D3: 10024 | E3: 501 | F3: 21143 | G3: 14707 | H3: 1 | I3: 0 | J3: 46226.396
A4: theorg.com | B4: FALSE | C4: 76 | D4: 13594 | E4: 820541 | F4: 98474 | G4: 73166 | H4: 1 | I4: 1 | J4: 46191.94
A5: rankyour.website | B5: TRUE | C5: 74 | D5: 165 | E5: 998 | F5: 0 | G5: 0 | H5: 1 | I5: 0 | J5: 46136.746
A6: factmags.com | B6: TRUE | C6: 74 | D6: 5194 | E6: 41279165 | F6: 0 | G6: 0 | H6: 1 | I6: 0 | J6: 46156.271
A7: buybacklinks.agency | B7: TRUE | C7: 71 | D7: 423 | E7: 998 | F7: 0 | G7: 0 | H7: 1 | I7: 0 | J7: 46108.468
A8: backlinker.shop | B8: TRUE | C8: 61 | D8: 553 | E8: 0 | F8: 0 | G8: 0 | H8: 1 | I8: 0 | J8: 45947.861
A9: rank-top.click | B9: TRUE | C9: 60 | D9: 145 | E9: 998 | F9: 0 | G9: 0 | H9: 1 | I9: 0 | J9: 46145.956
A10: linkrankpro.shop | B10: TRUE | C10: 54 | D10: 166 | E10: 998 | F10: 0 | G10: 0 | H10: 1 | I10: 0 | J10: 46149.883
A11: rankxlinks.shop | B11: TRUE | C11: 54 | D11: 119 | E11: 998 | F11: 0 | G11: 0 | H11: 1 | I11: 0 | J11: 46146.089
A12: ranklinkerpro.shop | B12: TRUE | C12: 54 | D12: 115 | E12: 2 | F12: 0 | G12: 0 | H12: 1 | I12: 0 | J12: 46148.835
A13: seorankflow.shop | B13: TRUE | C13: 54 | D13: 107 | E13: 2 | F13: 0 | G13: 0 | H13: 1 | I13: 0 | J13: 46195.999
... A165: siterankservice.shop | B165: TRUE | C165: 0 | D165: 0 | E165: 0 | F165: 0 | G165: 0 | H165: 1 | I165: 0 | J165: 46227.747

Sheet Referring domains - vs 6 months
A1: Domain | B1: Is spam | C1: DR | D1: Dofollow ref. domains | E1: Dofollow linked domains | F1: Traffic | G1: Keywords | H1: Links to target | I1: New links | J1: Lost links | K1: Dofollow links | L1: First seen | M1: Lost
A2: bbb.org | B2: FALSE | C2: 93 | D2: 193230 | E2: 9960 | F2: 3593412 | G2: 741789 | H2: 1 | I2: 0 | J2: 0 | K2: 0 | L2: 45935.997
A3: datanyze.com | B3: FALSE | C3: 77 | D3: 10024 | E3: 501 | F3: 21143 | G3: 14707 | H3: 1 | I3: 1 | J3: 0 | K3: 0 | L3: 46226.396
A4: theorg.com | B4: FALSE | C4: 76 | D4: 13594 | E4: 820541 | F4: 98474 | G4: 73166 | H4: 1 | I4: 1 | J4: 0 | K4: 1 | L4: 46191.94
A5: rankyour.website | B5: TRUE | C5: 74 | D5: 165 | E5: 998 | F5: 0 | G5: 0 | H5: 1 | I5: 1 | J5: 0 | K5: 0 | L5: 46136.746
A6: factmags.com | B6: TRUE | C6: 74 | D6: 5194 | E6: 41279165 | F6: 0 | G6: 0 | H6: 1 | I6: 1 | J6: 0 | K6: 0 | L6: 46156.271
A7: buybacklinks.agency | B7: TRUE | C7: 71 | D7: 423 | E7: 998 | F7: 0 | G7: 0 | H7: 1 | I7: 1 | J7: 0 | K7: 0 | L7: 46108.468
A8: seoexpress.org | B8: TRUE | C8: 66 | D8: 1303 | E8: 6 | F8: 0 | G8: 0 | H8: 1 | I8: 1 | J8: 1 | K8: 0 | L8: 46115.94 | M8: 46121.354
A9: backlinker.shop | B9: TRUE | C9: 61 | D9: 553 | E9: 0 | F9: 0 | G9: 0 | H9: 1 | I9: 0 | J9: 0 | K9: 0 | L9: 45947.861
A10: rank-top.click | B10: TRUE | C10: 60 | D10: 145 | E10: 998 | F10: 0 | G10: 0 | H10: 1 | I10: 1 | J10: 0 | K10: 0 | L10: 46145.956
A11: linkrankpro.shop | B11: TRUE | C11: 54 | D11: 166 | E11: 998 | F11: 0 | G11: 0 | H11: 1 | I11: 1 | J11: 0 | K11: 0 | L11: 46149.883
A12: rankxlinks.shop | B12: TRUE | C12: 54 | D12: 119 | E12: 998 | F12: 0 | G12: 0 | H12: 1 | I12: 1 | J12: 0 | K12: 0 | L12: 46146.089
A13: ranklinkerpro.shop | B13: TRUE | C13: 54 | D13: 115 | E13: 2 | F13: 0 | G13: 0 | H13: 1 | I13: 1 | J13: 0 | K13: 0 | L13: 46148.835
A14: seorankflow.shop | B14: TRUE | C14: 54 | D14: 107 | E14: 2 | F14: 0 | G14: 0 | H14: 1 | I14: 1 | J14: 0 | K14: 0 | L14: 46195.999
A15: authoritybacklinks.shop | B15: TRUE | C15: 54 | D15: 136 | E15: 998 | F15: 0 | G15: 0 | H15: 1 | I15: 1 | J15: 0 | K15: 0 | L15: 46152.204
A16: pbnseolinks.shop | B16: TRUE | C16: 53 | D16: 246 | E16: 998 | F16: 0 | G16: 0 | H16: 1 | I16: 1 | J16: 0 | K16: 0 | L16: 46149.681
A17: linkrankboost.shop | B17: TRUE | C17: 53 | D17: 153 | E17: 999 | F17: 0 | G17: 0 | H17: 1 | I17: 1 | J17: 0 | K17: 0 | L17: 46152.74
A18: linkseopro.shop | B18: TRUE | C18: 53 | D18: 213 | E18: 998 | F18: 0 | G18: 0 | H18: 1 | I18: 1 | J18: 0 | K18: 0 | L18: 46151.281
A19: ranklinkpro.shop | B19: TRUE | C19: 53 | D19: 143 | E19: 998 | F19: 0 | G19: 0 | H19: 1 | I19: 1 | J19: 0 | K19: 0 | L19: 46158.635
A20: seolinkpro.shop | B20: TRUE | C20: 53 | D20: 138 | E20: 998 | F20: 0 | G20: 0 | H20: 1 | I20: 1 | J20: 0 | K20: 0 | L20: 46153.73
... A22: toplinkranker.shop | B22: TRUE | C22: 53 | D22: 134 | E22: 998 | F22: 0 | G22: 0 | H22: 1 | I22: 1 | J22: 0 | K22: 0 | L22: 46153.742
A23: exlinko.net | B23: TRUE | C23: 50 | D23: 1762 | E23: 0 | F23: 0 | G23: 0 | H23: 1 | I23: 0 | J23: 1 | K23: 0 | L23: 45715.483 | M23: 46110.167
A24: bye.fyi | B24: FALSE | C24: 49 | D24: 871 | E24: 18 | F24: 33 | G24: 3 | H24: 1 | I24: 0 | J24: 1 | K24: 0 | L24: 46033.845 | M24: 46072.777
A25: quero.party | B25: FALSE | C25: 49 | D25: 478 | E25: 18 | F25: 0 | G25: 0 | H25: 1 | I25: 1 | J25: 1 | K25: 0 | L25: 46068.942 | M25: 46133.174
A26: thebestbacklinksavailable.click | B26: TRUE | C26: 47 | D26: 159 | E26: 0 | F26: 0 | G26: 0 | H26: 1 | I26: 0 | J26: 1 | K26: 1 | L26: 45860.377 | M26: 46105.946
A27: trafficspike.shop | B27: TRUE | C27: 47 | D27: 78 | E27: 0 | F27: 0 | G27: 0 | H27: 2 | I27: 2 | J27: 1 | K27: 0 | L27: 46189.378
A28: dsnylu.com | B28: TRUE | C28: 46 | D28: 1482 | E28: 5 | F28: 0 | G28: 0 | H28: 1 | I28: 0 | J28: 1 | K28: 1 | L28: 46034.466 | M28: 46094.987
A29: creativeposts.top | B29: FALSE | C29: 45 | D29: 192 | E29: 18 | F29: 0 | G29: 0 | H29: 1 | I29: 1 | J29: 0 | K29: 0 | L29: 46075.169
A30: sport-life.club | B30: TRUE | C30: 44 | D30: 1189 | E30: 9200 | F30: 0 | G30: 0 | H30: 1 | I30: 0 | J30: 1 | K30: 1 | L30: 46012.129 | M30: 46100.071
A31: byteshort.xyz | B31: FALSE | C31: 44 | D31: 182 | E31: 18 | F31: 0 | G31: 0 | H31: 1 | I31: 1 | J31: 0 | K31: 0 | L31: 46111.043
A32: atomizelink.icu | B32: FALSE | C32: 43 | D32: 547 | E32: 18 | F32: 0 | G32: 0 | H32: 2 | I32: 1 | J32: 0 | K32: 0 | L32: 46018.703
A33: metamagic.top | B33: FALSE | C33: 42 | D33: 123 | E33: 18 | F33: 0 | G33: 0 | H33: 1 | I33: 1 | J33: 0 | K33: 0 | L33: 46066.139
A34: analyticshaven.top | B34: FALSE | C34: 42 | D34: 183 | E34: 18 | F34: 0 | G34: 0 | H34: 1 | I34: 1 | J34: 1 | K34: 0 | L34: 46078.456 | M34: 46131.65
A35: screenshots.wiki | B35: TRUE | C35: 41 | D35: 166 | E35: 18 | F35: 0 | G35: 0 | H35: 2 | I35: 2 | J35: 1 | K35: 0 | L35: 46057.079
A36: seo-high-ranking.shop | B36: TRUE | C36: 41 | D36: 1447 | E36: 237 | F36: 0 | G36: 0 | H36: 1 | I36: 1 | J36: 1 | K36: 0 | L36: 46131.121 | M36: 46163.115
A37: optimizeflow.top | B37: FALSE | C37: 41 | D37: 239 | E37: 18 | F37: 0 | G37: 0 | H37: 2 | I37: 2 | J37: 0 | K37: 0 | L37: 46058.975
A38: ageddomainsforeverytaste.club | B38: TRUE | C38: 40 | D38: 129 | E38: 0 | F38: 0 | G38: 0 | H38: 1 | I38: 0 | J38: 1 | K38: 1 | L38: 45814.874 | M38: 46064.561
A39: jake.eu | B39: FALSE | C39: 40 | D39: 178 | E39: 1275 | F39: 0 | G39: 0 | H39: 1 | I39: 0 | J39: 1 | K39: 0 | L39: 46024.268 | M39: 46133.548
A40: hzdlpq.com | B40: TRUE | C40: 36 | D40: 1584 | E40: 18118 | F40: 0 | G40: 0 | H40: 1 | I40: 0 | J40: 1 | K40: 1 | L40: 46034.387 | M40: 46092.908
A41: kgzxkf.com | B41: TRUE | C41: 36 | D41: 1375 | E41: 5 | F41: 0 | G41: 0 | H41: 1 | I41: 0 | J41: 1 | K41: 1 | L41: 46029.936 | M41: 46088.257
...

Sheet New referring domains last 30 d
A1: Domain | B1: Is spam | C1: DR | D1: Dofollow ref. domains | E1: Dofollow linked domains | F1: Traffic | G1: Keywords | H1: Links to target | I1: Dofollow links | J1: First seen | K1: Lost
A2: datanyze.com | B2: FALSE | C2: 77 | D2: 10024 | E2: 501 | F2: 21143 | G2: 14707 | H2: 1 | I2: 0 | J2: 46226.396
A3: seolinkkart.shop | B3: TRUE | C3: 0.8 | D3: 68 | E3: 0 | F3: 0 | G3: 0 | H3: 1 | I3: 0 | J3: 46204.354
A4: rankdeals.shop | B4: TRUE | C4: 0.8 | D4: 68 | E4: 0 | F4: 0 | G4: 0 | H4: 1 | I4: 0 | J4: 46206.348
A5: seomart.shop | B5: TRUE | C5: 0.8 | D5: 68 | E5: 0 | F5: 0 | G5: 0 | H5: 1 | I5: 0 | J5: 46204.92
A6: seowarez.shop | B6: TRUE | C6: 0.7 | D6: 49 | E6: 0 | F6: 0 | G6: 0 | H6: 1 | I6: 0 | J6: 46204.364
A7: guestpostlinks.shop | B7: TRUE | C7: 0.7 | D7: 49 | E7: 0 | F7: 0 | G7: 0 | H7: 1 | I7: 0 | J7: 46213.325
A8: nexabacklinks.shop | B8: TRUE | C8: 0.7 | D8: 49 | E8: 0 | F8: 0 | G8: 0 | H8: 1 | I8: 0 | J8: 46203.126
A9: seoloot.shop | B9: TRUE | C9: 0.7 | D9: 49 | E9: 0 | F9: 0 | G9: 0 | H9: 1 | I9: 0 | J9: 46206.507
A10: seogear.shop | B10: TRUE | C10: 0.7 | D10: 49 | E10: 0 | F10: 0 | G10: 0 | H10: 1 | I10: 0 | J10: 46207.281
A11: seoprime.shop | B11: TRUE | C11: 0.7 | D11: 49 | E11: 0 | F11: 0 | G11: 0 | H11: 1 | I11: 0 | J11: 46205.846
A12: rankwares.shop | B12: TRUE | C12: 0.7 | D12: 49 | E12: 0 | F12: 0 | G12: 0 | H12: 1 | I12: 0 | J12: 46203.144
A13: rankcart.shop | B13: TRUE | C13: 0.7 | D13: 49 | E13: 0 | F13: 0 | G13: 0 | H13: 1 | I13: 0 | J13: 46206.309
... A76: siterankservice.shop | B76: TRUE | C76: 0 | D76: 0 | E76: 0 | F76: 0 | G76: 0 | H76: 1 | I76: 0 | J76: 46227.747

Sheet Cost of backlinks (with low tra
A1: DR range | B1: value per backlink | C1: min (not inclusive) | D1: max (not inclusive) | E1: total backlinks (wrong) | F1: with low traffic: | G1: referring domains | H1: backlinks | I1: value | J1: without low traffic: | K1: referring domains | L1: backlinks | M1: value | P1: =A2 -> 70-100 | Q1: =A3 -> 40-70 | R1: =A4 -> 30-40 | S1: =A5 -> 10-30 | T1: =A6 -> 0-10
A2: 70-100 | B2: 750 | C2: 69 | D2: 101 | E2: =sumifs('Referring domains - no comparis'!$D:$D, 'Referring domains - no comparis'!B:B,"<"&D2, 'Referring domains - no comparis'!B:B,">"&C2, 'Referring domains - no comparis'!K:K,">1000") -> 0 | G2: {=COUNTIFS( INDIRECT("'Referring domains'!"&SUBSTITUTE(ADDRESS(1,MATCH("DR",'Referring domains - no comparis'!$A$1:$M$1,0),4),1,"")&":"&SUBSTITUTE(ADDRESS(1,MATCH("DR",'Referring domains - no comparis'!$A$1:$M$1,0),4),1,"")),"<"&D2, INDIRECT("'Referring domains'!"&SUBSTITUTE(ADDRESS(1,MATCH("DR",'Referring domains - no comparis'!$A$1:$M$1,0),4),1,"")&":"&SUBSTITUTE(ADDRESS(1,MATCH("DR",'Referring domains - no comparis'!$A$1:$M$1,0),4),1,"")),">"&C2 )} -> 0 | H2: {=sumifs(INDIRECT("'Referring domains'!"&SUBSTITUTE(ADDRESS(1,MATCH("Links to target",'Referring domains - no comparis'!$A$1:$M$1,0),4),1,"")&":"&SUBSTITUTE(ADDRESS(1,MATCH("Links to target",'Referring domains - no comparis'!$A$1:$M$1,0),4),1,"")), INDIRECT("'Referring domains'!"&SUBSTITUTE(ADDRESS(1,MATCH("DR",'Referring domains - no comparis'!$A$1:$M$1,0),4),1,"")&":"&SUBSTITUTE(ADDRESS(1,MATCH("DR",'Referring domains - no comparis'!$A$1:$M$1,0),4),1,"")),"<"&D2, INDIRECT("'Referring domains'!"&SUBSTITUTE(ADDRESS(1,MATCH("DR",'Referring domains - no comparis'!$A$1:$M$1,0),4),1,"")&":"&SUBSTITUTE(ADDRESS(1,MATCH("DR",'Referring domains - no comparis'!$A$1:$M$1,0),4),1,"")),">"&C2)} -> #N/A | I2: =H2*B2 -> #N/A | K2: {=COUNTIFS( INDIRECT("'Referring domains'!"&SUBSTITUTE(ADDRESS(1,MATCH("Domain Rating (desc)",'Referring domains - no comparis'!$A$1:$M$1,0),4),1,"")&":"&SUBSTITUTE(ADDRESS(1,MATCH("Domain Rating (desc)",'Referring domains - no comparis'!$A$1:$M$1,0),4),1,"")),"<"&D2, INDIRECT("'Referring domains'!"&SUBSTITUTE(ADDRESS(1,MATCH("Domain Rating (desc)",'Referring domains - no comparis'!$A$1:$M$1,0),4),1,"")&":"&SUBSTITUTE(ADDRESS(1,MATCH("Domain Rating (desc)",'Referring domains - no comparis'!$A$1:$M$1,0),4),1,"")),">"&C2, INDIRECT("'Referring domains'!"&SUBSTITUTE(ADDRESS(1,MATCH("Organic Traffic",'Referring domains - no comparis'!$A$1:$M$1,0),4),1,"")&":"&SUBSTITUTE(ADDRESS(1,MATCH("Organic Traffic",'Referring domains - no comparis'!$A$1:$M$1,0),4),1,"")),">1000" )} -> 0 | L2: {=sumifs(INDIRECT("'Referring domains'!"&SUBSTITUTE(ADDRESS(1,MATCH("Total Backlinks",'Referring domains - no comparis'!$A$1:$M$1,0),4),1,"")&":"&SUBSTITUTE(ADDRESS(1,MATCH("Total Backlinks",'Referring domains - no comparis'!$A$1:$M$1,0),4),1,"")), INDIRECT("'Referring domains'!"&SUBSTITUTE(ADDRESS(1,MATCH("Domain Rating (desc)",'Referring domains - no comparis'!$A$1:$M$1,0),4),1,"")&":"&SUBSTITUTE(ADDRESS(1,MATCH("Domain Rating (desc)",'Referring domains - no comparis'!$A$1:$M$1,0),4),1,"")),"<"&D2, INDIRECT("'Referring domains'!"&SUBSTITUTE(ADDRESS(1,MATCH("Domain Rating (desc)",'Referring domains - no comparis'!$A$1:$M$1,0),4),1,"")&":"&SUBSTITUTE(ADDRESS(1,MATCH("Domain Rating (desc)",'Referring domains - no comparis'!$A$1:$M$1,0),4),1,"")),">"&C2, INDIRECT("'Referring domains'!"&SUBSTITUTE(ADDRESS(1,MATCH("Organic Traffic",'Referring domains - no comparis'!$A$1:$M$1,0),4),1,"")&":"&SUBSTITUTE(ADDRESS(1,MATCH("Organic Traffic",'Referring domains - no comparis'!$A$1:$M$1,0),4),1,"")),">1000")} -> #N/A | M2: =L2*B2 -> #N/A | P2: =IFERROR(__xludf.DUMMYFUNCTION("FILTER('Referring domains - no comparis'!$A$2:$A787, 'Referring domains - no comparis'!$B$2:$B787<101, 'Referring domains - no comparis'!$B$2:$B787>69, 'Referring domains - no comparis'!$K$1:$K787>$G$13)"),"#N/A") -> #N/A | Q2: =IFERROR(__xludf.DUMMYFUNCTION("FILTER('Referring domains - no comparis'!$A$2:$A787, 'Referring domains - no comparis'!$B$2:$B787<70, 'Referring domains - no comparis'!$B$2:$B787>39, 'Referring domains - no comparis'!$E$2:$E787>$G$13)"),"#N/A") -> #N/A | R2: =IFERROR(__xludf.DUMMYFUNCTION("FILTER('Referring domains - no comparis'!$A$2:$A787, 'Referring domains - no comparis'!$B$2:$B787<40, 'Referring domains - no comparis'!$B$2:$B787>29, 'Referring domains - no comparis'!$K$1:$K787>$G$13)"),"#N/A") -> #N/A | S2: =IFERROR(__xludf.DUMMYFUNCTION("FILTER('Referring domains - no comparis'!$A$2:$A787, 'Referring domains - no comparis'!$B$2:$B787<30, 'Referring domains - no comparis'!$B$2:$B787>9, 'Referring domains - no comparis'!$K$1:$K787>$G$13)"),"#N/A") -> #N/A | T2: =IFERROR(__xludf.DUMMYFUNCTION("FILTER('Referring domains - no comparis'!$A$2:$A787, 'Referring domains - no comparis'!$B$2:$B787<10, 'Referring domains - no comparis'!$B$2:$B787>-1, 'Referring domains - no comparis'!$K$1:$K787>$G$13)"),"#N/A") -> #N/A
A3: 40-70 | B3: 300 | C3: 39 | D3: 70 | E3: =sumifs('Referring domains - no comparis'!$D:$D,'Referring domains - no comparis'!B:B,"<"&D3,'Referring domains - no comparis'!B:B,">"&C3,'Referring domains - no comparis'!K:K,">1000") -> 0 | G3: {=COUNTIFS( INDIRECT("'Referring domains'!"&SUBSTITUTE(ADDRESS(1,MATCH("DR",'Referring domains - no comparis'!$A$1:$M$1,0),4),1,"")&":"&SUBSTITUTE(ADDRESS(1,MATCH("DR",'Referring domains - no comparis'!$A$1:$M$1,0),4),1,"")),"<"&D3, INDIRECT("'Referring domains'!"&SUBSTITUTE(ADDRESS(1,MATCH("DR",'Referring domains - no comparis'!$A$1:$M$1,0),4),1,"")&":"&SUBSTITUTE(ADDRESS(1,MATCH("DR",'Referring domains - no comparis'!$A$1:$M$1,0),4),1,"")),">"&C3 )} -> 0 | H3: {=sumifs(INDIRECT("'Referring domains'!"&SUBSTITUTE(ADDRESS(1,MATCH("Links to target",'Referring domains - no comparis'!$A$1:$M$1,0),4),1,"")&":"&SUBSTITUTE(ADDRESS(1,MATCH("Links to target",'Referring domains - no comparis'!$A$1:$M$1,0),4),1,"")), INDIRECT("'Referring domains'!"&SUBSTITUTE(ADDRESS(1,MATCH("DR",'Referring domains - no comparis'!$A$1:$M$1,0),4),1,"")&":"&SUBSTITUTE(ADDRESS(1,MATCH("DR",'Referring domains - no comparis'!$A$1:$M$1,0),4),1,"")),"<"&D3, INDIRECT("'Referring domains'!"&SUBSTITUTE(ADDRESS(1,MATCH("DR",'Referring domains - no comparis'!$A$1:$M$1,0),4),1,"")&":"&SUBSTITUTE(ADDRESS(1,MATCH("DR",'Referring domains - no comparis'!$A$1:$M$1,0),4),1,"")),">"&C3)} -> #N/A | I3: =H3*B3 -> #N/A | K3: {=COUNTIFS( INDIRECT("'Referring domains'!"&SUBSTITUTE(ADDRESS(1,MATCH("Domain Rating (desc)",'Referring domains - no comparis'!$A$1:$M$1,0),4),1,"")&":"&SUBSTITUTE(ADDRESS(1,MATCH("Domain Rating (desc)",'Referring domains - no comparis'!$A$1:$M$1,0),4),1,"")),"<"&D3, INDIRECT("'Referring domains'!"&SUBSTITUTE(ADDRESS(1,MATCH("Domain Rating (desc)",'Referring domains - no comparis'!$A$1:$M$1,0),4),1,"")&":"&SUBSTITUTE(ADDRESS(1,MATCH("Domain Rating (desc)",'Referring domains - no comparis'!$A$1:$M$1,0),4),1,"")),">"&C3, INDIRECT("'Referring domains'!"&SUBSTITUTE(ADDRESS(1,MATCH("Organic Traffic",'Referring domains - no comparis'!$A$1:$M$1,0),4),1,"")&":"&SUBSTITUTE(ADDRESS(1,MATCH("Organic Traffic",'Referring domains - no comparis'!$A$1:$M$1,0),4),1,"")),">1000" )} -> 0 | L3: {=sumifs(INDIRECT("'Referring domains'!"&SUBSTITUTE(ADDRESS(1,MATCH("Total Backlinks",'Referring domains - no comparis'!$A$1:$M$1,0),4),1,"")&":"&SUBSTITUTE(ADDRESS(1,MATCH("Total Backlinks",'Referring domains - no comparis'!$A$1:$M$1,0),4),1,"")), INDIRECT("'Referring domains'!"&SUBSTITUTE(ADDRESS(1,MATCH("Domain Rating (desc)",'Referring domains - no comparis'!$A$1:$M$1,0),4),1,"")&":"&SUBSTITUTE(ADDRESS(1,MATCH("Domain Rating (desc)",'Referring domains - no comparis'!$A$1:$M$1,0),4),1,"")),"<"&D3, INDIRECT("'Referring domains'!"&SUBSTITUTE(ADDRESS(1,MATCH("Domain Rating (desc)",'Referring domains - no comparis'!$A$1:$M$1,0),4),1,"")&":"&SUBSTITUTE(ADDRESS(1,MATCH("Domain Rating (desc)",'Referring domains - no comparis'!$A$1:$M$1,0),4),1,"")),">"&C3, INDIRECT("'Referring domains'!"&SUBSTITUTE(ADDRESS(1,MATCH("Organic Traffic",'Referring domains - no comparis'!$A$1:$M$1,0),4),1,"")&":"&SUBSTITUTE(ADDRESS(1,MATCH("Organic Traffic",'Referring domains - no comparis'!$A$1:$M$1,0),4),1,"")),">1000")} -> #N/A | M3: =L3*B3 -> #N/A
A4: 30-40 | B4: 100 | C4: 29 | D4: 40 | E4: =sumifs('Referring domains - no comparis'!$D:$D,'Referring domains - no comparis'!B:B,"<"&D4,'Referring domains - no comparis'!B:B,">"&C4,'Referring domains - no comparis'!K:K,">1000") -> 0 | G4: {=COUNTIFS( INDIRECT("'Referring domains'!"&SUBSTITUTE(ADDRESS(1,MATCH("DR",'Referring domains - no comparis'!$A$1:$M$1,0),4),1,"")&":"&SUBSTITUTE(ADDRESS(1,MATCH("DR",'Referring domains - no comparis'!$A$1:$M$1,0),4),1,"")),"<"&D4, INDIRECT("'Referring domains'!"&SUBSTITUTE(ADDRESS(1,MATCH("DR",'Referring domains - no comparis'!$A$1:$M$1,0),4),1,"")&":"&SUBSTITUTE(ADDRESS(1,MATCH("DR",'Referring domains - no comparis'!$A$1:$M$1,0),4),1,"")),">"&C4 )} -> 0 | H4: {=sumifs(INDIRECT("'Referring domains'!"&SUBSTITUTE(ADDRESS(1,MATCH("Links to target",'Referring domains - no comparis'!$A$1:$M$1,0),4),1,"")&":"&SUBSTITUTE(ADDRESS(1,MATCH("Links to target",'Referring domains - no comparis'!$A$1:$M$1,0),4),1,"")), INDIRECT("'Referring domains'!"&SUBSTITUTE(ADDRESS(1,MATCH("DR",'Referring domains - no comparis'!$A$1:$M$1,0),4),1,"")&":"&SUBSTITUTE(ADDRESS(1,MATCH("DR",'Referring domains - no comparis'!$A$1:$M$1,0),4),1,"")),"<"&D4, INDIRECT("'Referring domains'!"&SUBSTITUTE(ADDRESS(1,MATCH("DR",'Referring domains - no comparis'!$A$1:$M$1,0),4),1,"")&":"&SUBSTITUTE(ADDRESS(1,MATCH("DR",'Referring domains - no comparis'!$A$1:$M$1,0),4),1,"")),">"&C4)} -> #N/A | I4: =H4*B4 -> #N/A | K4: {=COUNTIFS( INDIRECT("'Referring domains'!"&SUBSTITUTE(ADDRESS(1,MATCH("Domain Rating (desc)",'Referring domains - no comparis'!$A$1:$M$1,0),4),1,"")&":"&SUBSTITUTE(ADDRESS(1,MATCH("Domain Rating (desc)",'Referring domains - no comparis'!$A$1:$M$1,0),4),1,"")),"<"&D4, INDIRECT("'Referring domains'!"&SUBSTITUTE(ADDRESS(1,MATCH("Domain Rating (desc)",'Referring domains - no comparis'!$A$1:$M$1,0),4),1,"")&":"&SUBSTITUTE(ADDRESS(1,MATCH("Domain Rating (desc)",'Referring domains - no comparis'!$A$1:$M$1,0),4),1,"")),">"&C4, INDIRECT("'Referring domains'!"&SUBSTITUTE(ADDRESS(1,MATCH("Organic Traffic",'Referring domains - no comparis'!$A$1:$M$1,0),4),1,"")&":"&SUBSTITUTE(ADDRESS(1,MATCH("Organic Traffic",'Referring domains - no comparis'!$A$1:$M$1,0),4),1,"")),">1000" )} -> 0 | L4: {=sumifs(INDIRECT("'Referring domains'!"&SUBSTITUTE(ADDRESS(1,MATCH("Total Backlinks",'Referring domains - no comparis'!$A$1:$M$1,0),4),1,"")&":"&SUBSTITUTE(ADDRESS(1,MATCH("Total Backlinks",'Referring domains - no comparis'!$A$1:$M$1,0),4),1,"")), INDIRECT("'Referring domains'!"&SUBSTITUTE(ADDRESS(1,MATCH("Domain Rating (desc)",'Referring domains - no comparis'!$A$1:$M$1,0),4),1,"")&":"&SUBSTITUTE(ADDRESS(1,MATCH("Domain Rating (desc)",'Referring domains - no comparis'!$A$1:$M$1,0),4),1,"")),"<"&D4, INDIRECT("'Referring domains'!"&SUBSTITUTE(ADDRESS(1,MATCH("Domain Rating (desc)",'Referring domains - no comparis'!$A$1:$M$1,0),4),1,"")&":"&SUBSTITUTE(ADDRESS(1,MATCH("Domain Rating (desc)",'Referring domains - no comparis'!$A$1:$M$1,0),4),1,"")),">"&C4, INDIRECT("'Referring domains'!"&SUBSTITUTE(ADDRESS(1,MATCH("Organic Traffic",'Referring domains - no comparis'!$A$1:$M$1,0),4),1,"")&":"&SUBSTITUTE(ADDRESS(1,MATCH("Organic Traffic",'Referring domains - no comparis'!$A$1:$M$1,0),4),1,"")),">1000")} -> #N/A | M4: =L4*B4 -> #N/A
A5: 10-30 | B5: 50 | C5: 9 | D5: 30 | E5: =sumifs('Referring domains - no comparis'!$D:$D,'Referring domains - no comparis'!B:B,"<"&D5,'Referring domains - no comparis'!B:B,">"&C5,'Referring domains - no comparis'!K:K,">1000") -> 0 | G5: {=COUNTIFS( INDIRECT("'Referring domains'!"&SUBSTITUTE(ADDRESS(1,MATCH("DR",'Referring domains - no comparis'!$A$1:$M$1,0),4),1,"")&":"&SUBSTITUTE(ADDRESS(1,MATCH("DR",'Referring domains - no comparis'!$A$1:$M$1,0),4),1,"")),"<"&D5, INDIRECT("'Referring domains'!"&SUBSTITUTE(ADDRESS(1,MATCH("DR",'Referring domains - no comparis'!$A$1:$M$1,0),4),1,"")&":"&SUBSTITUTE(ADDRESS(1,MATCH("DR",'Referring domains - no comparis'!$A$1:$M$1,0),4),1,"")),">"&C5 )} -> 0 | H5: {=sumifs(INDIRECT("'Referring domains'!"&SUBSTITUTE(ADDRESS(1,MATCH("Links to target",'Referring domains - no comparis'!$A$1:$M$1,0),4),1,"")&":"&SUBSTITUTE(ADDRESS(1,MATCH("Links to target",'Referring domains - no comparis'!$A$1:$M$1,0),4),1,"")), INDIRECT("'Referring domains'!"&SUBSTITUTE(ADDRESS(1,MATCH("DR",'Referring domains - no comparis'!$A$1:$M$1,0),4),1,"")&":"&SUBSTITUTE(ADDRESS(1,MATCH("DR",'Referring domains - no comparis'!$A$1:$M$1,0),4),1,"")),"<"&D5, INDIRECT("'Referring domains'!"&SUBSTITUTE(ADDRESS(1,MATCH("DR",'Referring domains - no comparis'!$A$1:$M$1,0),4),1,"")&":"&SUBSTITUTE(ADDRESS(1,MATCH("DR",'Referring domains - no comparis'!$A$1:$M$1,0),4),1,"")),">"&C5)} -> #N/A | I5: =H5*B5 -> #N/A | K5: {=COUNTIFS( INDIRECT("'Referring domains'!"&SUBSTITUTE(ADDRESS(1,MATCH("Domain Rating (desc)",'Referring domains - no comparis'!$A$1:$M$1,0),4),1,"")&":"&SUBSTITUTE(ADDRESS(1,MATCH("Domain Rating (desc)",'Referring domains - no comparis'!$A$1:$M$1,0),4),1,"")),"<"&D5, INDIRECT("'Referring domains'!"&SUBSTITUTE(ADDRESS(1,MATCH("Domain Rating (desc)",'Referring domains - no comparis'!$A$1:$M$1,0),4),1,"")&":"&SUBSTITUTE(ADDRESS(1,MATCH("Domain Rating (desc)",'Referring domains - no comparis'!$A$1:$M$1,0),4),1,"")),">"&C5, INDIRECT("'Referring domains'!"&SUBSTITUTE(ADDRESS(1,MATCH("Organic Traffic",'Referring domains - no comparis'!$A$1:$M$1,0),4),1,"")&":"&SUBSTITUTE(ADDRESS(1,MATCH("Organic Traffic",'Referring domains - no comparis'!$A$1:$M$1,0),4),1,"")),">1000" )} -> 0 | L5: {=sumifs(INDIRECT("'Referring domains'!"&SUBSTITUTE(ADDRESS(1,MATCH("Total Backlinks",'Referring domains - no comparis'!$A$1:$M$1,0),4),1,"")&":"&SUBSTITUTE(ADDRESS(1,MATCH("Total Backlinks",'Referring domains - no comparis'!$A$1:$M$1,0),4),1,"")), INDIRECT("'Referring domains'!"&SUBSTITUTE(ADDRESS(1,MATCH("Domain Rating (desc)",'Referring domains - no comparis'!$A$1:$M$1,0),4),1,"")&":"&SUBSTITUTE(ADDRESS(1,MATCH("Domain Rating (desc)",'Referring domains - no comparis'!$A$1:$M$1,0),4),1,"")),"<"&D5, INDIRECT("'Referring domains'!"&SUBSTITUTE(ADDRESS(1,MATCH("Domain Rating (desc)",'Referring domains - no comparis'!$A$1:$M$1,0),4),1,"")&":"&SUBSTITUTE(ADDRESS(1,MATCH("Domain Rating (desc)",'Referring domains - no comparis'!$A$1:$M$1,0),4),1,"")),">"&C5, INDIRECT("'Referring domains'!"&SUBSTITUTE(ADDRESS(1,MATCH("Organic Traffic",'Referring domains - no comparis'!$A$1:$M$1,0),4),1,"")&":"&SUBSTITUTE(ADDRESS(1,MATCH("Organic Traffic",'Referring domains - no comparis'!$A$1:$M$1,0),4),1,"")),">1000")} -> #N/A | M5: =L5*B5 -> #N/A
A6: 0-10 | B6: 10 | C6: -1 | D6: 10 | E6: =sumifs('Referring domains - no comparis'!$D:$D,'Referring domains - no comparis'!B:B,"<"&D6,'Referring domains - no comparis'!B:B,">"&C6,'Referring domains - no comparis'!K:K,">1000") -> 0 | G6: {=COUNTIFS( INDIRECT("'Referring domains'!"&SUBSTITUTE(ADDRESS(1,MATCH("DR",'Referring domains - no comparis'!$A$1:$M$1,0),4),1,"")&":"&SUBSTITUTE(ADDRESS(1,MATCH("DR",'Referring domains - no comparis'!$A$1:$M$1,0),4),1,"")),"<"&D6, INDIRECT("'Referring domains'!"&SUBSTITUTE(ADDRESS(1,MATCH("DR",'Referring domains - no comparis'!$A$1:$M$1,0),4),1,"")&":"&SUBSTITUTE(ADDRESS(1,MATCH("DR",'Referring domains - no comparis'!$A$1:$M$1,0),4),1,"")),">"&C6 )} -> 0 | H6: {=sumifs(INDIRECT("'Referring domains'!"&SUBSTITUTE(ADDRESS(1,MATCH("Links to target",'Referring domains - no comparis'!$A$1:$M$1,0),4),1,"")&":"&SUBSTITUTE(ADDRESS(1,MATCH("Links to target",'Referring domains - no comparis'!$A$1:$M$1,0),4),1,"")), INDIRECT("'Referring domains'!"&SUBSTITUTE(ADDRESS(1,MATCH("DR",'Referring domains - no comparis'!$A$1:$M$1,0),4),1,"")&":"&SUBSTITUTE(ADDRESS(1,MATCH("DR",'Referring domains - no comparis'!$A$1:$M$1,0),4),1,"")),"<"&D6, INDIRECT("'Referring domains'!"&SUBSTITUTE(ADDRESS(1,MATCH("DR",'Referring domains - no comparis'!$A$1:$M$1,0),4),1,"")&":"&SUBSTITUTE(ADDRESS(1,MATCH("DR",'Referring domains - no comparis'!$A$1:$M$1,0),4),1,"")),">"&C6)} -> #N/A | I6: =H6*B6 -> #N/A | K6: {=COUNTIFS( INDIRECT("'Referring domains'!"&SUBSTITUTE(ADDRESS(1,MATCH("Domain Rating (desc)",'Referring domains - no comparis'!$A$1:$M$1,0),4),1,"")&":"&SUBSTITUTE(ADDRESS(1,MATCH("Domain Rating (desc)",'Referring domains - no comparis'!$A$1:$M$1,0),4),1,"")),"<"&D6, INDIRECT("'Referring domains'!"&SUBSTITUTE(ADDRESS(1,MATCH("Domain Rating (desc)",'Referring domains - no comparis'!$A$1:$M$1,0),4),1,"")&":"&SUBSTITUTE(ADDRESS(1,MATCH("Domain Rating (desc)",'Referring domains - no comparis'!$A$1:$M$1,0),4),1,"")),">"&C6, INDIRECT("'Referring domains'!"&SUBSTITUTE(ADDRESS(1,MATCH("Organic Traffic",'Referring domains - no comparis'!$A$1:$M$1,0),4),1,"")&":"&SUBSTITUTE(ADDRESS(1,MATCH("Organic Traffic",'Referring domains - no comparis'!$A$1:$M$1,0),4),1,"")),">1000" )} -> 0 | L6: {=sumifs(INDIRECT("'Referring domains'!"&SUBSTITUTE(ADDRESS(1,MATCH("Total Backlinks",'Referring domains - no comparis'!$A$1:$M$1,0),4),1,"")&":"&SUBSTITUTE(ADDRESS(1,MATCH("Total Backlinks",'Referring domains - no comparis'!$A$1:$M$1,0),4),1,"")), INDIRECT("'Referring domains'!"&SUBSTITUTE(ADDRESS(1,MATCH("Domain Rating (desc)",'Referring domains - no comparis'!$A$1:$M$1,0),4),1,"")&":"&SUBSTITUTE(ADDRESS(1,MATCH("Domain Rating (desc)",'Referring domains - no comparis'!$A$1:$M$1,0),4),1,"")),"<"&D6, INDIRECT("'Referring domains'!"&SUBSTITUTE(ADDRESS(1,MATCH("Domain Rating (desc)",'Referring domains - no comparis'!$A$1:$M$1,0),4),1,"")&":"&SUBSTITUTE(ADDRESS(1,MATCH("Domain Rating (desc)",'Referring domains - no comparis'!$A$1:$M$1,0),4),1,"")),">"&C6, INDIRECT("'Referring domains'!"&SUBSTITUTE(ADDRESS(1,MATCH("Organic Traffic",'Referring domains - no comparis'!$A$1:$M$1,0),4),1,"")&":"&SUBSTITUTE(ADDRESS(1,MATCH("Organic Traffic",'Referring domains - no comparis'!$A$1:$M$1,0),4),1,"")),">1000")} -> #N/A | M6: =L6*B6 -> #N/A
G8: Total ref domains | H8: Total backlinks | I8: Total value | L8: Total backlinks | M8: Total value
G9: =SUM(G2:G6) -> 0 | H9: =sum(H2:H6) -> #N/A | I9: =SUM(I2:I6) -> #N/A | L9: =sum(L2:L6) -> #N/A | M9: =SUM(M2:M6) -> #N/A
G12: minimum traffic
G13: -1

Sheet Cost of backlinks (without low 
A1: DR range | B1: value per backlink | C1: min (not inclusive) | D1: max (not inclusive) | E1: total backlinks (wrong) | F1: with low traffic: | G1: referring domains | H1: backlinks | I1: value | J1: without low traffic: | K1: referring domains | L1: backlinks | M1: value | P1: =A2 -> 70-100 | Q1: =A3 -> 40-70 | R1: =A4 -> 30-40 | S1: =A5 -> 10-30 | T1: =A6 -> 0-10
A2: 70-100 | B2: 750 | C2: 69 | D2: 101 | E2: =sumifs('Referring domains - no comparis'!$D:$D, 'Referring domains - no comparis'!B:B,"<"&D2, 'Referring domains - no comparis'!B:B,">"&C2, 'Referring domains - no comparis'!K:K,">1000") -> 0 | G2: {=COUNTIFS( INDIRECT("'Referring domains'!"&SUBSTITUTE(ADDRESS(1,MATCH("Domain Rating (desc)",'Referring domains - no comparis'!$A$1:$M$1,0),4),1,"")&":"&SUBSTITUTE(ADDRESS(1,MATCH("Domain Rating (desc)",'Referring domains - no comparis'!$A$1:$M$1,0),4),1,"")),"<"&D2, INDIRECT("'Referring domains'!"&SUBSTITUTE(ADDRESS(1,MATCH("Domain Rating (desc)",'Referring domains - no comparis'!$A$1:$M$1,0),4),1,"")&":"&SUBSTITUTE(ADDRESS(1,MATCH("Domain Rating (desc)",'Referring domains - no comparis'!$A$1:$M$1,0),4),1,"")),">"&C2 )} -> 0 | H2: {=sumifs(INDIRECT("'Referring domains'!"&SUBSTITUTE(ADDRESS(1,MATCH("Total Backlinks",'Referring domains - no comparis'!$A$1:$M$1,0),4),1,"")&":"&SUBSTITUTE(ADDRESS(1,MATCH("Total Backlinks",'Referring domains - no comparis'!$A$1:$M$1,0),4),1,"")), INDIRECT("'Referring domains'!"&SUBSTITUTE(ADDRESS(1,MATCH("Domain Rating (desc)",'Referring domains - no comparis'!$A$1:$M$1,0),4),1,"")&":"&SUBSTITUTE(ADDRESS(1,MATCH("Domain Rating (desc)",'Referring domains - no comparis'!$A$1:$M$1,0),4),1,"")),"<"&D2, INDIRECT("'Referring domains'!"&SUBSTITUTE(ADDRESS(1,MATCH("Domain Rating (desc)",'Referring domains - no comparis'!$A$1:$M$1,0),4),1,"")&":"&SUBSTITUTE(ADDRESS(1,MATCH("Domain Rating (desc)",'Referring domains - no comparis'!$A$1:$M$1,0),4),1,"")),">"&C2)} -> #N/A | I2: =H2*B2 -> #N/A | K2: =COUNTA(P:P) - 1 -> 1 | L2: =IFERROR(__xludf.DUMMYFUNCTION("sum(filter('Referring domains - no comparis'!G1:G787,isnumber(match('Referring domains - no comparis'!A1:A787,'Cost of backlinks (without low '!P:P,0)))) "),"#N/A") -> #N/A | M2: =L2*B2 -> #N/A | P2: =IFERROR(__xludf.DUMMYFUNCTION("FILTER('Referring domains - no comparis'!$A$2:$A787, 'Referring domains - no comparis'!$B$2:$B787<101, 'Referring domains - no comparis'!$B$2:$B787>69, 'Referring domains - no comparis'!$E$2:$E787>$K$13)"),"#N/A") -> #N/A | Q2: =IFERROR(__xludf.DUMMYFUNCTION("FILTER('Referring domains - no comparis'!$A$2:$A787, 'Referring domains - no comparis'!$B$2:$B787<70, 'Referring domains - no comparis'!$B$2:$B787>39, 'Referring domains - no comparis'!$E$2:$E787>$K$13)"),"#N/A") -> #N/A | R2: =IFERROR(__xludf.DUMMYFUNCTION("FILTER('Referring domains - no comparis'!$A$2:$A787, 'Referring domains - no comparis'!$B$2:$B787<40, 'Referring domains - no comparis'!$B$2:$B787>29, 'Referring domains - no comparis'!$E$2:$E787>$K$13)"),"#N/A") -> #N/A | S2: =IFERROR(__xludf.DUMMYFUNCTION("FILTER('Referring domains - no comparis'!$A$2:$A787, 'Referring domains - no comparis'!$B$2:$B787<30, 'Referring domains - no comparis'!$B$2:$B787>9, 'Referring domains - no comparis'!$E$2:$E787>$K$13)"),"#N/A") -> #N/A | T2: =IFERROR(__xludf.DUMMYFUNCTION("FILTER('Referring domains - no comparis'!$A$2:$A787, 'Referring domains - no comparis'!$B$2:$B787<10, 'Referring domains - no comparis'!$B$2:$B787>-1, 'Referring domains - no comparis'!$E$2:$E787>$K$13)"),"#N/A") -> #N/A
A3: 40-70 | B3: 300 | C3: 39 | D3: 70 | E3: =sumifs('Referring domains - no comparis'!$D:$D,'Referring domains - no comparis'!B:B,"<"&D3,'Referring domains - no comparis'!B:B,">"&C3,'Referring domains - no comparis'!K:K,">1000") -> 0 | G3: {=COUNTIFS( INDIRECT("'Referring domains'!"&SUBSTITUTE(ADDRESS(1,MATCH("Domain Rating (desc)",'Referring domains - no comparis'!$A$1:$M$1,0),4),1,"")&":"&SUBSTITUTE(ADDRESS(1,MATCH("Domain Rating (desc)",'Referring domains - no comparis'!$A$1:$M$1,0),4),1,"")),"<"&D3, INDIRECT("'Referring domains'!"&SUBSTITUTE(ADDRESS(1,MATCH("Domain Rating (desc)",'Referring domains - no comparis'!$A$1:$M$1,0),4),1,"")&":"&SUBSTITUTE(ADDRESS(1,MATCH("Domain Rating (desc)",'Referring domains - no comparis'!$A$1:$M$1,0),4),1,"")),">"&C3 )} -> 0 | H3: {=sumifs(INDIRECT("'Referring domains'!"&SUBSTITUTE(ADDRESS(1,MATCH("Total Backlinks",'Referring domains - no comparis'!$A$1:$M$1,0),4),1,"")&":"&SUBSTITUTE(ADDRESS(1,MATCH("Total Backlinks",'Referring domains - no comparis'!$A$1:$M$1,0),4),1,"")), INDIRECT("'Referring domains'!"&SUBSTITUTE(ADDRESS(1,MATCH("Domain Rating (desc)",'Referring domains - no comparis'!$A$1:$M$1,0),4),1,"")&":"&SUBSTITUTE(ADDRESS(1,MATCH("Domain Rating (desc)",'Referring domains - no comparis'!$A$1:$M$1,0),4),1,"")),"<"&D3, INDIRECT("'Referring domains'!"&SUBSTITUTE(ADDRESS(1,MATCH("Domain Rating (desc)",'Referring domains - no comparis'!$A$1:$M$1,0),4),1,"")&":"&SUBSTITUTE(ADDRESS(1,MATCH("Domain Rating (desc)",'Referring domains - no comparis'!$A$1:$M$1,0),4),1,"")),">"&C3)} -> #N/A | I3: =H3*B3 -> #N/A | K3: =COUNTA(Q:Q) - 1 -> 1 | L3: =IFERROR(__xludf.DUMMYFUNCTION("sum(filter('Referring domains - no comparis'!G:G,isnumber(match('Referring domains - no comparis'!A:A,'Cost of backlinks (without low '!Q:Q,0)))) "),"#N/A") -> #N/A | M3: =L3*B3 -> #N/A
A4: 30-40 | B4: 100 | C4: 29 | D4: 40 | E4: =sumifs('Referring domains - no comparis'!$D:$D,'Referring domains - no comparis'!B:B,"<"&D4,'Referring domains - no comparis'!B:B,">"&C4,'Referring domains - no comparis'!K:K,">1000") -> 0 | G4: {=COUNTIFS( INDIRECT("'Referring domains'!"&SUBSTITUTE(ADDRESS(1,MATCH("Domain Rating (desc)",'Referring domains - no comparis'!$A$1:$M$1,0),4),1,"")&":"&SUBSTITUTE(ADDRESS(1,MATCH("Domain Rating (desc)",'Referring domains - no comparis'!$A$1:$M$1,0),4),1,"")),"<"&D4, INDIRECT("'Referring domains'!"&SUBSTITUTE(ADDRESS(1,MATCH("Domain Rating (desc)",'Referring domains - no comparis'!$A$1:$M$1,0),4),1,"")&":"&SUBSTITUTE(ADDRESS(1,MATCH("Domain Rating (desc)",'Referring domains - no comparis'!$A$1:$M$1,0),4),1,"")),">"&C4 )} -> 0 | H4: {=sumifs(INDIRECT("'Referring domains'!"&SUBSTITUTE(ADDRESS(1,MATCH("Total Backlinks",'Referring domains - no comparis'!$A$1:$M$1,0),4),1,"")&":"&SUBSTITUTE(ADDRESS(1,MATCH("Total Backlinks",'Referring domains - no comparis'!$A$1:$M$1,0),4),1,"")), INDIRECT("'Referring domains'!"&SUBSTITUTE(ADDRESS(1,MATCH("Domain Rating (desc)",'Referring domains - no comparis'!$A$1:$M$1,0),4),1,"")&":"&SUBSTITUTE(ADDRESS(1,MATCH("Domain Rating (desc)",'Referring domains - no comparis'!$A$1:$M$1,0),4),1,"")),"<"&D4, INDIRECT("'Referring domains'!"&SUBSTITUTE(ADDRESS(1,MATCH("Domain Rating (desc)",'Referring domains - no comparis'!$A$1:$M$1,0),4),1,"")&":"&SUBSTITUTE(ADDRESS(1,MATCH("Domain Rating (desc)",'Referring domains - no comparis'!$A$1:$M$1,0),4),1,"")),">"&C4)} -> #N/A | I4: =H4*B4 -> #N/A | K4: =COUNTA(R:R) - 1 -> 1 | L4: =IFERROR(__xludf.DUMMYFUNCTION("sum(filter('Referring domains - no comparis'!G:G,isnumber(match('Referring domains - no comparis'!A:A,'Cost of backlinks (without low '!R:R,0)))) "),"#N/A") -> #N/A | M4: =L4*B4 -> #N/A
A5: 10-30 | B5: 50 | C5: 9 | D5: 30 | E5: =sumifs('Referring domains - no comparis'!$D:$D,'Referring domains - no comparis'!B:B,"<"&D5,'Referring domains - no comparis'!B:B,">"&C5,'Referring domains - no comparis'!K:K,">1000") -> 0 | G5: {=COUNTIFS( INDIRECT("'Referring domains'!"&SUBSTITUTE(ADDRESS(1,MATCH("Domain Rating (desc)",'Referring domains - no comparis'!$A$1:$M$1,0),4),1,"")&":"&SUBSTITUTE(ADDRESS(1,MATCH("Domain Rating (desc)",'Referring domains - no comparis'!$A$1:$M$1,0),4),1,"")),"<"&D5, INDIRECT("'Referring domains'!"&SUBSTITUTE(ADDRESS(1,MATCH("Domain Rating (desc)",'Referring domains - no comparis'!$A$1:$M$1,0),4),1,"")&":"&SUBSTITUTE(ADDRESS(1,MATCH("Domain Rating (desc)",'Referring domains - no comparis'!$A$1:$M$1,0),4),1,"")),">"&C5 )} -> 0 | H5: {=sumifs(INDIRECT("'Referring domains'!"&SUBSTITUTE(ADDRESS(1,MATCH("Total Backlinks",'Referring domains - no comparis'!$A$1:$M$1,0),4),1,"")&":"&SUBSTITUTE(ADDRESS(1,MATCH("Total Backlinks",'Referring domains - no comparis'!$A$1:$M$1,0),4),1,"")), INDIRECT("'Referring domains'!"&SUBSTITUTE(ADDRESS(1,MATCH("Domain Rating (desc)",'Referring domains - no comparis'!$A$1:$M$1,0),4),1,"")&":"&SUBSTITUTE(ADDRESS(1,MATCH("Domain Rating (desc)",'Referring domains - no comparis'!$A$1:$M$1,0),4),1,"")),"<"&D5, INDIRECT("'Referring domains'!"&SUBSTITUTE(ADDRESS(1,MATCH("Domain Rating (desc)",'Referring domains - no comparis'!$A$1:$M$1,0),4),1,"")&":"&SUBSTITUTE(ADDRESS(1,MATCH("Domain Rating (desc)",'Referring domains - no comparis'!$A$1:$M$1,0),4),1,"")),">"&C5)} -> #N/A | I5: =H5*B5 -> #N/A | K5: =COUNTA(S:S) - 1 -> 1 | L5: =IFERROR(__xludf.DUMMYFUNCTION("sum(filter('Referring domains - no comparis'!G:G,isnumber(match('Referring domains - no comparis'!A:A,'Cost of backlinks (without low '!S:S,0)))) "),"#N/A") -> #N/A | M5: =L5*B5 -> #N/A
A6: 0-10 | B6: 10 | C6: -1 | D6: 10 | E6: =sumifs('Referring domains - no comparis'!$D:$D,'Referring domains - no comparis'!B:B,"<"&D6,'Referring domains - no comparis'!B:B,">"&C6,'Referring domains - no comparis'!K:K,">1000") -> 0 | G6: {=COUNTIFS( INDIRECT("'Referring domains'!"&SUBSTITUTE(ADDRESS(1,MATCH("Domain Rating (desc)",'Referring domains - no comparis'!$A$1:$M$1,0),4),1,"")&":"&SUBSTITUTE(ADDRESS(1,MATCH("Domain Rating (desc)",'Referring domains - no comparis'!$A$1:$M$1,0),4),1,"")),"<"&D6, INDIRECT("'Referring domains'!"&SUBSTITUTE(ADDRESS(1,MATCH("Domain Rating (desc)",'Referring domains - no comparis'!$A$1:$M$1,0),4),1,"")&":"&SUBSTITUTE(ADDRESS(1,MATCH("Domain Rating (desc)",'Referring domains - no comparis'!$A$1:$M$1,0),4),1,"")),">"&C6 )} -> 0 | H6: {=sumifs(INDIRECT("'Referring domains'!"&SUBSTITUTE(ADDRESS(1,MATCH("Total Backlinks",'Referring domains - no comparis'!$A$1:$M$1,0),4),1,"")&":"&SUBSTITUTE(ADDRESS(1,MATCH("Total Backlinks",'Referring domains - no comparis'!$A$1:$M$1,0),4),1,"")), INDIRECT("'Referring domains'!"&SUBSTITUTE(ADDRESS(1,MATCH("Domain Rating (desc)",'Referring domains - no comparis'!$A$1:$M$1,0),4),1,"")&":"&SUBSTITUTE(ADDRESS(1,MATCH("Domain Rating (desc)",'Referring domains - no comparis'!$A$1:$M$1,0),4),1,"")),"<"&D6, INDIRECT("'Referring domains'!"&SUBSTITUTE(ADDRESS(1,MATCH("Domain Rating (desc)",'Referring domains - no comparis'!$A$1:$M$1,0),4),1,"")&":"&SUBSTITUTE(ADDRESS(1,MATCH("Domain Rating (desc)",'Referring domains - no comparis'!$A$1:$M$1,0),4),1,"")),">"&C6)} -> #N/A | I6: =H6*B6 -> #N/A | K6: =COUNTA(T:T) - 1 -> 1 | L6: =IFERROR(__xludf.DUMMYFUNCTION("sum(filter('Referring domains - no comparis'!G:G,isnumber(match('Referring domains - no comparis'!A:A,'Cost of backlinks (without low '!T:T,0)))) "),"#N/A") -> #N/A | M6: =L6*B6 -> #N/A
H8: Total backlinks | I8: Total value | L8: Total backlinks | M8: Total value
H9: =sum(H2:H6) -> #N/A | I9: =SUM(I2:I6) -> #N/A | L9: =sum(L2:L6) -> #N/A | M9: =SUM(M2:M6) -> #N/A
K12: minimum traffic
K13: 1000
