Workbook

Sheet Backlinks
A1: Referring page title | B1: Referring page URL | C1: Language | D1: Platform | E1: Referring page HTTP code | F1: Domain rating | G1: UR | H1: Domain traffic | I1: Referring domains | J1: Linked domains | K1: External links | L1: Page traffic | M1: Keywords | N1: Target URL | O1: Left context | P1: Anchor | Q1: Right context | R1: Redirect Chain URLs | S1: Redirect Chain status codes | T1: Type | U1: Is spam | V1: Content | W1: Nofollow | X1: UGC | Y1: Sponsored | Z1: Rendered | AA1: Raw | AB1: Lost status | AC1: Drop reason | AD1: Discovered status | AE1: First seen | AF1: Last seen | AG1: Lost | AH1: Author | AI1: Page type | AJ1: Page category
A2: Pikeland Property Group LLC | BBB Business Profile | Better Business Bureau | B2: https://www.bbb.org/us/pa/phoenixville/profile/home-buyers/pikeland-property-group-llc-0241-236072398 | C2: en | E2: 200 | F2: 93 | G2: 4.5 | H2: 3593412 | I2: 0 | J2: 10 | K2: 17 | L2: 0 | M2: 0 | N2: https://www.pikelandpropertygroup.com/ | P2: Visit Website | T2: text | U2: FALSE | V2: FALSE | W2: TRUE | X2: FALSE | Y2: FALSE | Z2: FALSE | AA2: TRUE | AD2: linkfound | AE2: 45935.997 | AF2: 46182.579
A3: 👲 Domain Report 👲 | B3: https://screenshots.wiki/report/50888 | C3: en | E3: 200 | F3: 41 | G3: 0 | H3: 0 | I3: 0 | J3: 3702 | K3: 4156 | L3: 0 | M3: 0 | N3: https://www.pikelandpropertygroup.com/ | O3: Homepage | P3: pikelandpropertygroup.com | Q3: &nbsp | R3: https://pikelandpropertygroup.com/ | S3: 301 | T3: text | U3: TRUE | V3: TRUE | W3: TRUE | X3: FALSE | Y3: FALSE | Z3: FALSE | AA3: TRUE | AD3: linkfound | AE3: 46132.774 | AF3: 46132.774 | AI3: Site page > Services | AJ3: Internet > Web services > Development
A4: 🛸 Dark Side Links – Dark/White Hat Link Building Services – Global Waste Commodities | B4: https://gwc.spottedcow.media/2026/02/21/dark-side-links-dark-white-hat-link-building-1342/ | C4: en | D4: wordpress | E4: 200 | F4: 15 | G4: 0 | H4: 6 | I4: 0 | J4: 3119 | K4: 3419 | L4: 0 | M4: 0 | N4: https://www.pikelandpropertygroup.com/ | O4: DARK HAT AND WHITE HAT BACKLINKS | P4: JOIN OUR TELEGRAM https://t.me/s/darksidelinks | Q4: FOR CHEAP AND GOOGLE FRIENDLY BACKLINKS | T4: text | U4: TRUE | V4: FALSE | W4: TRUE | X4: FALSE | Y4: FALSE | Z4: FALSE | AA4: TRUE | AD4: pagefound | AE4: 46135.343 | AF4: 46212.496 | AI4: Site page > Services | AJ4: Internet > Web services > SEO and marketing; Business > Business services
A5: seowarez.shop — The 120-Day Traffic Services Case Study for Financial Advisory — Placements, Anchors, Rankings Before and After | B5: https://seowarez.shop/a3dl99t-build-unstoppable-law-firm-serp-local-seo-crowd-links-traffic-playbook/ | C5: en | E5: 200 | F5: 0.7 | G5: 0 | H5: 0 | I5: 2 | J5: 5175 | K5: 6070 | L5: 0 | M5: 0 | N5: https://www.pikelandpropertygroup.com/ | P5: Boost pikelandpropertygroup.com using high-DR backlinks, editorial guest posts, on-page SEO, local SEO, web development, SaaS tools and automation tools for sustained DR/DA/TF uplift with full transparency. | R5: https://pikelandpropertygroup.com/ | S5: 301 | T5: text | U5: TRUE | V5: FALSE | W5: TRUE | X5: FALSE | Y5: FALSE | Z5: FALSE | AA5: TRUE | AD5: pagefound | AE5: 46204.364 | AF5: 46232.417 | AI5: Article > Research | AJ5: Business > Marketing > Marketing; Internet > Web services > SEO and marketing; Finance > Management > Portfolio
A6: The 120-Day Traffic Services Case Study for Financial Advisory — Placements, Anchors, Rankings Before and After — rankdeals.shop | B6: https://rankdeals.shop/a3dl99t-build-unstoppable-law-firm-serp-local-seo-crowd-links-traffic-playbook/ | C6: en | E6: 200 | F6: 0.8 | G6: 0 | H6: 0 | I6: 0 | J6: 5175 | K6: 6065 | L6: 0 | M6: 0 | N6: https://www.pikelandpropertygroup.com/ | P6: Boost pikelandpropertygroup.com using high-DR backlinks, editorial guest posts, on-page SEO, local SEO, web development, SaaS tools and automation tools for sustained DR/DA/TF uplift with full transparency. | R6: https://pikelandpropertygroup.com/ | S6: 301 | T6: text | U6: TRUE | V6: FALSE | W6: TRUE | X6: FALSE | Y6: FALSE | Z6: FALSE | AA6: TRUE | AD6: linkfound | AE6: 46206.348 | AF6: 46220.429 | AI6: Article > Research | AJ6: Business > Marketing > Marketing; Internet > Web services > SEO and marketing; Finance > Management > Portfolio
A7: How to Build an Unstoppable Insurance SERP Presence Using PBN Backlinks, On-Page SEO, and Traffic — Full Playbook — Complete With hands-on strategy notes, quality-control requirements, and competitive search-positioning lessons — Site Rank Service — Managed professional services for site-wide SEO, keyword visibility and organic growth to turn search visibility into consistent website growth | B7: https://siterankservice.shop/d81d8072e-18-month-pbn-backlinks-journey-saas-zero-rankings-to-dr50-measurable-results-blueprint-planning-testing-and-tracking-for-scalable-seo-performance/ | C7: en | E7: 200 | F7: 0 | G7: 0 | H7: 0 | I7: 0 | J7: 6729 | K7: 7855 | L7: 0 | M7: 0 | N7: https://www.pikelandpropertygroup.com/ | P7: Everything pikelandpropertygroup.com needs: guest posts and backlinks, on-page SEO, local SEO, web development, SaaS integrations and automation tools — a strong DR/DA/TF increase worldwide. The strategy also covers competitor research, natural anchor distribution, quality verification, and clear monthly performance reporting. · Site Rank Service — Managed professional services for site-wide ... | R7: https://pikelandpropertygroup.com/ | S7: 301 | T7: text | U7: TRUE | V7: FALSE | W7: TRUE | X7: FALSE | Y7: FALSE | Z7: FALSE | AA7: TRUE | AD7: linkfound | AE7: 46227.747 | AF7: 46227.747 | AI7: Article > Guide | AJ7: Internet > Web services > SEO and marketing; Business > Marketing > Marketing
A8: 🛸 Dark Side Links – Dark/White Hat Link Building Services – Revan | B8: https://revan-me.com/bez-rubriki/dark-side-links-dark-white-hat-link-building-1342/ | C8: en | D8: wordpress | E8: 200 | F8: 8 | G8: 0 | H8: 0 | I8: 0 | J8: 3118 | K8: 3419 | L8: 0 | M8: 0 | N8: https://www.pikelandpropertygroup.com/ | O8: DARK HAT AND WHITE HAT BACKLINKS | P8: JOIN OUR TELEGRAM https://t.me/s/darksidelinks | Q8: FOR CHEAP AND GOOGLE FRIENDLY BACKLINKS | T8: text | U8: TRUE | V8: FALSE | W8: TRUE | X8: FALSE | Y8: FALSE | Z8: FALSE | AA8: TRUE | AD8: pagefound | AE8: 46154.768 | AF8: 46228.002 | AI8: Site page > Services | AJ8: Internet > Web services > SEO and marketing; Business > Marketing > Marketing
A9: Site Rank Builders — Growth builders specializing in site-wide SEO, keyword visibility and organic growth to improve website trust and sustainable search performance — How I Stacked PBN Backlinks With Web Development for Real Estate — The Dual Strategy That Doubled My Ranking Speed — Explaining a detailed execution roadmap, technical considerations, and safer scaling recommendations | B9: https://siterankbuilders.shop/efbb44080-do-crowd-links-still-work-2026-insurance-tested-10-placements-tracked-detailed-campaign-breakdown-budget-links-and-content-for-long-term-search-success/ | C9: en | E9: 200 | F9: 0 | G9: 0 | H9: 0 | I9: 0 | J9: 6735 | K9: 7857 | L9: 0 | M9: 0 | N9: https://www.pikelandpropertygroup.com/ | P9: Power up pikelandpropertygroup.com: guest posts, backlinks, on-page and local SEO, web development, SaaS tools and workflow automation tools for a clear DR/DA/TF lift in any language. Every delivery follows a structured plan for content relevance, link diversity, authority checks, traffic measurement, and ongoing optimization. · Site Rank Builders — Growth builders specializing in site-wide ... | R9: https://pikelandpropertygroup.com/ | S9: 301 | T9: text | U9: TRUE | V9: FALSE | W9: TRUE | X9: FALSE | Y9: FALSE | Z9: FALSE | AA9: TRUE | AD9: pagefound | AE9: 46229.313 | AF9: 46229.313 | AI9: Article > Guide | AJ9: Internet > Web services > SEO and marketing
A10: ✅ Website Stats 📊 | B10: https://optimizeflow.top/stats/50888 | C10: en | E10: 200 | F10: 41 | G10: 0 | H10: 0 | I10: 0 | J10: 3702 | K10: 4157 | L10: 0 | M10: 0 | N10: https://www.pikelandpropertygroup.com/ | O10: Homepage | P10: pikelandpropertygroup.com | Q10: &nbsp | R10: https://pikelandpropertygroup.com/ | S10: 301 | T10: text | U10: FALSE | V10: TRUE | W10: TRUE | X10: FALSE | Y10: FALSE | Z10: FALSE | AA10: TRUE | AD10: linkfound | AE10: 46068.119 | AF10: 46131.873 | AI10: Listing collection > Business | AJ10: Internet > Web services > Analytics; Reference
A11: Why Our Agency Stopped Manual Outreach Forever After Discovering Professional Link Building Results — linkrankpro.shop | B11: https://linkrankpro.shop/du3olt6-professional-link-campaign-biggest-agency-success-story/ | C11: en | E11: 200 | F11: 54 | G11: 0 | H11: 0 | I11: 4 | J11: 8299 | K11: 9726 | L11: 0 | M11: 0 | N11: https://www.pikelandpropertygroup.com/ | P11: Professional backlinks for pikelandpropertygroup.com from agency that built authority for 400 websites | R11: https://pikelandpropertygroup.com/ | S11: 301 | T11: text | U11: TRUE | V11: FALSE | W11: TRUE | X11: FALSE | Y11: FALSE | Z11: FALSE | AA11: TRUE | AD11: pagefound | AE11: 46149.883 | AF11: 46220.16 | AI11: Article > Story | AJ11: Internet > Web services > SEO and marketing; Business > Marketing > Marketing
A12: High-DA Guest Posts vs Crowd Links for Medical — Which One Moves Rankings Faster and Holds Longer? — Breaking Down hands-on strategy notes, technical considerations, and durable ranking strategies — Top Rank Company — A full-service company delivering top-position SEO, competitive visibility and ranking growth for reliable rankings, stronger authority and organic reach | B12: https://toprankcompany.shop/d67f93d69-used-traffic-services-rebuilt-dr-after-domain-migration-travel-site-month-by-month-progress-complete-implementation-guide-tools-tactics-and-insights-for-sustainable-organic-growth/ | C12: en | E12: 200 | F12: 0 | G12: 0 | H12: 0 | I12: 0 | J12: 6729 | K12: 7856 | L12: 0 | M12: 0 | N12: https://www.pikelandpropertygroup.com/ | P12: pikelandpropertygroup.com gets guest posts and backlinks, on-page SEO, local SEO, web development, SaaS integrations and automation tools, together driving a noticeable DR/DA/TF rise with proven results. The complete process includes website review, competitor benchmarking, anchor-risk control, placement validation, and practical growth recommendations. · Top Rank Company — A full-service ... | R12: https://pikelandpropertygroup.com/ | S12: 301 | T12: text | U12: TRUE | V12: FALSE | W12: TRUE | X12: FALSE | Y12: FALSE | Z12: FALSE | AA12: TRUE | AD12: linkfound | AE12: 46227.438 | AF12: 46227.438 | AI12: Article > Comparison | AJ12: Internet > Web services > SEO and marketing; Business > Marketing > Marketing
A13: The 120-Day Traffic Services Case Study for Financial Advisory — Placements, Anchors, Rankings Before and After — seostash.shop | B13: https://seostash.shop/a3dl99t-build-unstoppable-law-firm-serp-local-seo-crowd-links-traffic-playbook/ | C13: en | E13: 200 | F13: 0.7 | G13: 0 | H13: 0 | I13: 1 | J13: 5175 | K13: 6066 | L13: 0 | M13: 0 | N13: https://www.pikelandpropertygroup.com/ | P13: Boost pikelandpropertygroup.com using high-DR backlinks, editorial guest posts, on-page SEO, local SEO, web development, SaaS tools and automation tools for sustained DR/DA/TF uplift with full transparency. | R13: https://pikelandpropertygroup.com/ | S13: 301 | T13: text | U13: TRUE | V13: FALSE | W13: TRUE | X13: FALSE | Y13: FALSE | Z13: FALSE | AA13: TRUE | AD13: linkfound | AE13: 46205.864 | AF13: 46219.916 | AI13: Article > Research | AJ13: Business > Marketing > Marketing; Internet > Web services > SEO and marketing; Finance > Management > Portfolio
A14: Page 1 Rankings for Law Firm Using Only Link Insertions — Is This Possible in 2026? My Real Experiment — backlinkzeno.shop | B14: https://backlinkzeno.shop/alrp01b-90-day-serp-climb-saas-combined-editorial-links-traffic-services-position1/ | C14: en | E14: 200 | F14: 0.8 | G14: 0 | H14: 0 | I14: 5 | J14: 5693 | K14: 6661 | L14: 0 | M14: 0 | N14: https://www.pikelandpropertygroup.com/ | P14: Take pikelandpropertygroup.com to page one with contextual backlinks, premium guest posts, on-page SEO, local SEO, custom web development, SaaS tools plus automation tools — sustained DR/DA/TF uplift for every sector. | R14: https://pikelandpropertygroup.com/ | S14: 301 | T14: text | U14: TRUE | V14: FALSE | W14: TRUE | X14: FALSE | Y14: FALSE | Z14: FALSE | AA14: TRUE | AD14: pagefound | AE14: 46195.465 | AF14: 46224.675 | AI14: Article > Opinion | AJ14: Internet > Web services > SEO and marketing; Business > Marketing > Marketing; Government > Legal
A15: seocartly.shop — The 120-Day Traffic Services Case Study for Financial Advisory — Placements, Anchors, Rankings Before and After | B15: https://seocartly.shop/a3dl99t-build-unstoppable-law-firm-serp-local-seo-crowd-links-traffic-playbook/ | C15: en | E15: 200 | F15: 0.7 | G15: 0 | H15: 0 | I15: 6 | J15: 5175 | K15: 6070 | L15: 0 | M15: 0 | N15: https://www.pikelandpropertygroup.com/ | P15: Boost pikelandpropertygroup.com using high-DR backlinks, editorial guest posts, on-page SEO, local SEO, web development, SaaS tools and automation tools for sustained DR/DA/TF uplift with full transparency. | R15: https://pikelandpropertygroup.com/ | S15: 301 | T15: text | U15: TRUE | V15: FALSE | W15: TRUE | X15: FALSE | Y15: FALSE | Z15: FALSE | AA15: TRUE | AD15: pagefound | AE15: 46201.9 | AF15: 46229.932 | AI15: Article > Research | AJ15: Business > Marketing > Marketing; Internet > Web services > SEO and marketing; Finance > Management
A16: Ranking Velocity Blueprint for SaaS — How to Rank Using Guest Posts and Tiered Link Building — linkwares.shop | B16: https://linkwares.shop/qayi9jj-45-day-press-release-links-case-study-law-firm-placements-anchors-rankings/ | C16: en | E16: 200 | F16: 0.8 | G16: 0 | H16: 0 | I16: 8 | J16: 6204 | K16: 7245 | L16: 0 | M16: 0 | N16: https://www.pikelandpropertygroup.com/ | P16: Grow pikelandpropertygroup.com with guest posts, backlinks, on-page and local SEO, web development, SaaS tools and workflow automation tools — balanced DR/DA/TF growth for any business size. | R16: https://pikelandpropertygroup.com/ | S16: 301 | T16: text | U16: TRUE | V16: FALSE | W16: TRUE | X16: FALSE | Y16: FALSE | Z16: FALSE | AA16: TRUE | AD16: pagefound | AE16: 46194.696 | AF16: 46223.121 | AI16: Article > Guide | AJ16: Internet > Web services > SEO and marketing; Business > Marketing > Marketing
A17: seoagency.sale — Rank on Page One, Faster — Contextual Dofollow Links Google Values (Update-Safe, DR/DA/TF Up) | B17: https://seoagency.sale/d5qujh-rank-on-page-1-with-seo-and-backlinks/ | C17: en | E17: 200 | F17: 30 | G17: 0 | H17: 0 | I17: 2 | J17: 8232 | K17: 9501 | L17: 0 | M17: 0 | N17: https://www.pikelandpropertygroup.com/ | P17: pikelandpropertygroup.com — rank faster — clean PBN mix; grow Moz DA. | Visit Buyseolink.com for any Query | R17: https://pikelandpropertygroup.com/ | S17: 301 | T17: text | U17: TRUE | V17: FALSE | W17: TRUE | X17: FALSE | Y17: FALSE | Z17: FALSE | AA17: TRUE | AD17: pagefound | AE17: 46012.551 | AF17: 46230.366 | AI17: Listing > Service | AJ17: Internet > Web services > SEO and marketing; Business > Marketing > Marketing
A18: ✅ Website Stats 📊 | B18: https://optimizeflow.top/stats/50887 | C18: en | E18: 200 | F18: 41 | G18: 0 | H18: 0 | I18: 0 | J18: 3702 | K18: 4156 | L18: 0 | M18: 0 | N18: https://www.pikelandpropertygroup.com/ | O18: Homepage | P18: pikelandpropertygroup.com | Q18: &nbsp | R18: https://pikelandpropertygroup.com/ | S18: 301 | T18: text | U18: FALSE | V18: TRUE | W18: TRUE | X18: FALSE | Y18: FALSE | Z18: FALSE | AA18: TRUE | AD18: pagefound | AE18: 46058.975 | AF18: 46116.956 | AI18: Listing collection > Business | AJ18: Internet > Web services > Analytics; Reference
A19: From DR 2 to Full Recovery in Legal — The 30-Day Strategy Built Entirely on DR Boost Services — Explaining measurable performance checkpoints, provider evaluation criteria, and competitive search-positioning lessons — BBF101229 | B19: https://organicrankdirect.shop/bbf101229-high-da-guest-posts-grew-domain-authority-past-dr30-law-firm-money-site-every-dollar-ranking-tracked-measurable-results-blueprint-research-execution-and-analysis-for-reliable-page-one-progress/ | C19: en | E19: 200 | F19: 0 | G19: 0 | H19: 0 | I19: 0 | J19: 6729 | K19: 7851 | L19: 0 | M19: 0 | N19: https://www.pikelandpropertygroup.com/ | P19: Everything pikelandpropertygroup.com needs: contextual backlinks, premium guest posts, on-page SEO, local SEO, custom web development, SaaS tools plus automation tools — a measurable DR/DA/TF boost across any niche. The strategy also covers competitor research, natural anchor distribution, quality verification, and clear monthly performance reporting. · bbf101229 | R19: https://pikelandpropertygroup.com/ | S19: 301 | T19: text | U19: TRUE | V19: FALSE | W19: TRUE | X19: FALSE | Y19: FALSE | Z19: FALSE | AA19: TRUE | AD19: pagefound | AE19: 46224.298 | AF19: 46224.298 | AI19: Article > Guide | AJ19: Business > Marketing > Marketing; Jobs and education > Education > Certification; Internet > Web services > SEO and marketing; Government > Legal
A20: The 120-Day Traffic Services Case Study for Financial Advisory — Placements, Anchors, Rankings Before and After — seoprime.shop | B20: https://seoprime.shop/a3dl99t-build-unstoppable-law-firm-serp-local-seo-crowd-links-traffic-playbook/ | C20: en | E20: 200 | F20: 0.7 | G20: 0 | H20: 0 | I20: 0 | J20: 5183 | K20: 6067 | L20: 0 | M20: 0 | N20: https://www.pikelandpropertygroup.com/ | P20: Boost pikelandpropertygroup.com using high-DR backlinks, editorial guest posts, on-page SEO, local SEO, web development, SaaS tools and automation tools for sustained DR/DA/TF uplift with full transparency. | R20: https://pikelandpropertygroup.com/ | S20: 301 | T20: text | U20: TRUE | V20: FALSE | W20: TRUE | X20: FALSE | Y20: FALSE | Z20: FALSE | AA20: TRUE | AD20: linkfound | AE20: 46205.846 | AF20: 46219.85 | AI20: Article > Research | AJ20: Business > Marketing > Marketing; Internet > Web services > SEO and marketing; Finance > Management > Portfolio
A21: How I Used Guest Posts and recovered lost traffic fully for My Law Firm Site — Month-by-Month Progress Documentation — backlinkmart.shop | B21: https://backlinkmart.shop/i9y7o5a-30-day-local-seo-journey-b2b-page3-to-10x-traffic/ | C21: en | E21: 200 | F21: 0.7 | G21: 0 | H21: 0 | I21: 7 | J21: 8298 | K21: 9740 | L21: 0 | M21: 0 | N21: https://www.pikelandpropertygroup.com/ | P21: Everything pikelandpropertygroup.com needs: high-DR backlinks, editorial guest posts, on-page SEO, local SEO, web development, SaaS tools and automation tools — real DR/DA/TF improvement in competitive markets. | R21: https://pikelandpropertygroup.com/ | S21: 301 | T21: text | U21: TRUE | V21: FALSE | W21: TRUE | X21: FALSE | Y21: FALSE | Z21: FALSE | AA21: TRUE | AD21: pagefound | AE21: 46196.163 | AF21: 46224.217 | AI21: Article > Guide | AJ21: Internet > Web services > SEO and marketing; Government > Legal > Services; Business
A22: linkstock.shop — How I Used Authority Link Packages and recovered from a Google penalty in 60 days for My Fintech Site — Month-by-Month Progress Documentation | B22: https://linkstock.shop/ad5l39m-used-traffic-services-doubled-organic-revenue-90-days-saas-site-month-by-month-progress/ | C22: en | E22: 200 | F22: 0.7 | G22: 0 | H22: 0 | I22: 0 | J22: 8298 | K22: 9728 | L22: 0 | M22: 0 | N22: https://www.pikelandpropertygroup.com/ | P22: Boost pikelandpropertygroup.com using guest posts and backlinks, on-page SEO, local SEO, web development, SaaS integrations and automation tools for rising DR/DA/TF scores with relevance-first placements. | R22: https://pikelandpropertygroup.com/ | S22: 301 | T22: text | U22: TRUE | V22: FALSE | W22: TRUE | X22: FALSE | Y22: FALSE | Z22: FALSE | AA22: TRUE | AD22: pagefound | AE22: 46204.402 | AF22: 46232.47 | AI22: Article > Guide | AJ22: Internet > Web services > SEO and marketing; Finance > Management > Portfolio; Business > Marketing > Marketing
A23: The Flow Backlink Strategy That Worked for My New Website From the Very First Month — seorankflow.shop | B23: https://seorankflow.shop/du3olt6-consistent-flow-link-building-result-095-page-one-any-niche-worldwide/ | C23: en | E23: 200 | F23: 54 | G23: 0 | H23: 0 | I23: 10 | J23: 8299 | K23: 9741 | L23: 0 | M23: 0 | N23: https://www.pikelandpropertygroup.com/ | P23: Flow DR improvement for pikelandpropertygroup.com with genuine high-authority referring domain links | R23: https://pikelandpropertygroup.com/ | S23: 301 | T23: text | U23: TRUE | V23: FALSE | W23: TRUE | X23: FALSE | Y23: FALSE | Z23: FALSE | AA23: TRUE | AD23: pagefound | AE23: 46195.999 | AF23: 46224.459 | AI23: Article > Guide | AJ23: Internet > Web services > SEO and marketing; Business > Marketing > Marketing
A24: Categories Blumen | Free pdf textbooks download online | B24: https://www.pdfbookee.com/category/blumen/ | C24: en | E24: 200 | F24: 0 | G24: 0 | H24: 0 | I24: 0 | J24: 9 | K24: 10 | L24: 0 | M24: 0 | N24: https://www.pikelandpropertygroup.com/ | P24: Download | T24: text | U24: TRUE | V24: FALSE | W24: FALSE | X24: FALSE | Y24: FALSE | Z24: FALSE | AA24: TRUE | AD24: linkfound | AE24: 46211.658 | AF24: 46211.658
A25: Where to buy 🚀 aged domains and backlinks 🔥 | 1204-6378 | B25: https://wonvision.com/1add20ae4edb6e37d8ff4b4d2677f240-l/ | C25: en | D25: wordpress | E25: 200 | F25: 0.8 | G25: 0 | H25: 0 | I25: 0 | J25: 9169 | K25: 9997 | L25: 0 | M25: 0 | N25: https://www.pikelandpropertygroup.com/ | O25: pikelandia.com pikelandmotors.com | P25: pikelandpropertygroup.com | Q25: pikelandscape.com pikelandschools.com | R25: https://pikelandpropertygroup.com/ | S25: 301 | T25: text | U25: TRUE | V25: FALSE | W25: FALSE | X25: FALSE | Y25: FALSE | Z25: FALSE | AA25: TRUE | AD25: linkfound | AE25: 46164.877 | AF25: 46164.877 | AI25: Listing > Product | AJ25: Internet > Web services > SEO and marketing
A26: 👲 Domain Report 👲 | B26: https://atomizelink.icu/report/50888 | C26: en | E26: 200 | F26: 43 | G26: 0 | H26: 0 | I26: 0 | J26: 3701 | K26: 4156 | L26: 0 | M26: 0 | N26: https://www.pikelandpropertygroup.com/ | O26: Homepage | P26: pikelandpropertygroup.com | Q26: &nbsp | R26: https://pikelandpropertygroup.com/ | S26: 301 | T26: text | U26: FALSE | V26: TRUE | W26: TRUE | X26: FALSE | Y26: FALSE | Z26: FALSE | AA26: TRUE | AD26: pagefound | AE26: 46018.703 | AF26: 46131.869 | AI26: Site page > Services | AJ26: Internet > Web services > Development
A27: Link Growth Source — A trusted information and service source for authority link acquisition, referral visibility and ranking growth for better keyword positions and lasting digital authority — Do PBN Backlinks Still Work in 2025 for Healthcare Websites? I Tested 10 Placements and Tracked Every Move — Explaining actionable ranking improvements, provider evaluation criteria, and lasting traffic-growth insights | B27: https://linkgrowthsource.shop/f6b960faf-ranking-recovery-blueprint-medical-rank-using-authority-link-packages-local-seo-step-by-step-strategy-research-execution-and-analysis-for-reliable-page-one-progress/ | C27: en | E27: 200 | F27: 0 | G27: 0 | H27: 0 | I27: 0 | J27: 6729 | K27: 7855 | L27: 0 | M27: 0 | N27: https://www.pikelandpropertygroup.com/ | P27: Power up pikelandpropertygroup.com: contextual backlinks, premium guest posts, on-page SEO, local SEO, custom web development, SaaS tools plus automation tools for DR/DA/TF that climbs steadily with proven results. The service also includes technical review, content alignment, backlink-quality screening, conversion considerations, and transparent milestone reporting. · Link Growth Source — A ... | R27: https://pikelandpropertygroup.com/ | S27: 301 | T27: text | U27: TRUE | V27: FALSE | W27: TRUE | X27: FALSE | Y27: FALSE | Z27: FALSE | AA27: TRUE | AD27: linkfound | AE27: 46227.66 | AF27: 46227.66 | AI27: Article > Guide | AJ27: Internet > Web services > SEO and marketing; Health > Medical services; Business
A28: seomart.shop — The 120-Day Traffic Services Case Study for Financial Advisory — Placements, Anchors, Rankings Before and After | B28: https://seomart.shop/a3dl99t-build-unstoppable-law-firm-serp-local-seo-crowd-links-traffic-playbook/ | C28: en | E28: 200 | F28: 0.8 | G28: 0 | H28: 0 | I28: 0 | J28: 5174 | K28: 6071 | L28: 0 | M28: 0 | N28: https://www.pikelandpropertygroup.com/ | P28: Boost pikelandpropertygroup.com using high-DR backlinks, editorial guest posts, on-page SEO, local SEO, web development, SaaS tools and automation tools for sustained DR/DA/TF uplift with full transparency. | R28: https://pikelandpropertygroup.com/ | S28: 301 | T28: text | U28: TRUE | V28: FALSE | W28: TRUE | X28: FALSE | Y28: FALSE | Z28: FALSE | AA28: TRUE | AD28: pagefound | AE28: 46204.92 | AF28: 46232.963 | AI28: Article > Research | AJ28: Business > Marketing > Marketing; Internet > Web services > SEO and marketing; Finance > Management
A29: How Crowd Links restored rankings after an algorithm update for My Dental Money Site — Every Dollar Spent, Every Ranking Gained, Tracked — Complete With clear planning and execution details, realistic outcome expectations, and competitive search-positioning lessons — Rank SEO Masters — Experienced specialists in ranking strategy, technical optimization and authority signals for reliable rankings, stronger authority and organic reach | B29: https://rankseomasters.shop/f89672fda-editorial-links-took-every-keyword-page1-ymyl-money-site-every-dollar-ranking-tracked-detailed-campaign-breakdown-budget-links-and-content-for-higher-search-visibility/ | C29: en | E29: 200 | F29: 0 | G29: 0 | H29: 0 | I29: 0 | J29: 6729 | K29: 7855 | L29: 0 | M29: 0 | N29: https://www.pikelandpropertygroup.com/ | P29: Power up pikelandpropertygroup.com: guest posts, backlinks, on-page and local SEO, web development, SaaS tools and workflow automation tools for a noticeable DR/DA/TF rise for local or global targets. Results are supported by relevant placements, sensible link velocity, documented checks, competitor comparisons, and clear evidence of progress. · Rank SEO Masters — Experienced specialists in ... | R29: https://pikelandpropertygroup.com/ | S29: 301 | T29: text | U29: TRUE | V29: FALSE | W29: TRUE | X29: FALSE | Y29: FALSE | Z29: FALSE | AA29: TRUE | AD29: linkfound | AE29: 46226.909 | AF29: 46226.909 | AI29: Article > Guide | AJ29: Internet > Web services > SEO and marketing; Business > Marketing > Marketing
A30: seolinkkart.shop — The 120-Day Traffic Services Case Study for Financial Advisory — Placements, Anchors, Rankings Before and After | B30: https://seolinkkart.shop/a3dl99t-build-unstoppable-law-firm-serp-local-seo-crowd-links-traffic-playbook/ | C30: en | E30: 200 | F30: 0.8 | G30: 0 | H30: 0 | I30: 0 | J30: 5173 | K30: 6070 | L30: 0 | M30: 0 | N30: https://www.pikelandpropertygroup.com/ | P30: Boost pikelandpropertygroup.com using high-DR backlinks, editorial guest posts, on-page SEO, local SEO, web development, SaaS tools and automation tools for sustained DR/DA/TF uplift with full transparency. | R30: https://pikelandpropertygroup.com/ | S30: 301 | T30: text | U30: TRUE | V30: FALSE | W30: TRUE | X30: FALSE | Y30: FALSE | Z30: FALSE | AA30: TRUE | AD30: pagefound | AE30: 46204.354 | AF30: 46232.356 | AI30: Article > Research | AJ30: Internet > Web services > SEO and marketing; Business > Marketing > Marketing; Finance
A31: The 60-Day SERP Climb for Financial Advisory — How I Combined Sidebar Links and Traffic Services to Reach Position 1 — Covering hands-on strategy notes, provider evaluation criteria, and durable ranking strategies — BF177064C | B31: https://pageseopartners.shop/bf177064c-stacked-on-page-seo-dr-boost-services-real-estate-dual-strategy-doubled-ranking-speed-advanced-growth-framework-mistakes-risks-and-solutions-for-stronger-domain-authority/ | C31: en | E31: 200 | F31: 0 | G31: 0 | H31: 0 | I31: 0 | J31: 6721 | K31: 7846 | L31: 0 | M31: 0 | N31: https://www.pikelandpropertygroup.com/ | P31: pikelandpropertygroup.com: high-quality backlinks, guest posts, on-page and local SEO, custom web development, SaaS tools and automation tools, all driving long-term DR/DA/TF gains with full transparency. Every campaign includes niche-relevance checks, diversified anchor planning, placement review, and transparent progress tracking. · bf177064c | R31: https://pikelandpropertygroup.com/ | S31: 301 | T31: text | U31: TRUE | V31: FALSE | W31: TRUE | X31: FALSE | Y31: FALSE | Z31: FALSE | AA31: TRUE | AD31: pagefound | AE31: 46226.012 | AF31: 46226.012 | AI31: Article > Guide | AJ31: Internet > Web services > SEO and marketing; Finance > Management > Portfolio; Business > Marketing > Marketing
A32: ranktrove.shop — The 120-Day Traffic Services Case Study for Financial Advisory — Placements, Anchors, Rankings Before and After | B32: https://ranktrove.shop/a3dl99t-build-unstoppable-law-firm-serp-local-seo-crowd-links-traffic-playbook/ | C32: en | E32: 200 | F32: 0.7 | G32: 0 | H32: 0 | I32: 0 | J32: 5175 | K32: 6070 | L32: 0 | M32: 0 | N32: https://www.pikelandpropertygroup.com/ | P32: Boost pikelandpropertygroup.com using high-DR backlinks, editorial guest posts, on-page SEO, local SEO, web development, SaaS tools and automation tools for sustained DR/DA/TF uplift with full transparency. | R32: https://pikelandpropertygroup.com/ | S32: 301 | T32: text | U32: TRUE | V32: FALSE | W32: TRUE | X32: FALSE | Y32: FALSE | Z32: FALSE | AA32: TRUE | AD32: pagefound | AE32: 46204.402 | AF32: 46232.466 | AI32: Article > Research | AJ32: Business > Marketing > Marketing; Internet > Web services > SEO and marketing; Finance > Management > Portfolio
A33: The 18-Month SERP Climb for SaaS — How I Combined Blogroll Links and High-DA Guest Posts to Reach Position 1 — Explaining actionable ranking improvements, common mistakes to avoid, and future campaign planning — 6E724A3AE — Search Rank Builders — Growth builders specializing in keyword rankings, search visibility and competitive SEO performance to turn search visibility into consistent website growth | B33: https://searchrankbuilders.shop/6e724a3ae-topical-authority-blueprint-financial-advisory-rank-using-tiered-link-building-dofollow-backlinks-measurable-results-blueprint-research-execution-and-analysis-for-consistent-traffic-growth/ | C33: en | E33: 200 | F33: 0 | G33: 0 | H33: 0 | I33: 0 | J33: 6721 | K33: 7844 | L33: 0 | M33: 0 | N33: https://www.pikelandpropertygroup.com/ | P33: Strengthen pikelandpropertygroup.com through guest posts and backlinks, on-page SEO, local SEO, web development, SaaS integrations and automation tools for a measurable DR/DA/TF boost across any niche. Every delivery follows a structured plan for content relevance, link diversity, authority checks, traffic measurement, and ongoing optimization. · 6e724a3ae | R33: https://pikelandpropertygroup.com/ | S33: 301 | T33: text | U33: TRUE | V33: FALSE | W33: TRUE | X33: FALSE | Y33: FALSE | Z33: FALSE | AA33: TRUE | AD33: linkfound | AE33: 46224.583 | AF33: 46224.583 | AI33: Article > Guide | AJ33: Internet > Web services > SEO and marketing; Business
A34: The 120-Day Traffic Services Case Study for Financial Advisory — Placements, Anchors, Rankings Before and After — seocrate.shop | B34: https://seocrate.shop/a3dl99t-build-unstoppable-law-firm-serp-local-seo-crowd-links-traffic-playbook/ | C34: en | E34: 200 | F34: 0.7 | G34: 0 | H34: 0 | I34: 0 | J34: 5175 | K34: 6065 | L34: 0 | M34: 0 | N34: https://www.pikelandpropertygroup.com/ | P34: Boost pikelandpropertygroup.com using high-DR backlinks, editorial guest posts, on-page SEO, local SEO, web development, SaaS tools and automation tools for sustained DR/DA/TF uplift with full transparency. | R34: https://pikelandpropertygroup.com/ | S34: 301 | T34: text | U34: TRUE | V34: FALSE | W34: TRUE | X34: FALSE | Y34: FALSE | Z34: FALSE | AA34: TRUE | AD34: pagefound | AE34: 46192.325 | AF34: 46220.345 | AI34: Article > Research | AJ34: Business > Marketing > Marketing; Internet > Web services > SEO and marketing; Finance > Management > Portfolio
A35: rankstash.shop — The 120-Day Traffic Services Case Study for Financial Advisory — Placements, Anchors, Rankings Before and After | B35: https://rankstash.shop/a3dl99t-build-unstoppable-law-firm-serp-local-seo-crowd-links-traffic-playbook/ | C35: en | E35: 200 | F35: 0.7 | G35: 0 | H35: 0 | I35: 3 | J35: 5175 | K35: 6070 | L35: 0 | M35: 0 | N35: https://www.pikelandpropertygroup.com/ | P35: Boost pikelandpropertygroup.com using high-DR backlinks, editorial guest posts, on-page SEO, local SEO, web development, SaaS tools and automation tools for sustained DR/DA/TF uplift with full transparency. | R35: https://pikelandpropertygroup.com/ | S35: 301 | T35: text | U35: TRUE | V35: FALSE | W35: TRUE | X35: FALSE | Y35: FALSE | Z35: FALSE | AA35: TRUE | AD35: pagefound | AE35: 46201.999 | AF35: 46230.034 | AI35: Article > Research | AJ35: Business > Marketing > Marketing; Internet > Web services > SEO and marketing; Finance > Management
A36: ✅ Website Stats 📊 | B36: https://metamagic.top/stats/50888 | C36: en | E36: 200 | F36: 42 | G36: 0 | H36: 0 | I36: 0 | J36: 3700 | K36: 4150 | L36: 0 | M36: 0 | N36: https://www.pikelandpropertygroup.com/ | O36: Homepage | P36: pikelandpropertygroup.com | Q36: &nbsp | R36: https://pikelandpropertygroup.com/ | S36: 301 | T36: text | U36: FALSE | V36: TRUE | W36: TRUE | X36: FALSE | Y36: FALSE | Z36: FALSE | AA36: TRUE | AD36: pagefound | AE36: 46066.139 | AF36: 46066.139 | AI36: Listing collection > Business | AJ36: Internet > Web services > Analytics; Reference
A37: Backlink Builders — Growth builders specializing in editorial backlinks, authority placements and off-page SEO for better keyword positions and lasting digital authority — DR Growth Blueprint for Dental — How to Rank Using DR Boost Services and Traffic Services — Featuring actionable ranking improvements, content and link-quality checks, and long-term organic growth lessons | B37: https://backlinkbuilders.shop/956300d60-best-sidebar-links-medical-2026-compared-15-providers-roi-advanced-growth-framework-data-progress-and-outcomes-for-stronger-domain-authority/ | C37: en | E37: 200 | F37: 0 | G37: 0 | H37: 0 | I37: 0 | J37: 6720 | K37: 7846 | L37: 0 | M37: 0 | N37: https://www.pikelandpropertygroup.com/ | P37: Power up pikelandpropertygroup.com: high-DR backlinks, editorial guest posts, on-page SEO, local SEO, web development, SaaS tools and automation tools for long-term DR/DA/TF gains with editorial standards. We also prioritize topical relevance, clean placement standards, sensible campaign pacing, and reporting that connects work to outcomes. · Backlink Builders — Growth builders specializing in ... | R37: https://pikelandpropertygroup.com/ | S37: 301 | T37: text | U37: TRUE | V37: FALSE | W37: TRUE | X37: FALSE | Y37: FALSE | Z37: FALSE | AA37: TRUE | AD37: pagefound | AE37: 46228.6 | AF37: 46228.6 | AI37: Site page > Services | AJ37: Internet > Web services > SEO and marketing; Business > Marketing > Marketing
A38: Pikeland Property Group | The Org | B38: https://theorg.com/org/pikeland-property-group | C38: en | E38: 200 | F38: 76 | G38: 0 | H38: 98474 | I38: 0 | J38: 5 | K38: 6 | L38: 0 | M38: 0 | N38: https://www.pikelandpropertygroup.com/ | P38: View the website | T38: text | U38: FALSE | V38: FALSE | W38: FALSE | X38: FALSE | Y38: FALSE | Z38: FALSE | AA38: TRUE | AD38: linkfound | AE38: 46191.94 | AF38: 46191.94
A39: 6-Month Blogroll Link Experiment for Automotive — Final Verdict on Whether These Links Are Worth Buying in a Competitive Market — TopLinkRanker — The Agency That Ranks Websites Others Cannot. | B39: https://toplinkranker.shop/1f1h6zd-pbn-links-strategically-hit-targets-photography-portfolio-page1-traffic/ | C39: en | E39: 200 | F39: 53 | G39: 0 | H39: 0 | I39: 0 | J39: 8287 | K39: 9899 | L39: 0 | M39: 0 | N39: https://www.pikelandpropertygroup.com/ | P39: Power pikelandpropertygroup.com with Expert Professional Guest Posting + Dofollow Link Building — Increase Ahrefs Domain Rating DR • Moz Domain Authority DA • Majestic Trust Flow TF Certified — Any Website • Any Niche • Any Language | R39: https://pikelandpropertygroup.com/ | S39: 301 | T39: text | U39: TRUE | V39: FALSE | W39: TRUE | X39: FALSE | Y39: FALSE | Z39: FALSE | AA39: TRUE | AD39: linkfound | AE39: 46153.742 | AF39: 46167.863 | AI39: Article > Review | AJ39: Internet > Web services > SEO and marketing; Business > Marketing > Marketing; Autos > Vehicle shopping
A40: Rank Growth Group — A professional services group for organic ranking growth, keyword visibility and website authority to build trust, visibility and competitive keyword positions — Scaling Blogroll Links for Insurance Agencies — How to Manage Hundreds of Monthly Placements at Quality — Explaining hands-on strategy notes, budget allocation guidance, and safer scaling recommendations | B40: https://rankgrowthgroup.shop/766c2ea96-90-day-homepage-links-journey-insurance-dr5-to-serp-domination-measurable-results-blueprint-quality-checks-and-reporting-for-competitive-serp-results/ | C40: en | E40: 200 | F40: 0 | G40: 0 | H40: 0 | I40: 0 | J40: 6729 | K40: 7855 | L40: 0 | M40: 0 | N40: https://www.pikelandpropertygroup.com/ | P40: Scale pikelandpropertygroup.com with guest posts, backlinks, on-page and local SEO, web development, SaaS tools and workflow automation tools, earning a measurable DR/DA/TF boost tailored to your vertical. Campaign quality is protected through manual review, realistic pacing, diversified sources, accurate reporting, and continuous performance checks. · Rank Growth Group — A professional ... | R40: https://pikelandpropertygroup.com/ | S40: 301 | T40: text | U40: TRUE | V40: FALSE | W40: TRUE | X40: FALSE | Y40: FALSE | Z40: FALSE | AA40: TRUE | AD40: pagefound | AE40: 46227.002 | AF40: 46227.002 | AI40: Article > Guide | AJ40: Internet > Web services > SEO and marketing; Business > Marketing > Marketing
...

Sheet Unique Anchor
A1: Anchor | B1: Count
A2: {=UNIQUE(Backlinks!P2:P179)} -> Visit Website | B2: =COUNTIF(Backlinks!P$2:P$179,"="&A2) -> 1
A3: pikelandpropertygroup.com | B3: =COUNTIF(Backlinks!P$2:P$179,"="&A3) -> 32
A4: JOIN OUR TELEGRAM https://t.me/s/darksidelinks | B4: =COUNTIF(Backlinks!P$2:P$179,"="&A4) -> 12
A5: Boost pikelandpropertygroup.com using high-DR backlinks, editorial guest posts, on-page SEO, local SEO, web development, SaaS tools and automation tools for sustained DR/DA/TF uplift with full transparency. | B5: =COUNTIF(Backlinks!P$2:P$179,"="&A5) -> 39
A6: Everything pikelandpropertygroup.com needs: guest posts and backlinks, on-page SEO, local SEO, web development, SaaS integrations and automation tools — a strong DR/DA/TF increase worldwide. The strategy also covers competitor research, natural anchor distribution, quality verification, and clear monthly performance reporting. · Site Rank Service — Managed professional services for site-wide ... | B6: =COUNTIF(Backlinks!P$2:P$179,"="&A6) -> 1
A7: Power up pikelandpropertygroup.com: guest posts, backlinks, on-page and local SEO, web development, SaaS tools and workflow automation tools for a clear DR/DA/TF lift in any language. Every delivery follows a structured plan for content relevance, link diversity, authority checks, traffic measurement, and ongoing optimization. · Site Rank Builders — Growth builders specializing in site-wide ... | B7: =COUNTIF(Backlinks!P$2:P$179,"="&A7) -> 1
A8: Professional backlinks for pikelandpropertygroup.com from agency that built authority for 400 websites | B8: =COUNTIF(Backlinks!P$2:P$179,"="&A8) -> 1
A9: pikelandpropertygroup.com gets guest posts and backlinks, on-page SEO, local SEO, web development, SaaS integrations and automation tools, together driving a noticeable DR/DA/TF rise with proven results. The complete process includes website review, competitor benchmarking, anchor-risk control, placement validation, and practical growth recommendations. · Top Rank Company — A full-service ... | B9: =COUNTIF(Backlinks!P$2:P$179,"="&A9) -> 1
A10: Take pikelandpropertygroup.com to page one with contextual backlinks, premium guest posts, on-page SEO, local SEO, custom web development, SaaS tools plus automation tools — sustained DR/DA/TF uplift for every sector. | B10: =COUNTIF(Backlinks!P$2:P$179,"="&A10) -> 6
A11: Grow pikelandpropertygroup.com with guest posts, backlinks, on-page and local SEO, web development, SaaS tools and workflow automation tools — balanced DR/DA/TF growth for any business size. | B11: =COUNTIF(Backlinks!P$2:P$179,"="&A11) -> 1
A12: pikelandpropertygroup.com — rank faster — clean PBN mix; grow Moz DA. | Visit Buyseolink.com for any Query | B12: =COUNTIF(Backlinks!P$2:P$179,"="&A12) -> 1
A13: Everything pikelandpropertygroup.com needs: contextual backlinks, premium guest posts, on-page SEO, local SEO, custom web development, SaaS tools plus automation tools — a measurable DR/DA/TF boost across any niche. The strategy also covers competitor research, natural anchor distribution, quality verification, and clear monthly performance reporting. · bbf101229 | B13: =COUNTIF(Backlinks!P$2:P$179,"="&A13) -> 1
A14: Everything pikelandpropertygroup.com needs: high-DR backlinks, editorial guest posts, on-page SEO, local SEO, web development, SaaS tools and automation tools — real DR/DA/TF improvement in competitive markets. | B14: =COUNTIF(Backlinks!P$2:P$179,"="&A14) -> 1
... A94: Scale pikelandpropertygroup.com with backlinks and guest posts, on-page SEO, local SEO, custom web development, SaaS integrations and automation tools, earning long-term DR/DA/TF gains with clean reporting. Each campaign combines strategic research, safe anchor variation, editorial quality control, progress monitoring, and recommendations for the next stage. · Top Rank Service — Managed ... | B94: =COUNTIF(Backlinks!P$2:P$179,"="&A94) -> 1
