Workbook

Sheet 00 How to Use
A1: Bahamas iGaming Competitor Audit — Template & Method
A2: Casino, sportsbook and content audit across three domestic competitors, benchmarked against Paradise Games.
A3: Purpose | B3: This workbook produces a defensible, evidence-based view of how the three largest domestic competitors structure, optimise and merchandise their casino and sportsbook offerings, and where Paradise Games can take share. Every audit point carries a written rationale so the finished document explains not only what was found, but why it matters commercially.
A4: Competitor set | B4: Island Luck, Chances Games and A Sure Win. All are Gaming Board for The Bahamas licensed Gaming House Operators. Paradise Games is audited on the same criteria in every tab so the output is a gap analysis, not just a competitor list.
A5: How to complete | B5: Work tab by tab, one competitor at a time rather than one row at a time. Auditing a single site end to end keeps context intact and is roughly twice as fast as switching between sites per row.
A6: Scoring scale | B6: 0 = absent · 1 = present but poor · 2 = adequate / market standard · 3 = strong, best in market. Enter N/A where a check genuinely does not apply. Scores roll up automatically into the Summary Dashboard.
A7: Evidence rule | B7: Every score needs a finding written beside it. A score without a note is unusable three weeks later and indefensible in a client meeting.
A8: Cells you fill in | B8: All cream-shaded cells. Grey and white cells are the fixed framework and should not be edited unless you are adding audit points.
A9: Adding rows | B9: Insert rows inside the existing block, not below the last row, so the Summary Dashboard formulas continue to cover them.
A10: Tools assumed | B10: Ahrefs or Semrush (keywords, backlinks, share of voice), Screaming Frog (crawl, index, schema, internal links), PageSpeed Insights or CrUX (Core Web Vitals), Google Rich Results Test (schema validation), manual account registration for product and payment checks, and prompts to ChatGPT, Claude, Gemini and Perplexity for AI visibility.
A11: Bahamas context | B11: Domestic online gaming operates under the Gaming Act 2014 through licensed Gaming House Operators. Casinos serve tourists; web shops serve residents. This means the addressable market is domestic, local trust and payment rails matter more than international brand strength, and geo-restriction will distort any competitive data gathered from outside the jurisdiction.
A12: Google Sheets note | B12: Upload to Drive and open with Google Sheets. Dropdowns, filters, conditional formatting and formulas all carry across. Re-apply freeze panes if Sheets does not preserve them.
A14: WORKED EXAMPLE — how a completed row should read (illustrative values only)
A15: Audit point | B15: Individual game page inventory and whether game pages are indexable
A16: Why this matters | B16: Game-name searches are the largest volume block in casino SEO and convert well. An unclaimed long tail is cheap share.
A17: Island Luck — finding / score | B17: 412 indexable game URLs, each with RTP, volatility and provider. Reachable in two clicks from the lobby. Score: 3
A18: Paradise Games (Client) — finding / score | B18: No individual game pages. Games render in a JS lobby with no crawlable URL. Score: 0
A19: Gap / opportunity | B19: Roughly 400 long-tail game queries per month are uncontested by us. Competitor pages are thin on written review copy, so a data table plus a genuine 150-word review beats them on the same URL count.
A20: Priority / action | B20: High — build an indexable game page template with RTP, volatility, provider and review copy; launch with the top 100 titles by lobby popularity.

Sheet 01 Competitor Profiles
A1: Competitor Profiles & Audit Log
A2: Complete this first. It sets the scope, the dates and the baseline metrics every later tab is read against.
A3: Field | B3: Why it is captured | C3: Island Luck | D3: Chances Games | E3: A Sure Win | F3: Paradise Games (Client)
A4: Brand name | B4: Trading name as presented on site. | C4: Island Luck | F4: Paradise Games
A5: Licensed entity | B5: Registered company holding the Gaming House Operator licence.
A6: Primary domain | B6: Root domain audited. | C6: islandluck.com | F6: paradisegames.com
A7: Additional domains / subdomains | B7: Redirects, legacy domains, app landing pages.
A8: Date audited | B8: Fixes the point-in-time context for all findings. | C8: 46238 | D8: 46238 | E8: 46238 | F8: 46238
A9: Auditor | B9: Who completed this pass. | C9: Jacques | D9: Jacques | E9: Jacques | F9: Jacques
A10: Positioning statement | B10: How the brand describes itself in its own words. | C10: The Leading Lottery Retailer & Gaming Lounge In The Bahamas. Operating in over 60 Bahamas islands and cays | F10: An innovative and dynamic gaming organization in The Bahamas specializing in Lottery, Casino and Sports Betting.
A11: Target audience | B11: Who they appear to be built for: age, island, product bias. | C11: Bahamian Bettors; seasoned | D11: Bahamian Bettors; seasoned | E11: Bahamian Bettors; seasoned | F11: Bahamian Bettors; seasoned
A12: Estimated organic traffic (monthly) | B12: Ahrefs or Semrush estimate. Note the tool and date. | C12: TBA | F12: TBA
A13: Estimated organic keywords | B13: Total ranking keywords, all silos. | C13: TBA | F13: TBA
A14: Domain Rating / Authority Score | B14: Note which tool. Do not mix tools across competitors. | C14: TBA | F14: TBA
A15: Referring domains | B15: Total unique linking domains. | C15: 175156 | F15: 19098
A16: Total indexed pages (estimate) | B16: Site: operator or crawl-derived.
A17: Casino URLs indexed | B17: Scale of the casino silo.
A18: Sports URLs indexed | B18: Scale of the sports silo.
A19: Blog / guide URLs indexed | B19: Scale of the content programme.
A20: Physical premises / agent locations | B20: Omnichannel footprint, including Family Islands. | C20: Multiple Locations | F20: Multiple locations
A21: Sportsbook / casino supplier (observed) | B21: Determines product ceiling and market depth.
A22: Headline strengths | B22: Three lines maximum. Written after the tabs are complete.
A23: Headline weaknesses | B23: Three lines maximum. These become our attack points.
A24: Overall threat level (High / Med / Low) | B24: Judgement call combining product, authority and content velocity.

Sheet 02 Technical SEO
A1: Technical SEO
A2: Site-wide technical foundations. These determine whether anything built in the casino and sports silos can actually rank.
A3: Ref | B3: Section | C3: Audit point | D3: Why this matters (rationale for the client) | E3: What good looks like (benchmark) | F3: Island Luck — finding | G3: Score | H3: Chances Games — finding | I3: Score | J3: A Sure Win — finding | K3: Score | L3: Paradise Games (Client) — finding | M3: Score | N3: Gap / opportunity | O3: Priority | P3: Recommended action
A4: T01 | B4: Crawl & Indexation | C4: Indexed page count by silo (site: operator, GSC-style estimate, crawl of XML sitemaps) | D4: Index footprint shows how much of the market a competitor is actually eligible to rank for. A rival with 400 indexed casino URLs versus our 40 is competing on breadth we cannot match without a content programme. | E4: Indexed count broadly matches sitemap count. No large gap between submitted and indexed, which would signal quality or crawl budget problems.
A5: T02 | B5: Crawl & Indexation | C5: robots.txt directives and blocked paths | D5: Reveals what the competitor deliberately hides (staging, filtered game paths, affiliate parameters) and where they are wasting or protecting crawl budget. Their blocks tell us their known problem areas. | E5: Clean, minimal disallows. Sitemap declared. No blocking of CSS/JS. No accidental blocking of money pages.
A6: T03 | B6: Crawl & Indexation | C6: XML sitemap structure, segmentation and lastmod accuracy | D6: Sitemap segmentation (casino / sports / blog) is the fastest way to reverse-engineer a competitor's full URL inventory and content velocity. Accurate lastmod tells us how often they genuinely refresh pages. | E6: Index sitemap plus child sitemaps per silo. Under 50k URLs each. Honest lastmod values that move when content changes.
A7: T04 | B7: Crawl & Indexation | C7: Faceted navigation, filter and sort URL handling | D7: Casino lobbies generate huge parameter bloat. Whoever controls this ranks; whoever does not buries their money pages under thin duplicates. This is the single most common technical failure in iGaming. | E7: Filters use JS state or canonicalised parameters. Only curated, demand-backed filter combinations get an indexable URL.
A8: T05 | B8: Crawl & Indexation | C8: Canonical tag logic across game, provider and league pages | D8: Canonical errors cause the wrong page to rank for the money term. Identifying a competitor's canonical mistakes exposes rankings we can take with a technically clean equivalent page. | E8: Self-referencing canonicals on all indexable pages. Cross-domain canonicals only where intentional.
A9: T06 | B9: Crawl & Indexation | C9: Pagination handling in game lobbies and sports archives | D9: Deep game libraries are often only reachable via infinite scroll, leaving most games uncrawlable. If a competitor's tail games are unindexed, long-tail game-name searches are open to us. | E9: Crawlable paginated links or a browse-all path. Games reachable within three clicks of the lobby.
A10: T07 | B10: Site Speed & Core Web Vitals | C10: LCP, INP and CLS on mobile for homepage, casino lobby and a sports event page | D10: Mobile speed is a ranking and revenue factor in a market where most traffic is mobile and connections are variable across the Family Islands. Slow lobbies also depress deposit conversion. | E10: LCP under 2.5s, INP under 200ms, CLS under 0.1 on mobile 4G throttling.
A11: T08 | B11: Site Speed & Core Web Vitals | C11: Weight and loading strategy of game tiles, odds feeds and third-party scripts | D11: Odds widgets and game aggregator iframes are the heaviest assets in this vertical. How a competitor loads them shows whether their speed advantage is real engineering or just a lighter product. | E11: Lazy-loaded tiles, deferred non-critical scripts, image CDN with WebP or AVIF.
A12: T09 | B12: Site Speed & Core Web Vitals | C12: Hosting, CDN and edge presence relevant to Caribbean latency | D12: Latency from a US-East or European origin is felt in Nassau and Freeport. A competitor on a CDN with regional edge nodes has a structural speed advantage we would need to match at infrastructure level. | E12: CDN with Caribbean or US-East edge coverage. TTFB under 600ms from a Bahamian connection.
A13: T10 | B13: Rendering & JS | C13: Client-side vs server-side rendering of game names, odds and category content | D13: If a competitor's content only exists after JS execution, Google may index an empty shell and AI crawlers almost certainly see nothing. This is a large, quiet opportunity. | E13: Critical content present in raw HTML. SSR or static generation for lobby and category pages.
A14: T11 | B14: Rendering & JS | C14: Whether AI crawlers (GPTBot, ClaudeBot, PerplexityBot, Google-Extended) are allowed and served content | D14: AI assistants are becoming a discovery channel for 'best casino in the Bahamas' type queries. A competitor blocking these bots is ceding that surface entirely. | E14: Bots allowed, served server-rendered content, with clean semantic HTML.
A15: T12 | B15: Site Architecture | C15: Depth of click path from homepage to a game page, league page and guide | D15: Crawl depth correlates with indexation and ranking. A flat architecture pushes authority into the tail; a deep one strands it. | E15: No money page deeper than three clicks. Hub-and-spoke silos with clear parent-child links.
... A22: T19 | B22: Migration & History | C22: Historic domain changes, redirect chains and legacy URLs still live | D22: Directly relevant to our own paradisegames.com migration. Seeing how a competitor handled or fumbled a migration tells us what to avoid and where their equity leaked. | E22: Single-hop 301s, no chains, no orphaned legacy URLs, consistent domain in all internal links.

Sheet 03 Casino Silo
A1: Casino Silo
A2: Casino silo structure, content, product and SEO. The largest revenue silo and the deepest page inventory opportunity.
A3: Ref | B3: Section | C3: Audit point | D3: Why this matters (rationale for the client) | E3: What good looks like (benchmark) | F3: Island Luck — finding | G3: Score | H3: Chances Games — finding | I3: Score | J3: A Sure Win — finding | K3: Score | L3: Paradise Games (Client) — finding | M3: Score | N3: Gap / opportunity | O3: Priority | P3: Recommended action
A4: C01 | B4: Silo Architecture | C4: Casino hub URL and whether it is a true silo parent (/casino/) | D4: The hub is where category authority consolidates. If a competitor has no genuine parent page, their category pages compete as orphans and are beatable with a properly structured silo. | E4: A substantive /casino/ hub linking down to every category, not a bare lobby.
A5: C02 | B5: Silo Architecture | C5: Category page inventory (slots, live casino, table games, jackpots, bingo, instant win, lotto/numbers) | D5: The category set is the map of their commercial coverage. Any category they lack is a gap we can own before they notice. | E5: One indexable, content-supported page per commercial category with genuine search demand.
A6: C03 | B6: Silo Architecture | C6: Provider/studio page inventory (Pragmatic Play, Evolution, Hacksaw, Play'n GO etc.) | D6: Provider searches carry high commercial intent from players who already know what they want. Provider pages are also the easiest scalable content play in casino SEO. | E6: A page per major provider, with the provider's game library, an accurate studio profile and internal links to top titles.
A7: C04 | B7: Silo Architecture | C7: Individual game page inventory and whether game pages are indexable | D7: Game-name searches are the largest volume block in casino SEO and convert well. If a competitor has no indexable game pages, the entire long tail is unclaimed. | E7: Indexable page per game with RTP, volatility, paylines, provider, demo where permitted, and a written review.
A8: C05 | B8: Silo Architecture | C8: Depth and quality of internal linking between hub, category, provider and game pages | D8: Internal linking is how authority reaches the tail. A competitor with a strong hub but no downward links is leaving their own inventory unranked. | E8: Contextual and modular links flowing hub to category to provider to game, and back up.
A9: C06 | B9: Page Content | C9: Word count, content placement (above/below the lobby) and genuine informational depth on category pages | D9: Establishes the content bar we need to clear. Placement also shows how they balance SEO copy against player experience, which is the perennial tension in casino pages. | E9: 500 to 1,200 words of useful, non-padded copy, placed below the game grid so it never delays play.
A10: C07 | B10: Page Content | C10: Uniqueness of copy across categories and providers (templated vs bespoke) | D10: Templated spun copy at scale is a visible weakness. Competitors relying on it are exposed to helpful-content style demotions and are beatable with genuinely differentiated pages. | E10: Each page written to its own angle, with specifics no template could produce.
A11: C08 | B11: Page Content | C11: Presence of game data: RTP, volatility, min/max stake, paylines, release date, demo mode | D11: Structured game facts are the substance behind game-page rankings and are exactly what AI assistants extract when answering 'what is the RTP of X'. Data completeness is a citation advantage. | E11: A consistent data table on every game page, kept accurate and updated.
A12: C09 | B12: Page Content | C12: Editorial signals: named authors, review methodology, last-updated dates, expertise statements | D12: Gambling is a trust-sensitive vertical. Named, credentialed authorship and a stated review process are the E-E-A-T levers most operators ignore and the cheapest differentiator available. | E12: Bylines with real bios, a published review methodology, visible update dates.
A13: C10 | B13: Keywords & Intent | C13: Top-ranking casino keywords, estimated traffic and which page types earn it | D13: Shows which page archetype actually drives their casino revenue, so we invest where returns are proven rather than where theory says. | E13: Clear picture of top 50 casino keywords per competitor mapped to landing page type.
A14: C11 | B14: Keywords & Intent | C14: Keyword cannibalisation between lobby, category and game pages | D14: Cannibalisation splits their authority and creates unstable rankings we can displace with a single consolidated page. | E14: One page per intent. No two URLs ranking alternately for the same head term.
A15: C12 | B15: Keywords & Intent | C15: Coverage of Bahamian-modified terms (online slots Bahamas, casino games Nassau, play slots Bahamas) | D15: Local modifiers are lower volume but far higher conversion in a domestic-only licensed market. If competitors ignore them, this is cheap ground. | E15: Record in full and compare like-for-like across all four operators.
... A27: C24 | B27: AI & GEO Visibility | C27: Content formatting for extraction: question headings, direct answers, tables, lists, definitions | D27: Extractable formatting is the mechanical requirement for AI citation. Most operator copy is written as marketing prose and cannot be quoted cleanly. | E27: Question-form H2s answered in the first two sentences, supported by tables and defined terms.

Sheet 04 Sports Silo
A1: Sports Silo
A2: Sportsbook silo structure, content, betting product and SEO, weighted to the US-league demand that dominates Bahamian betting interest.
A3: Ref | B3: Section | C3: Audit point | D3: Why this matters (rationale for the client) | E3: What good looks like (benchmark) | F3: Island Luck — finding | G3: Score | H3: Chances Games — finding | I3: Score | J3: A Sure Win — finding | K3: Score | L3: Paradise Games (Client) — finding | M3: Score | N3: Gap / opportunity | O3: Priority | P3: Recommended action
A4: S01 | B4: Silo Architecture | C4: Sportsbook hub URL and its role as silo parent (/sports/ or /sportsbook/) | D4: Same logic as casino: without a genuine parent, sport pages compete as orphans and their authority never compounds. | E4: A substantive hub linking to every sport, with copy explaining the offering.
A5: S02 | B5: Silo Architecture | C5: Sport-level page inventory (basketball, American football, football/soccer, baseball, boxing, MMA, cricket, athletics) | D5: The sport set reveals which audiences they are actually chasing. Given Bahamian demand skews to NBA, NFL, MLB and boxing, coverage gaps in those sports are serious commercial gaps. | E5: An indexable, content-supported page per sport with real betting demand locally.
A6: S03 | B6: Silo Architecture | C6: League and competition page inventory (NBA, NFL, MLB, NCAA, Premier League, Champions League, UFC) | D6: League terms carry the bulk of sports search volume and repeat seasonal demand. League pages are the workhorses of sportsbook SEO. | E6: A page per major league with markets, fixtures, odds and written context.
A7: S04 | B7: Silo Architecture | C7: Team, event and fixture page inventory and whether they are indexable | D7: Team and match pages capture enormous, spiky, low-competition demand around fixtures. Whoever automates these well owns the seasonal tail. | E7: Templated but data-rich team and fixture pages generated programmatically, with noindex on dead events handled deliberately.
A8: S05 | B8: Silo Architecture | C8: Handling of expired events and seasonal pages after the fixture passes | D8: Poor expiry handling creates thousands of thin, dead URLs that drag on site quality. Good handling recycles authority season to season. | E8: Persistent evergreen URLs per fixture matchup or clean 301s, never mass 404s.
A9: S06 | B9: Page Content | C9: Depth and uniqueness of copy on sport and league pages | D9: Sets the content benchmark and exposes templating. Sports copy is usually thinner than casino copy, which makes it easier ground to win. | E9: Record in full and compare like-for-like across all four operators.
A10: S07 | B10: Page Content | C10: Presence of odds, fixtures and live data directly on the landing page | D10: Live data is what the searcher actually wants. Static pages without odds satisfy nothing and rank poorly on engagement, whatever their word count. | E10: Live odds modules server-rendered or progressively enhanced so content is crawlable.
A11: S08 | B11: Page Content | C11: Betting-market explanation content (spreads, moneyline, totals, parlays, props, futures) | D11: Market education captures informational demand and feeds AI answers, while internally linking straight to the relevant market page. It is the bridge between the blog and the sportsbook. | E11: Record in full and compare like-for-like across all four operators.
A12: S09 | B12: Page Content | C12: Editorial signals: named tipsters or analysts, credentials, update cadence | D12: Sports betting content lives or dies on perceived expertise. Named analysts with a track record are a durable trust asset competitors rarely build. | E12: Record in full and compare like-for-like across all four operators.
A13: S10 | B13: Betting Product | C13: Sports and market coverage breadth (number of sports, markets per major fixture) | D13: Market depth is the core sportsbook product comparison and determines how many pages can be legitimately built. It is also the top reason players switch operator. | E13: Record in full and compare like-for-like across all four operators.
A14: S11 | B14: Betting Product | C14: In-play/live betting availability, latency and market count | D14: Live betting drives the majority of modern sportsbook turnover. Absence or weakness here is a structural commercial gap. | E14: Record in full and compare like-for-like across all four operators.
A15: S12 | B15: Betting Product | C15: Bet builder, same-game parlay, cash out, early payout and boosted odds features | D15: Feature parity determines whether ranking traffic converts. These features also generate their own search demand and dedicated landing pages. | E15: Record in full and compare like-for-like across all four operators.
... A25: S22 | B25: AI & GEO Visibility | C25: Structured, extractable formatting on market explainer and how-to-bet content | D25: Explainer content is the most AI-extracted content type in this vertical, making it the highest-leverage format for citation share. | E25: Record in full and compare like-for-like across all four operators.

Sheet 05 Content & Guides
A1: Content & Guides
A2: Blog, how-to and guide content: top-of-funnel capture, E-E-A-T, internal linking into money pages and AI citation readiness.
A3: Ref | B3: Section | C3: Audit point | D3: Why this matters (rationale for the client) | E3: What good looks like (benchmark) | F3: Island Luck — finding | G3: Score | H3: Chances Games — finding | I3: Score | J3: A Sure Win — finding | K3: Score | L3: Paradise Games (Client) — finding | M3: Score | N3: Gap / opportunity | O3: Priority | P3: Recommended action
A4: B01 | B4: Structure & Taxonomy | C4: Location and URL pattern of the content section (/blog/, /guides/, /how-to/, /news/) | D4: Where the content sits determines whether its authority flows into the money silos or sits in a disconnected corner. A /guides/ folder nested under /casino/ passes relevance in a way a detached /blog/ does not. | E4: Content nested within or tightly linked to the relevant silo, with a clear parent hub.
A5: B02 | B5: Structure & Taxonomy | C5: Category and tag architecture, and whether taxonomy pages are indexable | D5: Thin, auto-generated tag archives are a common source of index bloat. Conversely, well-built category hubs rank for topic-level terms in their own right. | E5: Curated category hubs indexed, tag archives noindexed unless deliberately built out.
A6: B03 | B6: Structure & Taxonomy | C6: Publishing volume and cadence over the last 12 months | D6: Cadence indicates resourcing and intent. A rival publishing weekly is compounding topical authority; one publishing quarterly is not defending the space. | E6: Documented post count by month, so we can size the effort needed to overtake them.
A7: B04 | B7: Topic Coverage | C7: How-to and beginner content (how to bet, how to read odds, how slots work, how to deposit) | D7: Beginner content captures the top of the funnel in a market where a large share of players are newly converting from in-person web shops to online play. It is also the most AI-cited format. | E7: Record in full and compare like-for-like across all four operators.
A8: B05 | B8: Topic Coverage | C8: Strategy and tips content (betting strategy, bankroll management, blackjack basic strategy) | D8: Strategy content earns links and repeat visits, and signals genuine expertise rather than pure commercial intent. | E8: Record in full and compare like-for-like across all four operators.
A9: B06 | B9: Topic Coverage | C9: Game and provider explainer content (RTP explained, volatility, progressive jackpots) | D9: These explainers are the definitional content AI assistants quote and are the natural internal-link feeders into game and provider pages. | E9: Record in full and compare like-for-like across all four operators.
A10: B07 | B10: Topic Coverage | C10: Sports previews, predictions and match analysis, and their publishing lead time | D10: Preview content captures pre-event spikes but only if published before demand peaks. Their lead time is a directly copyable operational benchmark. | E10: Record in full and compare like-for-like across all four operators.
A11: B08 | B11: Topic Coverage | C11: Payments, withdrawals and account help content | D11: Payment queries are high-intent and high-anxiety. Whoever answers them clearly reduces support load and captures searchers at the point of deciding to deposit. | E11: Record in full and compare like-for-like across all four operators.
A12: B09 | B12: Topic Coverage | C12: Responsible gambling and player-protection content | D12: Beyond compliance, RG content is a strong trust and E-E-A-T signal that quality raters and AI systems weigh heavily in this vertical. | E12: Record in full and compare like-for-like across all four operators.
A13: B10 | B13: Topic Coverage | C13: Bahamas-specific content (is online gambling legal in the Bahamas, Gaming Board, local payments, local sport) | D13: This is the most defensible content territory available. Global affiliate sites cannot match genuine local knowledge, and domestic searchers explicitly seek it. | E13: Record in full and compare like-for-like across all four operators.
A14: B11 | B14: Content Quality | C14: Average depth, originality and evidence of first-hand experience | D14: Distinguishes rivals producing genuinely useful content from those producing volume. The latter are vulnerable to every quality-focused algorithm update. | E14: Record in full and compare like-for-like across all four operators.
A15: B12 | B15: Content Quality | C15: Author attribution, bios, credentials and editorial policy pages | D15: The clearest E-E-A-T gap in the domestic market. Most operators publish anonymously, so named expertise is a cheap and durable differentiator. | E15: Record in full and compare like-for-like across all four operators.
... A24: B21 | B24: SERP & AI Visibility | C24: Formatting for extraction: summary boxes, direct answers under question headings, tables, defined terms | D24: Format determines extractability more than quality does. This is the concrete change list for our own content brief templates. | E24: Record in full and compare like-for-like across all four operators.

Sheet 06 Off-Page & Authority
A1: Off-Page & Authority
A2: Backlinks, brand demand, local presence and partnerships. Explains whether ranking gaps are content problems or authority problems.
A3: Ref | B3: Section | C3: Audit point | D3: Why this matters (rationale for the client) | E3: What good looks like (benchmark) | F3: Island Luck — finding | G3: Score | H3: Chances Games — finding | I3: Score | J3: A Sure Win — finding | K3: Score | L3: Paradise Games (Client) — finding | M3: Score | N3: Gap / opportunity | O3: Priority | P3: Recommended action
A4: O01 | B4: Backlink Profile | C4: Referring domains, total backlinks and Domain Rating / Authority Score | D4: Sets the authority gap we need to close and tells us whether a ranking gap is content-driven or link-driven. Those two problems need entirely different budgets. | E4: Record in full and compare like-for-like across all four operators.
A5: O02 | B5: Backlink Profile | C5: Referring domain growth trend over 24 months | D5: Trajectory matters more than the current total. Flat growth means their position is defensible by out-earning them; steep growth means an active PR budget we must match. | E5: Record in full and compare like-for-like across all four operators.
A6: O03 | B6: Backlink Profile | C6: Quality mix: local Bahamian media, Caribbean press, iGaming trade, affiliates, directories, spam | D6: Link quality composition reveals their actual strategy. Heavy directory and spam profiles are fragile; earned national press is not. | E6: Record in full and compare like-for-like across all four operators.
A7: O04 | B7: Backlink Profile | C7: Bahamian and Caribbean media links specifically (Tribune 242, Nassau Guardian, Eyewitness News, Our News) | D7: Local press links carry disproportionate relevance for a domestically licensed operator and are realistically obtainable, unlike global iGaming media. | E7: Record in full and compare like-for-like across all four operators.
A8: O05 | B8: Backlink Profile | C8: Top linked pages and what earned those links | D8: Shows which asset types earn links in this market, so our digital PR is aimed at proven formats rather than guesses. | E8: Record in full and compare like-for-like across all four operators.
A9: O06 | B9: Backlink Profile | C9: Anchor text distribution and any evidence of manipulation | D9: Over-optimised anchor profiles signal paid link programmes and carry penalty risk. Useful for assessing how sustainable their position is. | E9: Record in full and compare like-for-like across all four operators.
A10: O07 | B10: Brand & Demand | C10: Branded search volume and its trend | D10: Branded volume is the truest measure of market share and the single best predictor of non-branded ranking strength in this vertical. | E10: Record in full and compare like-for-like across all four operators.
A11: O08 | B11: Brand & Demand | C11: Share of voice across tracked casino and sports keyword sets | D11: Converts individual rankings into a single comparable market position that can be reported to the client month on month. | E11: Record in full and compare like-for-like across all four operators.
A12: O09 | B12: Brand & Demand | C12: Unlinked brand mentions across Bahamian media and forums | D12: Unlinked mentions are the cheapest link acquisition route available and also feed AI entity understanding. | E12: Record in full and compare like-for-like across all four operators.
A13: O10 | B13: Local Presence | C13: Google Business Profiles for physical locations and agent network | D13: With a licensed agent and premises network, local pack visibility is a real acquisition channel that pure-online SEO thinking tends to miss. | E13: Record in full and compare like-for-like across all four operators.
A14: O11 | B14: Local Presence | C14: NAP consistency across directories, social profiles and their own site | D14: Inconsistent NAP suppresses local visibility and confuses entity resolution for both Google and AI systems. | E14: Record in full and compare like-for-like across all four operators.
A15: O12 | B15: Local Presence | C15: Local citation coverage (Bahamas Local, Yellow Pages Bahamas, chamber listings) | D15: Directory citations remain a functioning local ranking factor in smaller markets where they are still actively used. | E15: Record in full and compare like-for-like across all four operators.
... A20: O17 | B20: Affiliate & Partnerships | C20: Whether they run a public affiliate programme and its terms | D20: An affiliate programme is a parallel acquisition channel and a link source. Its absence or presence changes our channel recommendation. | E20: Record in full and compare like-for-like across all four operators.

Sheet 07 Bahamas & Compliance
A1: Bahamas & Compliance
A2: Jurisdiction-specific factors: Gaming Board licensing, responsible gambling, local payment rails, local relevance and geo signals.
A3: Ref | B3: Section | C3: Audit point | D3: Why this matters (rationale for the client) | E3: What good looks like (benchmark) | F3: Island Luck — finding | G3: Score | H3: Chances Games — finding | I3: Score | J3: A Sure Win — finding | K3: Score | L3: Paradise Games (Client) — finding | M3: Score | N3: Gap / opportunity | O3: Priority | P3: Recommended action
A4: L01 | B4: Licensing & Compliance | C4: Gaming Board for The Bahamas licence details displayed, and where | D4: Licensing display is both a legal expectation and the strongest trust signal available in a domestic market. Its prominence differs widely between operators and is easily beaten. | E4: Record in full and compare like-for-like across all four operators.
A5: L02 | B5: Licensing & Compliance | C5: Age verification and 18+ gating on entry and in advertising | D5: A compliance requirement that also affects crawlability. Hard age gates that block crawlers can suppress indexation entirely. | E5: Record in full and compare like-for-like across all four operators.
A6: L03 | B6: Licensing & Compliance | C6: Responsible gambling tools offered (deposit limits, self-exclusion, time-outs, reality checks) | D6: Tool depth is a genuine differentiator with regulators and increasingly with players. It is also content that ranks for its own queries. | E6: Record in full and compare like-for-like across all four operators.
A7: L04 | B7: Licensing & Compliance | C7: KYC and registration flow: documents required, steps, time to first deposit | D7: Registration friction is where ranked traffic is lost. Benchmarking step count gives the client a concrete conversion target. | E7: Record in full and compare like-for-like across all four operators.
A8: L05 | B8: Licensing & Compliance | C8: Geo-restriction handling and messaging for non-Bahamian visitors | D8: Domestic licences do not permit international play. How rivals handle out-of-jurisdiction traffic affects their indexation and how tools crawl them, which distorts naive competitive data. | E8: Record in full and compare like-for-like across all four operators.
A9: L06 | B9: Payments | C9: Local payment methods supported (Sand Dollar, Kanoo, Omni, bank transfer, cash at agent locations, cards) | D9: Payment coverage is the most decisive product factor in this market. Cash-in at agent locations in particular has no online equivalent for competitors without a premises network. | E9: Record in full and compare like-for-like across all four operators.
A10: L07 | B10: Payments | C10: Deposit and withdrawal limits, fees and processing times | D10: Withdrawal speed drives retention and complaint volume, and is a frequent search query in its own right. | E10: Record in full and compare like-for-like across all four operators.
A11: L08 | B11: Payments | C11: Currency handling (BSD/USD) and clarity of presentation | D11: Clear local currency handling removes a friction point and signals a genuinely local product rather than a ported international one. | E11: Record in full and compare like-for-like across all four operators.
A12: L09 | B12: Local Relevance | C12: Use of Bahamian references, imagery, place names and local voice in copy | D12: Local authenticity is the one advantage a domestic operator holds over international affiliates and offshore books. Under-using it is a wasted structural asset. | E12: Record in full and compare like-for-like across all four operators.
A13: L10 | B13: Local Relevance | C13: Coverage of Bahamian numbers, cash pot and asue draw style games | D13: These games are culturally specific and drive daily-habit engagement. They also carry search demand no international competitor will ever target. | E13: Record in full and compare like-for-like across all four operators.
A14: L11 | B14: Local Relevance | C14: Family Islands coverage in content, agent listings and service messaging | D14: Nassau-centric messaging leaves Grand Bahama, Abaco, Eleuthera and Exuma underserved. Local content for those islands is uncontested and reaches genuine demand. | E14: Record in full and compare like-for-like across all four operators.
A15: L12 | B15: Local Relevance | C15: Alignment with local sporting calendar and interests (NBA, NFL, MLB, boxing, athletics, regattas) | D15: Content matched to what Bahamians actually watch converts far better than generic global sports coverage. | E15: Record in full and compare like-for-like across all four operators.
... A19: L16 | B19: Local Technical | C19: Localised NAP, contact numbers and physical addresses in schema and footer | D19: Feeds local pack eligibility and entity confidence for both search engines and AI systems. | E19: Record in full and compare like-for-like across all four operators.

Sheet 08 Feature Matrix
A1: Product & Feature Matrix
A2: Binary and quantitative product comparison. Use Yes / No / Partial, or a number where the feature is a count.
A3: Ref | B3: Category | C3: Feature | D3: Why it matters commercially | E3: Island Luck | F3: Chances Games | G3: A Sure Win | H3: Paradise Games (Client) | I3: Gap note
A4: F01 | B4: Casino Product | C4: Slots library size (count) | D4: Primary breadth comparison and the ceiling on how many game pages can be built.
A5: F02 | B5: Casino Product | C5: Live dealer casino | D5: Highest-margin casino vertical and a major retention driver.
A6: F03 | B6: Casino Product | C6: Table games (blackjack, roulette, baccarat, poker) | D6: Core category demand with distinct search volume.
A7: F04 | B7: Casino Product | C7: Progressive jackpots | D7: Draws aspirational traffic and high-volume branded jackpot searches.
A8: F05 | B8: Casino Product | C8: Instant win / scratch games | D8: Low-friction, high-frequency play that suits mobile-first local users.
A9: F06 | B9: Casino Product | C9: Bingo | D9: Category with its own demand pocket and community retention effect.
A10: F07 | B10: Casino Product | C10: Numbers / cash pot / asue draw | D10: Culturally central to Bahamian domestic gaming and a daily-habit product.
A11: F08 | B11: Casino Product | C11: Lottery and draw-based games | D11: Recurring engagement with predictable, schedulable search demand.
A12: F09 | B12: Casino Product | C12: Demo / free play without registration | D12: Drives free-play long-tail traffic and lowers acquisition friction.
A13: F10 | B13: Casino Product | C13: Exclusive or branded in-house games | D13: Owned titles create branded search demand competitors cannot capture.
A14: F11 | B14: Casino Product | C14: Lobby search, filter and sort | D14: Determines game discovery, session depth and filter-URL SEO exposure.
A15: F12 | B15: Casino Product | C15: Recently played / favourites | D15: Retention feature that increases return-visit frequency.
... A36: F33 | B36: Platform & Account | C36: Responsible gambling tool suite | D36: Compliance expectation and a genuine trust differentiator.

Sheet 09 Summary Dashboard
A1: Summary of Findings
A2: Calculates automatically from the audit tabs. Scores are averages on the 0-3 scale; blanks are ignored until you fill them in.
A3: Area | B3: Section | C3: Island Luck | D3: Chances Games | E3: A Sure Win | F3: Paradise Games (Client) | G3: Client gap vs best competitor
A4: Technical SEO | B4: Crawl & Indexation | C4: =IFERROR(AVERAGEIFS('02 Technical SEO'!$G$4:$G$22,'02 Technical SEO'!$B$4:$B$22,$B4),"") | D4: =IFERROR(AVERAGEIFS('02 Technical SEO'!$I$4:$I$22,'02 Technical SEO'!$B$4:$B$22,$B4),"") | E4: =IFERROR(AVERAGEIFS('02 Technical SEO'!$K$4:$K$22,'02 Technical SEO'!$B$4:$B$22,$B4),"") | F4: =IFERROR(AVERAGEIFS('02 Technical SEO'!$M$4:$M$22,'02 Technical SEO'!$B$4:$B$22,$B4),"") | G4: =IFERROR(F4-MAX(C4:E4),"") -> 0
A5: Technical SEO | B5: Site Speed & Core Web Vitals | C5: =IFERROR(AVERAGEIFS('02 Technical SEO'!$G$4:$G$22,'02 Technical SEO'!$B$4:$B$22,$B5),"") | D5: =IFERROR(AVERAGEIFS('02 Technical SEO'!$I$4:$I$22,'02 Technical SEO'!$B$4:$B$22,$B5),"") | E5: =IFERROR(AVERAGEIFS('02 Technical SEO'!$K$4:$K$22,'02 Technical SEO'!$B$4:$B$22,$B5),"") | F5: =IFERROR(AVERAGEIFS('02 Technical SEO'!$M$4:$M$22,'02 Technical SEO'!$B$4:$B$22,$B5),"") | G5: =IFERROR(F5-MAX(C5:E5),"") -> 0
A6: Technical SEO | B6: Rendering & JS | C6: =IFERROR(AVERAGEIFS('02 Technical SEO'!$G$4:$G$22,'02 Technical SEO'!$B$4:$B$22,$B6),"") | D6: =IFERROR(AVERAGEIFS('02 Technical SEO'!$I$4:$I$22,'02 Technical SEO'!$B$4:$B$22,$B6),"") | E6: =IFERROR(AVERAGEIFS('02 Technical SEO'!$K$4:$K$22,'02 Technical SEO'!$B$4:$B$22,$B6),"") | F6: =IFERROR(AVERAGEIFS('02 Technical SEO'!$M$4:$M$22,'02 Technical SEO'!$B$4:$B$22,$B6),"") | G6: =IFERROR(F6-MAX(C6:E6),"") -> 0
A7: Technical SEO | B7: Site Architecture | C7: =IFERROR(AVERAGEIFS('02 Technical SEO'!$G$4:$G$22,'02 Technical SEO'!$B$4:$B$22,$B7),"") | D7: =IFERROR(AVERAGEIFS('02 Technical SEO'!$I$4:$I$22,'02 Technical SEO'!$B$4:$B$22,$B7),"") | E7: =IFERROR(AVERAGEIFS('02 Technical SEO'!$K$4:$K$22,'02 Technical SEO'!$B$4:$B$22,$B7),"") | F7: =IFERROR(AVERAGEIFS('02 Technical SEO'!$M$4:$M$22,'02 Technical SEO'!$B$4:$B$22,$B7),"") | G7: =IFERROR(F7-MAX(C7:E7),"") -> 0
A8: Technical SEO | B8: Mobile & App | C8: =IFERROR(AVERAGEIFS('02 Technical SEO'!$G$4:$G$22,'02 Technical SEO'!$B$4:$B$22,$B8),"") | D8: =IFERROR(AVERAGEIFS('02 Technical SEO'!$I$4:$I$22,'02 Technical SEO'!$B$4:$B$22,$B8),"") | E8: =IFERROR(AVERAGEIFS('02 Technical SEO'!$K$4:$K$22,'02 Technical SEO'!$B$4:$B$22,$B8),"") | F8: =IFERROR(AVERAGEIFS('02 Technical SEO'!$M$4:$M$22,'02 Technical SEO'!$B$4:$B$22,$B8),"") | G8: =IFERROR(F8-MAX(C8:E8),"") -> 0
A9: Technical SEO | B9: Security & Trust | C9: =IFERROR(AVERAGEIFS('02 Technical SEO'!$G$4:$G$22,'02 Technical SEO'!$B$4:$B$22,$B9),"") | D9: =IFERROR(AVERAGEIFS('02 Technical SEO'!$I$4:$I$22,'02 Technical SEO'!$B$4:$B$22,$B9),"") | E9: =IFERROR(AVERAGEIFS('02 Technical SEO'!$K$4:$K$22,'02 Technical SEO'!$B$4:$B$22,$B9),"") | F9: =IFERROR(AVERAGEIFS('02 Technical SEO'!$M$4:$M$22,'02 Technical SEO'!$B$4:$B$22,$B9),"") | G9: =IFERROR(F9-MAX(C9:E9),"") -> 0
A10: Technical SEO | B10: Migration & History | C10: =IFERROR(AVERAGEIFS('02 Technical SEO'!$G$4:$G$22,'02 Technical SEO'!$B$4:$B$22,$B10),"") | D10: =IFERROR(AVERAGEIFS('02 Technical SEO'!$I$4:$I$22,'02 Technical SEO'!$B$4:$B$22,$B10),"") | E10: =IFERROR(AVERAGEIFS('02 Technical SEO'!$K$4:$K$22,'02 Technical SEO'!$B$4:$B$22,$B10),"") | F10: =IFERROR(AVERAGEIFS('02 Technical SEO'!$M$4:$M$22,'02 Technical SEO'!$B$4:$B$22,$B10),"") | G10: =IFERROR(F10-MAX(C10:E10),"") -> 0
A11: Technical SEO | B11: AREA AVERAGE — Technical SEO | C11: =IFERROR(AVERAGE('02 Technical SEO'!$G$4:$G$22),"") | D11: =IFERROR(AVERAGE('02 Technical SEO'!$I$4:$I$22),"") | E11: =IFERROR(AVERAGE('02 Technical SEO'!$K$4:$K$22),"") | F11: =IFERROR(AVERAGE('02 Technical SEO'!$M$4:$M$22),"") | G11: =IFERROR(F11-MAX(C11:E11),"") -> 0
A12: Casino Silo | B12: Silo Architecture | C12: =IFERROR(AVERAGEIFS('03 Casino Silo'!$G$4:$G$27,'03 Casino Silo'!$B$4:$B$27,$B12),"") | D12: =IFERROR(AVERAGEIFS('03 Casino Silo'!$I$4:$I$27,'03 Casino Silo'!$B$4:$B$27,$B12),"") | E12: =IFERROR(AVERAGEIFS('03 Casino Silo'!$K$4:$K$27,'03 Casino Silo'!$B$4:$B$27,$B12),"") | F12: =IFERROR(AVERAGEIFS('03 Casino Silo'!$M$4:$M$27,'03 Casino Silo'!$B$4:$B$27,$B12),"") | G12: =IFERROR(F12-MAX(C12:E12),"") -> 0
A13: Casino Silo | B13: Page Content | C13: =IFERROR(AVERAGEIFS('03 Casino Silo'!$G$4:$G$27,'03 Casino Silo'!$B$4:$B$27,$B13),"") | D13: =IFERROR(AVERAGEIFS('03 Casino Silo'!$I$4:$I$27,'03 Casino Silo'!$B$4:$B$27,$B13),"") | E13: =IFERROR(AVERAGEIFS('03 Casino Silo'!$K$4:$K$27,'03 Casino Silo'!$B$4:$B$27,$B13),"") | F13: =IFERROR(AVERAGEIFS('03 Casino Silo'!$M$4:$M$27,'03 Casino Silo'!$B$4:$B$27,$B13),"") | G13: =IFERROR(F13-MAX(C13:E13),"") -> 0
A14: Casino Silo | B14: Keywords & Intent | C14: =IFERROR(AVERAGEIFS('03 Casino Silo'!$G$4:$G$27,'03 Casino Silo'!$B$4:$B$27,$B14),"") | D14: =IFERROR(AVERAGEIFS('03 Casino Silo'!$I$4:$I$27,'03 Casino Silo'!$B$4:$B$27,$B14),"") | E14: =IFERROR(AVERAGEIFS('03 Casino Silo'!$K$4:$K$27,'03 Casino Silo'!$B$4:$B$27,$B14),"") | F14: =IFERROR(AVERAGEIFS('03 Casino Silo'!$M$4:$M$27,'03 Casino Silo'!$B$4:$B$27,$B14),"") | G14: =IFERROR(F14-MAX(C14:E14),"") -> 0
A15: Casino Silo | B15: Bonuses & Promotions | C15: =IFERROR(AVERAGEIFS('03 Casino Silo'!$G$4:$G$27,'03 Casino Silo'!$B$4:$B$27,$B15),"") | D15: =IFERROR(AVERAGEIFS('03 Casino Silo'!$I$4:$I$27,'03 Casino Silo'!$B$4:$B$27,$B15),"") | E15: =IFERROR(AVERAGEIFS('03 Casino Silo'!$K$4:$K$27,'03 Casino Silo'!$B$4:$B$27,$B15),"") | F15: =IFERROR(AVERAGEIFS('03 Casino Silo'!$M$4:$M$27,'03 Casino Silo'!$B$4:$B$27,$B15),"") | G15: =IFERROR(F15-MAX(C15:E15),"") -> 0
A16: Casino Silo | B16: Schema & SERP Features | C16: =IFERROR(AVERAGEIFS('03 Casino Silo'!$G$4:$G$27,'03 Casino Silo'!$B$4:$B$27,$B16),"") | D16: =IFERROR(AVERAGEIFS('03 Casino Silo'!$I$4:$I$27,'03 Casino Silo'!$B$4:$B$27,$B16),"") | E16: =IFERROR(AVERAGEIFS('03 Casino Silo'!$K$4:$K$27,'03 Casino Silo'!$B$4:$B$27,$B16),"") | F16: =IFERROR(AVERAGEIFS('03 Casino Silo'!$M$4:$M$27,'03 Casino Silo'!$B$4:$B$27,$B16),"") | G16: =IFERROR(F16-MAX(C16:E16),"") -> 0
A17: Casino Silo | B17: Product & Features | C17: =IFERROR(AVERAGEIFS('03 Casino Silo'!$G$4:$G$27,'03 Casino Silo'!$B$4:$B$27,$B17),"") | D17: =IFERROR(AVERAGEIFS('03 Casino Silo'!$I$4:$I$27,'03 Casino Silo'!$B$4:$B$27,$B17),"") | E17: =IFERROR(AVERAGEIFS('03 Casino Silo'!$K$4:$K$27,'03 Casino Silo'!$B$4:$B$27,$B17),"") | F17: =IFERROR(AVERAGEIFS('03 Casino Silo'!$M$4:$M$27,'03 Casino Silo'!$B$4:$B$27,$B17),"") | G17: =IFERROR(F17-MAX(C17:E17),"") -> 0
A18: Casino Silo | B18: AI & GEO Visibility | C18: =IFERROR(AVERAGEIFS('03 Casino Silo'!$G$4:$G$27,'03 Casino Silo'!$B$4:$B$27,$B18),"") | D18: =IFERROR(AVERAGEIFS('03 Casino Silo'!$I$4:$I$27,'03 Casino Silo'!$B$4:$B$27,$B18),"") | E18: =IFERROR(AVERAGEIFS('03 Casino Silo'!$K$4:$K$27,'03 Casino Silo'!$B$4:$B$27,$B18),"") | F18: =IFERROR(AVERAGEIFS('03 Casino Silo'!$M$4:$M$27,'03 Casino Silo'!$B$4:$B$27,$B18),"") | G18: =IFERROR(F18-MAX(C18:E18),"") -> 0
A19: Casino Silo | B19: AREA AVERAGE — Casino Silo | C19: =IFERROR(AVERAGE('03 Casino Silo'!$G$4:$G$27),"") | D19: =IFERROR(AVERAGE('03 Casino Silo'!$I$4:$I$27),"") | E19: =IFERROR(AVERAGE('03 Casino Silo'!$K$4:$K$27),"") | F19: =IFERROR(AVERAGE('03 Casino Silo'!$M$4:$M$27),"") | G19: =IFERROR(F19-MAX(C19:E19),"") -> 0
A20: Sports Silo | B20: Silo Architecture | C20: =IFERROR(AVERAGEIFS('04 Sports Silo'!$G$4:$G$25,'04 Sports Silo'!$B$4:$B$25,$B20),"") | D20: =IFERROR(AVERAGEIFS('04 Sports Silo'!$I$4:$I$25,'04 Sports Silo'!$B$4:$B$25,$B20),"") | E20: =IFERROR(AVERAGEIFS('04 Sports Silo'!$K$4:$K$25,'04 Sports Silo'!$B$4:$B$25,$B20),"") | F20: =IFERROR(AVERAGEIFS('04 Sports Silo'!$M$4:$M$25,'04 Sports Silo'!$B$4:$B$25,$B20),"") | G20: =IFERROR(F20-MAX(C20:E20),"") -> 0
A21: Sports Silo | B21: Page Content | C21: =IFERROR(AVERAGEIFS('04 Sports Silo'!$G$4:$G$25,'04 Sports Silo'!$B$4:$B$25,$B21),"") | D21: =IFERROR(AVERAGEIFS('04 Sports Silo'!$I$4:$I$25,'04 Sports Silo'!$B$4:$B$25,$B21),"") | E21: =IFERROR(AVERAGEIFS('04 Sports Silo'!$K$4:$K$25,'04 Sports Silo'!$B$4:$B$25,$B21),"") | F21: =IFERROR(AVERAGEIFS('04 Sports Silo'!$M$4:$M$25,'04 Sports Silo'!$B$4:$B$25,$B21),"") | G21: =IFERROR(F21-MAX(C21:E21),"") -> 0
A22: Sports Silo | B22: Betting Product | C22: =IFERROR(AVERAGEIFS('04 Sports Silo'!$G$4:$G$25,'04 Sports Silo'!$B$4:$B$25,$B22),"") | D22: =IFERROR(AVERAGEIFS('04 Sports Silo'!$I$4:$I$25,'04 Sports Silo'!$B$4:$B$25,$B22),"") | E22: =IFERROR(AVERAGEIFS('04 Sports Silo'!$K$4:$K$25,'04 Sports Silo'!$B$4:$B$25,$B22),"") | F22: =IFERROR(AVERAGEIFS('04 Sports Silo'!$M$4:$M$25,'04 Sports Silo'!$B$4:$B$25,$B22),"") | G22: =IFERROR(F22-MAX(C22:E22),"") -> 0
A23: Sports Silo | B23: Keywords & Intent | C23: =IFERROR(AVERAGEIFS('04 Sports Silo'!$G$4:$G$25,'04 Sports Silo'!$B$4:$B$25,$B23),"") | D23: =IFERROR(AVERAGEIFS('04 Sports Silo'!$I$4:$I$25,'04 Sports Silo'!$B$4:$B$25,$B23),"") | E23: =IFERROR(AVERAGEIFS('04 Sports Silo'!$K$4:$K$25,'04 Sports Silo'!$B$4:$B$25,$B23),"") | F23: =IFERROR(AVERAGEIFS('04 Sports Silo'!$M$4:$M$25,'04 Sports Silo'!$B$4:$B$25,$B23),"") | G23: =IFERROR(F23-MAX(C23:E23),"") -> 0
A24: Sports Silo | B24: Promotions | C24: =IFERROR(AVERAGEIFS('04 Sports Silo'!$G$4:$G$25,'04 Sports Silo'!$B$4:$B$25,$B24),"") | D24: =IFERROR(AVERAGEIFS('04 Sports Silo'!$I$4:$I$25,'04 Sports Silo'!$B$4:$B$25,$B24),"") | E24: =IFERROR(AVERAGEIFS('04 Sports Silo'!$K$4:$K$25,'04 Sports Silo'!$B$4:$B$25,$B24),"") | F24: =IFERROR(AVERAGEIFS('04 Sports Silo'!$M$4:$M$25,'04 Sports Silo'!$B$4:$B$25,$B24),"") | G24: =IFERROR(F24-MAX(C24:E24),"") -> 0
A25: Sports Silo | B25: Schema & SERP Features | C25: =IFERROR(AVERAGEIFS('04 Sports Silo'!$G$4:$G$25,'04 Sports Silo'!$B$4:$B$25,$B25),"") | D25: =IFERROR(AVERAGEIFS('04 Sports Silo'!$I$4:$I$25,'04 Sports Silo'!$B$4:$B$25,$B25),"") | E25: =IFERROR(AVERAGEIFS('04 Sports Silo'!$K$4:$K$25,'04 Sports Silo'!$B$4:$B$25,$B25),"") | F25: =IFERROR(AVERAGEIFS('04 Sports Silo'!$M$4:$M$25,'04 Sports Silo'!$B$4:$B$25,$B25),"") | G25: =IFERROR(F25-MAX(C25:E25),"") -> 0
A26: Sports Silo | B26: AI & GEO Visibility | C26: =IFERROR(AVERAGEIFS('04 Sports Silo'!$G$4:$G$25,'04 Sports Silo'!$B$4:$B$25,$B26),"") | D26: =IFERROR(AVERAGEIFS('04 Sports Silo'!$I$4:$I$25,'04 Sports Silo'!$B$4:$B$25,$B26),"") | E26: =IFERROR(AVERAGEIFS('04 Sports Silo'!$K$4:$K$25,'04 Sports Silo'!$B$4:$B$25,$B26),"") | F26: =IFERROR(AVERAGEIFS('04 Sports Silo'!$M$4:$M$25,'04 Sports Silo'!$B$4:$B$25,$B26),"") | G26: =IFERROR(F26-MAX(C26:E26),"") -> 0
A27: Sports Silo | B27: AREA AVERAGE — Sports Silo | C27: =IFERROR(AVERAGE('04 Sports Silo'!$G$4:$G$25),"") | D27: =IFERROR(AVERAGE('04 Sports Silo'!$I$4:$I$25),"") | E27: =IFERROR(AVERAGE('04 Sports Silo'!$K$4:$K$25),"") | F27: =IFERROR(AVERAGE('04 Sports Silo'!$M$4:$M$25),"") | G27: =IFERROR(F27-MAX(C27:E27),"") -> 0
A28: Content & Guides | B28: Structure & Taxonomy | C28: =IFERROR(AVERAGEIFS('05 Content & Guides'!$G$4:$G$24,'05 Content & Guides'!$B$4:$B$24,$B28),"") | D28: =IFERROR(AVERAGEIFS('05 Content & Guides'!$I$4:$I$24,'05 Content & Guides'!$B$4:$B$24,$B28),"") | E28: =IFERROR(AVERAGEIFS('05 Content & Guides'!$K$4:$K$24,'05 Content & Guides'!$B$4:$B$24,$B28),"") | F28: =IFERROR(AVERAGEIFS('05 Content & Guides'!$M$4:$M$24,'05 Content & Guides'!$B$4:$B$24,$B28),"") | G28: =IFERROR(F28-MAX(C28:E28),"") -> 0
A29: Content & Guides | B29: Topic Coverage | C29: =IFERROR(AVERAGEIFS('05 Content & Guides'!$G$4:$G$24,'05 Content & Guides'!$B$4:$B$24,$B29),"") | D29: =IFERROR(AVERAGEIFS('05 Content & Guides'!$I$4:$I$24,'05 Content & Guides'!$B$4:$B$24,$B29),"") | E29: =IFERROR(AVERAGEIFS('05 Content & Guides'!$K$4:$K$24,'05 Content & Guides'!$B$4:$B$24,$B29),"") | F29: =IFERROR(AVERAGEIFS('05 Content & Guides'!$M$4:$M$24,'05 Content & Guides'!$B$4:$B$24,$B29),"") | G29: =IFERROR(F29-MAX(C29:E29),"") -> 0
A30: Content & Guides | B30: Content Quality | C30: =IFERROR(AVERAGEIFS('05 Content & Guides'!$G$4:$G$24,'05 Content & Guides'!$B$4:$B$24,$B30),"") | D30: =IFERROR(AVERAGEIFS('05 Content & Guides'!$I$4:$I$24,'05 Content & Guides'!$B$4:$B$24,$B30),"") | E30: =IFERROR(AVERAGEIFS('05 Content & Guides'!$K$4:$K$24,'05 Content & Guides'!$B$4:$B$24,$B30),"") | F30: =IFERROR(AVERAGEIFS('05 Content & Guides'!$M$4:$M$24,'05 Content & Guides'!$B$4:$B$24,$B30),"") | G30: =IFERROR(F30-MAX(C30:E30),"") -> 0
A31: Content & Guides | B31: Internal Linking | C31: =IFERROR(AVERAGEIFS('05 Content & Guides'!$G$4:$G$24,'05 Content & Guides'!$B$4:$B$24,$B31),"") | D31: =IFERROR(AVERAGEIFS('05 Content & Guides'!$I$4:$I$24,'05 Content & Guides'!$B$4:$B$24,$B31),"") | E31: =IFERROR(AVERAGEIFS('05 Content & Guides'!$K$4:$K$24,'05 Content & Guides'!$B$4:$B$24,$B31),"") | F31: =IFERROR(AVERAGEIFS('05 Content & Guides'!$M$4:$M$24,'05 Content & Guides'!$B$4:$B$24,$B31),"") | G31: =IFERROR(F31-MAX(C31:E31),"") -> 0
A32: Content & Guides | B32: SERP & AI Visibility | C32: =IFERROR(AVERAGEIFS('05 Content & Guides'!$G$4:$G$24,'05 Content & Guides'!$B$4:$B$24,$B32),"") | D32: =IFERROR(AVERAGEIFS('05 Content & Guides'!$I$4:$I$24,'05 Content & Guides'!$B$4:$B$24,$B32),"") | E32: =IFERROR(AVERAGEIFS('05 Content & Guides'!$K$4:$K$24,'05 Content & Guides'!$B$4:$B$24,$B32),"") | F32: =IFERROR(AVERAGEIFS('05 Content & Guides'!$M$4:$M$24,'05 Content & Guides'!$B$4:$B$24,$B32),"") | G32: =IFERROR(F32-MAX(C32:E32),"") -> 0
A33: Content & Guides | B33: AREA AVERAGE — Content & Guides | C33: =IFERROR(AVERAGE('05 Content & Guides'!$G$4:$G$24),"") | D33: =IFERROR(AVERAGE('05 Content & Guides'!$I$4:$I$24),"") | E33: =IFERROR(AVERAGE('05 Content & Guides'!$K$4:$K$24),"") | F33: =IFERROR(AVERAGE('05 Content & Guides'!$M$4:$M$24),"") | G33: =IFERROR(F33-MAX(C33:E33),"") -> 0
A34: Off-Page & Authority | B34: Backlink Profile | C34: =IFERROR(AVERAGEIFS('06 Off-Page & Authority'!$G$4:$G$20,'06 Off-Page & Authority'!$B$4:$B$20,$B34),"") | D34: =IFERROR(AVERAGEIFS('06 Off-Page & Authority'!$I$4:$I$20,'06 Off-Page & Authority'!$B$4:$B$20,$B34),"") | E34: =IFERROR(AVERAGEIFS('06 Off-Page & Authority'!$K$4:$K$20,'06 Off-Page & Authority'!$B$4:$B$20,$B34),"") | F34: =IFERROR(AVERAGEIFS('06 Off-Page & Authority'!$M$4:$M$20,'06 Off-Page & Authority'!$B$4:$B$20,$B34),"") | G34: =IFERROR(F34-MAX(C34:E34),"") -> 0
A35: Off-Page & Authority | B35: Brand & Demand | C35: =IFERROR(AVERAGEIFS('06 Off-Page & Authority'!$G$4:$G$20,'06 Off-Page & Authority'!$B$4:$B$20,$B35),"") | D35: =IFERROR(AVERAGEIFS('06 Off-Page & Authority'!$I$4:$I$20,'06 Off-Page & Authority'!$B$4:$B$20,$B35),"") | E35: =IFERROR(AVERAGEIFS('06 Off-Page & Authority'!$K$4:$K$20,'06 Off-Page & Authority'!$B$4:$B$20,$B35),"") | F35: =IFERROR(AVERAGEIFS('06 Off-Page & Authority'!$M$4:$M$20,'06 Off-Page & Authority'!$B$4:$B$20,$B35),"") | G35: =IFERROR(F35-MAX(C35:E35),"") -> 0
A36: Off-Page & Authority | B36: Local Presence | C36: =IFERROR(AVERAGEIFS('06 Off-Page & Authority'!$G$4:$G$20,'06 Off-Page & Authority'!$B$4:$B$20,$B36),"") | D36: =IFERROR(AVERAGEIFS('06 Off-Page & Authority'!$I$4:$I$20,'06 Off-Page & Authority'!$B$4:$B$20,$B36),"") | E36: =IFERROR(AVERAGEIFS('06 Off-Page & Authority'!$K$4:$K$20,'06 Off-Page & Authority'!$B$4:$B$20,$B36),"") | F36: =IFERROR(AVERAGEIFS('06 Off-Page & Authority'!$M$4:$M$20,'06 Off-Page & Authority'!$B$4:$B$20,$B36),"") | G36: =IFERROR(F36-MAX(C36:E36),"") -> 0
A37: Off-Page & Authority | B37: Social & Community | C37: =IFERROR(AVERAGEIFS('06 Off-Page & Authority'!$G$4:$G$20,'06 Off-Page & Authority'!$B$4:$B$20,$B37),"") | D37: =IFERROR(AVERAGEIFS('06 Off-Page & Authority'!$I$4:$I$20,'06 Off-Page & Authority'!$B$4:$B$20,$B37),"") | E37: =IFERROR(AVERAGEIFS('06 Off-Page & Authority'!$K$4:$K$20,'06 Off-Page & Authority'!$B$4:$B$20,$B37),"") | F37: =IFERROR(AVERAGEIFS('06 Off-Page & Authority'!$M$4:$M$20,'06 Off-Page & Authority'!$B$4:$B$20,$B37),"") | G37: =IFERROR(F37-MAX(C37:E37),"") -> 0
A38: Off-Page & Authority | B38: Affiliate & Partnerships | C38: =IFERROR(AVERAGEIFS('06 Off-Page & Authority'!$G$4:$G$20,'06 Off-Page & Authority'!$B$4:$B$20,$B38),"") | D38: =IFERROR(AVERAGEIFS('06 Off-Page & Authority'!$I$4:$I$20,'06 Off-Page & Authority'!$B$4:$B$20,$B38),"") | E38: =IFERROR(AVERAGEIFS('06 Off-Page & Authority'!$K$4:$K$20,'06 Off-Page & Authority'!$B$4:$B$20,$B38),"") | F38: =IFERROR(AVERAGEIFS('06 Off-Page & Authority'!$M$4:$M$20,'06 Off-Page & Authority'!$B$4:$B$20,$B38),"") | G38: =IFERROR(F38-MAX(C38:E38),"") -> 0
A39: Off-Page & Authority | B39: AREA AVERAGE — Off-Page & Authority | C39: =IFERROR(AVERAGE('06 Off-Page & Authority'!$G$4:$G$20),"") | D39: =IFERROR(AVERAGE('06 Off-Page & Authority'!$I$4:$I$20),"") | E39: =IFERROR(AVERAGE('06 Off-Page & Authority'!$K$4:$K$20),"") | F39: =IFERROR(AVERAGE('06 Off-Page & Authority'!$M$4:$M$20),"") | G39: =IFERROR(F39-MAX(C39:E39),"") -> 0
A40: Bahamas & Compliance | B40: Licensing & Compliance | C40: =IFERROR(AVERAGEIFS('07 Bahamas & Compliance'!$G$4:$G$19,'07 Bahamas & Compliance'!$B$4:$B$19,$B40),"") | D40: =IFERROR(AVERAGEIFS('07 Bahamas & Compliance'!$I$4:$I$19,'07 Bahamas & Compliance'!$B$4:$B$19,$B40),"") | E40: =IFERROR(AVERAGEIFS('07 Bahamas & Compliance'!$K$4:$K$19,'07 Bahamas & Compliance'!$B$4:$B$19,$B40),"") | F40: =IFERROR(AVERAGEIFS('07 Bahamas & Compliance'!$M$4:$M$19,'07 Bahamas & Compliance'!$B$4:$B$19,$B40),"") | G40: =IFERROR(F40-MAX(C40:E40),"") -> 0
...

Sheet 10 Action Plan
A1: Prioritised Action Plan
A2: Populated after the audit tabs. Pull every High and Medium priority row through to here and sequence it.
A3: Ref | B3: Source tab | C3: Opportunity | D3: Why it matters (client rationale) | E3: Competitor benchmark | F3: Recommended action | G3: Silo | H3: Effort (H/M/L) | I3: Impact (H/M/L) | J3: Owner / target date

Sheet Screenshots
