Workbook

Sheet Referring domains
A1: Domain | B1: Is spam | C1: DR | D1: Dofollow ref. domains | E1: Dofollow linked domains | F1: Traffic | G1: Keywords | H1: Links to target | I1: New links | J1: Lost links | K1: Dofollow links | L1: First seen | M1: Lost
A2: ovh.net | B2: FALSE | C2: 90 | D2: 31648 | E2: 33092 | F2: 201070 | G2: 3130 | H2: 2 | I2: 0 | J2: 0 | K2: 0 | L2: 45641.893
A3: itxoft.com | B3: TRUE | C3: 84 | D3: 2565 | E3: 7 | F3: 0 | G3: 0 | H3: 3 | I3: 0 | J3: 3 | K3: 0 | L3: 45716.106 | M3: 46133.702
A4: eventcaddy.com | B4: FALSE | C4: 80 | D4: 2344 | E4: 2641 | F4: 1668 | G4: 231 | H4: 2 | I4: 0 | J4: 2 | K4: 0 | L4: 45723.656 | M4: 46057.477
A5: ewp.live | B5: FALSE | C5: 79 | D5: 3818 | E5: 4576 | F5: 27 | G5: 2 | H5: 2 | I5: 2 | J5: 0 | K5: 0 | L5: 46004.087
A6: buybacklinks.agency | B6: TRUE | C6: 77 | D6: 318 | E6: 1 | F6: 0 | G6: 0 | H6: 3 | I6: 3 | J6: 0 | K6: 0 | L6: 46121.624
A7: wanderlog.com | B7: TRUE | C7: 77 | D7: 15809 | E7: 1059353 | F7: 1980193 | G7: 652744 | H7: 7 | I7: 7 | J7: 0 | K7: 7 | L7: 46092.893
A8: temp-site.link | B8: FALSE | C8: 76 | D8: 2445 | E8: 20344 | F8: 15 | G8: 4 | H8: 9 | I8: 6 | J8: 0 | K8: 0 | L8: 45889.031
A9: mapcarta.com | B9: FALSE | C9: 75 | D9: 11463 | E9: 28 | F9: 375302 | G9: 225520 | H9: 2 | I9: 2 | J9: 0 | K9: 0 | L9: 46017.757
A10: rank-your.site | B10: TRUE | C10: 75 | D10: 1487 | E10: 0 | F10: 7 | G10: 1 | H10: 1 | I10: 0 | J10: 1 | K10: 0 | L10: 45773.078 | M10: 46050.591
A11: hol.es | B11: FALSE | C11: 74 | D11: 6852 | E11: 17243 | F11: 33 | G11: 19 | H11: 6 | I11: 6 | J11: 0 | K11: 0 | L11: 45988.429
A12: xrea.jp | B12: FALSE | C12: 74 | D12: 9356 | E12: 57859 | F12: 11694 | G12: 1056 | H12: 2 | I12: 0 | J12: 2 | K12: 0 | L12: 45886.889 | M12: 46140.361
A13: yogonet.com | B13: FALSE | C13: 74 | D13: 11424 | E13: 9427 | F13: 49669 | G13: 5393 | H13: 32 | I13: 8 | J13: 14 | K13: 32 | L13: 45715.927
A14: factmags.com | B14: TRUE | C14: 73 | D14: 4987 | E14: 39241294 | F14: 0 | G14: 0 | H14: 1 | I14: 1 | J14: 0 | K14: 0 | L14: 46149.596
A15: rankyour.website | B15: TRUE | C15: 73 | D15: 45 | E15: 0 | F15: 0 | G15: 0 | H15: 3 | I15: 3 | J15: 0 | K15: 0 | L15: 46136.358
A16: rank-top.click | B16: TRUE | C16: 72 | D16: 43 | E16: 1 | F16: 0 | G16: 0 | H16: 3 | I16: 3 | J16: 0 | K16: 0 | L16: 46120.837
A17: goedbegin.nl | B17: TRUE | C17: 70 | D17: 3069 | E17: 191789 | F17: 633 | G17: 571 | H17: 2 | I17: 0 | J17: 0 | K17: 2 | L17: 45984.272
A18: backlinker.shop | B18: TRUE | C18: 65 | D18: 506 | E18: 0 | F18: 0 | G18: 0 | H18: 3 | I18: 0 | J18: 0 | K18: 0 | L18: 45940.338
A19: bahamaslocal.com | B19: FALSE | C19: 65 | D19: 9473 | E19: 19015 | F19: 11032 | G19: 4267 | H19: 102 | I19: 0 | J19: 0 | K19: 102 | L19: 45205.475
A20: clodura.ai | B20: TRUE | C20: 64 | D20: 4342 | E20: 615900 | F20: 4320 | G20: 2428 | H20: 1 | I20: 0 | J20: 1 | K20: 1 | L20: 45736.499 | M20: 46113.955
A21: bnt.bs | B21: FALSE | C21: 62 | D21: 1194 | E21: 201 | F21: 1806 | G21: 244 | H21: 2 | I21: 0 | J21: 0 | K21: 2 | L21: 45714.739
A22: 6te.net | B22: FALSE | C22: 62 | D22: 10692 | E22: 20009 | F22: 3892 | G22: 942 | H22: 1 | I22: 1 | J22: 1 | K22: 0 | L22: 46019.115 | M22: 46068.985
A23: ioerj.com.br | B23: FALSE | C23: 61 | D23: 2050 | E23: 11396 | F23: 25038 | G23: 378 | H23: 1 | I23: 0 | J23: 0 | K23: 0 | L23: 45861.969
A24: heavenarticle.com | B24: TRUE | C24: 59 | D24: 7104 | E24: 3493588 | F24: 0 | G24: 0 | H24: 4 | I24: 0 | J24: 0 | K24: 4 | L24: 45732.332
A25: creativecreation.io | B25: FALSE | C25: 59 | D25: 136 | E25: 47 | F25: 31 | G25: 3 | H25: 2 | I25: 0 | J25: 1 | K25: 0 | L25: 45972.766
A26: host.io | B26: FALSE | C26: 58 | D26: 6825 | E26: 7 | F26: 8255 | G26: 136 | H26: 2 | I26: 1 | J26: 1 | K26: 0 | L26: 45914.533
A27: loneus.biz | B27: FALSE | C27: 58 | D27: 1911 | E27: 986 | F27: 51 | G27: 16 | H27: 1 | I27: 1 | J27: 1 | K27: 0 | L27: 46032.375 | M27: 46053.192
A28: promozionebranding.com | B28: TRUE | C28: 57 | D28: 120 | E28: 3574 | F28: 48 | G28: 6 | H28: 1 | I28: 1 | J28: 0 | K28: 0 | L28: 46003.041
A29: peaktech.nz | B29: TRUE | C29: 55 | D29: 1933 | E29: 110 | F29: 0 | G29: 0 | H29: 1 | I29: 0 | J29: 1 | K29: 0 | L29: 45893.898 | M29: 46107.268
A30: food-stadium.com | B30: FALSE | C30: 55 | D30: 2787 | E30: 2751 | F30: 4109 | G30: 1069 | H30: 43 | I30: 37 | J30: 43 | K30: 0 | L30: 45672.135 | M30: 46053.836
A31: kingranks.com | B31: TRUE | C31: 55 | D31: 4962 | E31: 6203816 | F31: 0 | G31: 0 | H31: 4 | I31: 0 | J31: 2 | K31: 4 | L31: 45714.041
A32: bounceme.net | B32: FALSE | C32: 55 | D32: 1442 | E32: 869 | F32: 0 | G32: 3 | H32: 1 | I32: 1 | J32: 0 | K32: 0 | L32: 46004.98
A33: gamingboardbahamas.com | B33: FALSE | C33: 54 | D33: 208 | E33: 102 | F33: 120 | G33: 39 | H33: 2 | I33: 0 | J33: 0 | K33: 2 | L33: 45717.4
A34: rankxlinks.shop | B34: TRUE | C34: 54 | D34: 16 | E34: 2 | F34: 0 | G34: 0 | H34: 3 | I34: 3 | J34: 0 | K34: 0 | L34: 46142.087
A35: linkrankpro.shop | B35: TRUE | C35: 54 | D35: 16 | E35: 2 | F35: 0 | G35: 0 | H35: 3 | I35: 3 | J35: 0 | K35: 0 | L35: 46144.795
A36: ranklinkerpro.shop | B36: TRUE | C36: 54 | D36: 16 | E36: 2 | F36: 0 | G36: 0 | H36: 3 | I36: 3 | J36: 0 | K36: 0 | L36: 46145.995
A37: starcourts.com | B37: TRUE | C37: 51 | D37: 1458 | E37: 4414137 | F37: 0 | G37: 1 | H37: 2 | I37: 0 | J37: 0 | K37: 2 | L37: 45715.214
A38: sante.gov.mg | B38: FALSE | C38: 50 | D38: 3554 | E38: 15203 | F38: 15 | G38: 22 | H38: 1 | I38: 1 | J38: 0 | K38: 0 | L38: 46053.177
A39: anlis.gov.ar | B39: TRUE | C39: 50 | D39: 428 | E39: 5202 | F39: 0 | G39: 1 | H39: 3 | I39: 0 | J39: 0 | K39: 0 | L39: 45930.085
A40: exlinko.net | B40: TRUE | C40: 50 | D40: 1841 | E40: 0 | F40: 0 | G40: 0 | H40: 3 | I40: 0 | J40: 3 | K40: 0 | L40: 45716.477 | M40: 46133.489
...

Sheet Cost of backlinks (with low tra
A1: DR range | B1: value per backlink | C1: min (not inclusive) | D1: max (not inclusive) | E1: total backlinks (wrong) | F1: with low traffic: | G1: referring domains | H1: backlinks | I1: value | J1: without low traffic: | K1: referring domains | L1: backlinks | M1: value | P1: =A2 -> 70-100 | Q1: =A3 -> 40-70 | R1: =A4 -> 30-40 | S1: =A5 -> 10-30 | T1: =A6 -> 0-10
A2: 70-100 | B2: 750 | C2: 69 | D2: 101 | E2: =sumifs('Referring domains'!$D:$D, 'Referring domains'!B:B,"<"&D2, 'Referring domains'!B:B,">"&C2, 'Referring domains'!K:K,">1000") -> 0 | G2: {=COUNTIFS( INDIRECT("'Referring domains'!"&SUBSTITUTE(ADDRESS(1,MATCH("DR",'Referring domains'!$A$1:$M$1,0),4),1,"")&":"&SUBSTITUTE(ADDRESS(1,MATCH("DR",'Referring domains'!$A$1:$M$1,0),4),1,"")),"<"&D2, INDIRECT("'Referring domains'!"&SUBSTITUTE(ADDRESS(1,MATCH("DR",'Referring domains'!$A$1:$M$1,0),4),1,"")&":"&SUBSTITUTE(ADDRESS(1,MATCH("DR",'Referring domains'!$A$1:$M$1,0),4),1,"")),">"&C2 )} -> 16 | H2: {=sumifs(INDIRECT("'Referring domains'!"&SUBSTITUTE(ADDRESS(1,MATCH("Links to target",'Referring domains'!$A$1:$M$1,0),4),1,"")&":"&SUBSTITUTE(ADDRESS(1,MATCH("Links to target",'Referring domains'!$A$1:$M$1,0),4),1,"")), INDIRECT("'Referring domains'!"&SUBSTITUTE(ADDRESS(1,MATCH("DR",'Referring domains'!$A$1:$M$1,0),4),1,"")&":"&SUBSTITUTE(ADDRESS(1,MATCH("DR",'Referring domains'!$A$1:$M$1,0),4),1,"")),"<"&D2, INDIRECT("'Referring domains'!"&SUBSTITUTE(ADDRESS(1,MATCH("DR",'Referring domains'!$A$1:$M$1,0),4),1,"")&":"&SUBSTITUTE(ADDRESS(1,MATCH("DR",'Referring domains'!$A$1:$M$1,0),4),1,"")),">"&C2)} -> 80 | I2: =H2*B2 -> 60000 | K2: {=COUNTIFS( INDIRECT("'Referring domains'!"&SUBSTITUTE(ADDRESS(1,MATCH("Domain Rating (desc)",'Referring domains'!$A$1:$M$1,0),4),1,"")&":"&SUBSTITUTE(ADDRESS(1,MATCH("Domain Rating (desc)",'Referring domains'!$A$1:$M$1,0),4),1,"")),"<"&D2, INDIRECT("'Referring domains'!"&SUBSTITUTE(ADDRESS(1,MATCH("Domain Rating (desc)",'Referring domains'!$A$1:$M$1,0),4),1,"")&":"&SUBSTITUTE(ADDRESS(1,MATCH("Domain Rating (desc)",'Referring domains'!$A$1:$M$1,0),4),1,"")),">"&C2, INDIRECT("'Referring domains'!"&SUBSTITUTE(ADDRESS(1,MATCH("Organic Traffic",'Referring domains'!$A$1:$M$1,0),4),1,"")&":"&SUBSTITUTE(ADDRESS(1,MATCH("Organic Traffic",'Referring domains'!$A$1:$M$1,0),4),1,"")),">1000" )} -> 0 | L2: {=sumifs(INDIRECT("'Referring domains'!"&SUBSTITUTE(ADDRESS(1,MATCH("Total Backlinks",'Referring domains'!$A$1:$M$1,0),4),1,"")&":"&SUBSTITUTE(ADDRESS(1,MATCH("Total Backlinks",'Referring domains'!$A$1:$M$1,0),4),1,"")), INDIRECT("'Referring domains'!"&SUBSTITUTE(ADDRESS(1,MATCH("Domain Rating (desc)",'Referring domains'!$A$1:$M$1,0),4),1,"")&":"&SUBSTITUTE(ADDRESS(1,MATCH("Domain Rating (desc)",'Referring domains'!$A$1:$M$1,0),4),1,"")),"<"&D2, INDIRECT("'Referring domains'!"&SUBSTITUTE(ADDRESS(1,MATCH("Domain Rating (desc)",'Referring domains'!$A$1:$M$1,0),4),1,"")&":"&SUBSTITUTE(ADDRESS(1,MATCH("Domain Rating (desc)",'Referring domains'!$A$1:$M$1,0),4),1,"")),">"&C2, INDIRECT("'Referring domains'!"&SUBSTITUTE(ADDRESS(1,MATCH("Organic Traffic",'Referring domains'!$A$1:$M$1,0),4),1,"")&":"&SUBSTITUTE(ADDRESS(1,MATCH("Organic Traffic",'Referring domains'!$A$1:$M$1,0),4),1,"")),">1000")} -> #N/A | M2: =L2*B2 -> #N/A | P2: =IFERROR(__xludf.DUMMYFUNCTION("FILTER('Referring domains'!$A$2:$A788, 'Referring domains'!$B$2:$B788<101, 'Referring domains'!$B$2:$B788>69, 'Referring domains'!$K$1:$K788>$G$13)"),"#N/A") -> #N/A | Q2: =IFERROR(__xludf.DUMMYFUNCTION("FILTER('Referring domains'!$A$2:$A788, 'Referring domains'!$B$2:$B788<70, 'Referring domains'!$B$2:$B788>39, 'Referring domains'!$E$2:$E788>$G$13)"),"#N/A") -> #N/A | R2: =IFERROR(__xludf.DUMMYFUNCTION("FILTER('Referring domains'!$A$2:$A788, 'Referring domains'!$B$2:$B788<40, 'Referring domains'!$B$2:$B788>29, 'Referring domains'!$K$1:$K788>$G$13)"),"#N/A") -> #N/A | S2: =IFERROR(__xludf.DUMMYFUNCTION("FILTER('Referring domains'!$A$2:$A788, 'Referring domains'!$B$2:$B788<30, 'Referring domains'!$B$2:$B788>9, 'Referring domains'!$K$1:$K788>$G$13)"),"#N/A") -> #N/A | T2: =IFERROR(__xludf.DUMMYFUNCTION("FILTER('Referring domains'!$A$2:$A788, 'Referring domains'!$B$2:$B788<10, 'Referring domains'!$B$2:$B788>-1, 'Referring domains'!$K$1:$K788>$G$13)"),"#N/A") -> #N/A
A3: 40-70 | B3: 300 | C3: 39 | D3: 70 | E3: =sumifs('Referring domains'!$D:$D,'Referring domains'!B:B,"<"&D3,'Referring domains'!B:B,">"&C3,'Referring domains'!K:K,">1000") -> 0 | G3: {=COUNTIFS( INDIRECT("'Referring domains'!"&SUBSTITUTE(ADDRESS(1,MATCH("DR",'Referring domains'!$A$1:$M$1,0),4),1,"")&":"&SUBSTITUTE(ADDRESS(1,MATCH("DR",'Referring domains'!$A$1:$M$1,0),4),1,"")),"<"&D3, INDIRECT("'Referring domains'!"&SUBSTITUTE(ADDRESS(1,MATCH("DR",'Referring domains'!$A$1:$M$1,0),4),1,"")&":"&SUBSTITUTE(ADDRESS(1,MATCH("DR",'Referring domains'!$A$1:$M$1,0),4),1,"")),">"&C3 )} -> 53 | H3: {=sumifs(INDIRECT("'Referring domains'!"&SUBSTITUTE(ADDRESS(1,MATCH("Links to target",'Referring domains'!$A$1:$M$1,0),4),1,"")&":"&SUBSTITUTE(ADDRESS(1,MATCH("Links to target",'Referring domains'!$A$1:$M$1,0),4),1,"")), INDIRECT("'Referring domains'!"&SUBSTITUTE(ADDRESS(1,MATCH("DR",'Referring domains'!$A$1:$M$1,0),4),1,"")&":"&SUBSTITUTE(ADDRESS(1,MATCH("DR",'Referring domains'!$A$1:$M$1,0),4),1,"")),"<"&D3, INDIRECT("'Referring domains'!"&SUBSTITUTE(ADDRESS(1,MATCH("DR",'Referring domains'!$A$1:$M$1,0),4),1,"")&":"&SUBSTITUTE(ADDRESS(1,MATCH("DR",'Referring domains'!$A$1:$M$1,0),4),1,"")),">"&C3)} -> 24870 | I3: =H3*B3 -> 7461000 | K3: {=COUNTIFS( INDIRECT("'Referring domains'!"&SUBSTITUTE(ADDRESS(1,MATCH("Domain Rating (desc)",'Referring domains'!$A$1:$M$1,0),4),1,"")&":"&SUBSTITUTE(ADDRESS(1,MATCH("Domain Rating (desc)",'Referring domains'!$A$1:$M$1,0),4),1,"")),"<"&D3, INDIRECT("'Referring domains'!"&SUBSTITUTE(ADDRESS(1,MATCH("Domain Rating (desc)",'Referring domains'!$A$1:$M$1,0),4),1,"")&":"&SUBSTITUTE(ADDRESS(1,MATCH("Domain Rating (desc)",'Referring domains'!$A$1:$M$1,0),4),1,"")),">"&C3, INDIRECT("'Referring domains'!"&SUBSTITUTE(ADDRESS(1,MATCH("Organic Traffic",'Referring domains'!$A$1:$M$1,0),4),1,"")&":"&SUBSTITUTE(ADDRESS(1,MATCH("Organic Traffic",'Referring domains'!$A$1:$M$1,0),4),1,"")),">1000" )} -> 0 | L3: {=sumifs(INDIRECT("'Referring domains'!"&SUBSTITUTE(ADDRESS(1,MATCH("Total Backlinks",'Referring domains'!$A$1:$M$1,0),4),1,"")&":"&SUBSTITUTE(ADDRESS(1,MATCH("Total Backlinks",'Referring domains'!$A$1:$M$1,0),4),1,"")), INDIRECT("'Referring domains'!"&SUBSTITUTE(ADDRESS(1,MATCH("Domain Rating (desc)",'Referring domains'!$A$1:$M$1,0),4),1,"")&":"&SUBSTITUTE(ADDRESS(1,MATCH("Domain Rating (desc)",'Referring domains'!$A$1:$M$1,0),4),1,"")),"<"&D3, INDIRECT("'Referring domains'!"&SUBSTITUTE(ADDRESS(1,MATCH("Domain Rating (desc)",'Referring domains'!$A$1:$M$1,0),4),1,"")&":"&SUBSTITUTE(ADDRESS(1,MATCH("Domain Rating (desc)",'Referring domains'!$A$1:$M$1,0),4),1,"")),">"&C3, INDIRECT("'Referring domains'!"&SUBSTITUTE(ADDRESS(1,MATCH("Organic Traffic",'Referring domains'!$A$1:$M$1,0),4),1,"")&":"&SUBSTITUTE(ADDRESS(1,MATCH("Organic Traffic",'Referring domains'!$A$1:$M$1,0),4),1,"")),">1000")} -> #N/A | M3: =L3*B3 -> #N/A
A4: 30-40 | B4: 100 | C4: 29 | D4: 40 | E4: =sumifs('Referring domains'!$D:$D,'Referring domains'!B:B,"<"&D4,'Referring domains'!B:B,">"&C4,'Referring domains'!K:K,">1000") -> 0 | G4: {=COUNTIFS( INDIRECT("'Referring domains'!"&SUBSTITUTE(ADDRESS(1,MATCH("DR",'Referring domains'!$A$1:$M$1,0),4),1,"")&":"&SUBSTITUTE(ADDRESS(1,MATCH("DR",'Referring domains'!$A$1:$M$1,0),4),1,"")),"<"&D4, INDIRECT("'Referring domains'!"&SUBSTITUTE(ADDRESS(1,MATCH("DR",'Referring domains'!$A$1:$M$1,0),4),1,"")&":"&SUBSTITUTE(ADDRESS(1,MATCH("DR",'Referring domains'!$A$1:$M$1,0),4),1,"")),">"&C4 )} -> 143 | H4: {=sumifs(INDIRECT("'Referring domains'!"&SUBSTITUTE(ADDRESS(1,MATCH("Links to target",'Referring domains'!$A$1:$M$1,0),4),1,"")&":"&SUBSTITUTE(ADDRESS(1,MATCH("Links to target",'Referring domains'!$A$1:$M$1,0),4),1,"")), INDIRECT("'Referring domains'!"&SUBSTITUTE(ADDRESS(1,MATCH("DR",'Referring domains'!$A$1:$M$1,0),4),1,"")&":"&SUBSTITUTE(ADDRESS(1,MATCH("DR",'Referring domains'!$A$1:$M$1,0),4),1,"")),"<"&D4, INDIRECT("'Referring domains'!"&SUBSTITUTE(ADDRESS(1,MATCH("DR",'Referring domains'!$A$1:$M$1,0),4),1,"")&":"&SUBSTITUTE(ADDRESS(1,MATCH("DR",'Referring domains'!$A$1:$M$1,0),4),1,"")),">"&C4)} -> 663 | I4: =H4*B4 -> 66300 | K4: {=COUNTIFS( INDIRECT("'Referring domains'!"&SUBSTITUTE(ADDRESS(1,MATCH("Domain Rating (desc)",'Referring domains'!$A$1:$M$1,0),4),1,"")&":"&SUBSTITUTE(ADDRESS(1,MATCH("Domain Rating (desc)",'Referring domains'!$A$1:$M$1,0),4),1,"")),"<"&D4, INDIRECT("'Referring domains'!"&SUBSTITUTE(ADDRESS(1,MATCH("Domain Rating (desc)",'Referring domains'!$A$1:$M$1,0),4),1,"")&":"&SUBSTITUTE(ADDRESS(1,MATCH("Domain Rating (desc)",'Referring domains'!$A$1:$M$1,0),4),1,"")),">"&C4, INDIRECT("'Referring domains'!"&SUBSTITUTE(ADDRESS(1,MATCH("Organic Traffic",'Referring domains'!$A$1:$M$1,0),4),1,"")&":"&SUBSTITUTE(ADDRESS(1,MATCH("Organic Traffic",'Referring domains'!$A$1:$M$1,0),4),1,"")),">1000" )} -> 0 | L4: {=sumifs(INDIRECT("'Referring domains'!"&SUBSTITUTE(ADDRESS(1,MATCH("Total Backlinks",'Referring domains'!$A$1:$M$1,0),4),1,"")&":"&SUBSTITUTE(ADDRESS(1,MATCH("Total Backlinks",'Referring domains'!$A$1:$M$1,0),4),1,"")), INDIRECT("'Referring domains'!"&SUBSTITUTE(ADDRESS(1,MATCH("Domain Rating (desc)",'Referring domains'!$A$1:$M$1,0),4),1,"")&":"&SUBSTITUTE(ADDRESS(1,MATCH("Domain Rating (desc)",'Referring domains'!$A$1:$M$1,0),4),1,"")),"<"&D4, INDIRECT("'Referring domains'!"&SUBSTITUTE(ADDRESS(1,MATCH("Domain Rating (desc)",'Referring domains'!$A$1:$M$1,0),4),1,"")&":"&SUBSTITUTE(ADDRESS(1,MATCH("Domain Rating (desc)",'Referring domains'!$A$1:$M$1,0),4),1,"")),">"&C4, INDIRECT("'Referring domains'!"&SUBSTITUTE(ADDRESS(1,MATCH("Organic Traffic",'Referring domains'!$A$1:$M$1,0),4),1,"")&":"&SUBSTITUTE(ADDRESS(1,MATCH("Organic Traffic",'Referring domains'!$A$1:$M$1,0),4),1,"")),">1000")} -> #N/A | M4: =L4*B4 -> #N/A
A5: 10-30 | B5: 50 | C5: 9 | D5: 30 | E5: =sumifs('Referring domains'!$D:$D,'Referring domains'!B:B,"<"&D5,'Referring domains'!B:B,">"&C5,'Referring domains'!K:K,">1000") -> 0 | G5: {=COUNTIFS( INDIRECT("'Referring domains'!"&SUBSTITUTE(ADDRESS(1,MATCH("DR",'Referring domains'!$A$1:$M$1,0),4),1,"")&":"&SUBSTITUTE(ADDRESS(1,MATCH("DR",'Referring domains'!$A$1:$M$1,0),4),1,"")),"<"&D5, INDIRECT("'Referring domains'!"&SUBSTITUTE(ADDRESS(1,MATCH("DR",'Referring domains'!$A$1:$M$1,0),4),1,"")&":"&SUBSTITUTE(ADDRESS(1,MATCH("DR",'Referring domains'!$A$1:$M$1,0),4),1,"")),">"&C5 )} -> 415 | H5: {=sumifs(INDIRECT("'Referring domains'!"&SUBSTITUTE(ADDRESS(1,MATCH("Links to target",'Referring domains'!$A$1:$M$1,0),4),1,"")&":"&SUBSTITUTE(ADDRESS(1,MATCH("Links to target",'Referring domains'!$A$1:$M$1,0),4),1,"")), INDIRECT("'Referring domains'!"&SUBSTITUTE(ADDRESS(1,MATCH("DR",'Referring domains'!$A$1:$M$1,0),4),1,"")&":"&SUBSTITUTE(ADDRESS(1,MATCH("DR",'Referring domains'!$A$1:$M$1,0),4),1,"")),"<"&D5, INDIRECT("'Referring domains'!"&SUBSTITUTE(ADDRESS(1,MATCH("DR",'Referring domains'!$A$1:$M$1,0),4),1,"")&":"&SUBSTITUTE(ADDRESS(1,MATCH("DR",'Referring domains'!$A$1:$M$1,0),4),1,"")),">"&C5)} -> 1383 | I5: =H5*B5 -> 69150 | K5: {=COUNTIFS( INDIRECT("'Referring domains'!"&SUBSTITUTE(ADDRESS(1,MATCH("Domain Rating (desc)",'Referring domains'!$A$1:$M$1,0),4),1,"")&":"&SUBSTITUTE(ADDRESS(1,MATCH("Domain Rating (desc)",'Referring domains'!$A$1:$M$1,0),4),1,"")),"<"&D5, INDIRECT("'Referring domains'!"&SUBSTITUTE(ADDRESS(1,MATCH("Domain Rating (desc)",'Referring domains'!$A$1:$M$1,0),4),1,"")&":"&SUBSTITUTE(ADDRESS(1,MATCH("Domain Rating (desc)",'Referring domains'!$A$1:$M$1,0),4),1,"")),">"&C5, INDIRECT("'Referring domains'!"&SUBSTITUTE(ADDRESS(1,MATCH("Organic Traffic",'Referring domains'!$A$1:$M$1,0),4),1,"")&":"&SUBSTITUTE(ADDRESS(1,MATCH("Organic Traffic",'Referring domains'!$A$1:$M$1,0),4),1,"")),">1000" )} -> 0 | L5: {=sumifs(INDIRECT("'Referring domains'!"&SUBSTITUTE(ADDRESS(1,MATCH("Total Backlinks",'Referring domains'!$A$1:$M$1,0),4),1,"")&":"&SUBSTITUTE(ADDRESS(1,MATCH("Total Backlinks",'Referring domains'!$A$1:$M$1,0),4),1,"")), INDIRECT("'Referring domains'!"&SUBSTITUTE(ADDRESS(1,MATCH("Domain Rating (desc)",'Referring domains'!$A$1:$M$1,0),4),1,"")&":"&SUBSTITUTE(ADDRESS(1,MATCH("Domain Rating (desc)",'Referring domains'!$A$1:$M$1,0),4),1,"")),"<"&D5, INDIRECT("'Referring domains'!"&SUBSTITUTE(ADDRESS(1,MATCH("Domain Rating (desc)",'Referring domains'!$A$1:$M$1,0),4),1,"")&":"&SUBSTITUTE(ADDRESS(1,MATCH("Domain Rating (desc)",'Referring domains'!$A$1:$M$1,0),4),1,"")),">"&C5, INDIRECT("'Referring domains'!"&SUBSTITUTE(ADDRESS(1,MATCH("Organic Traffic",'Referring domains'!$A$1:$M$1,0),4),1,"")&":"&SUBSTITUTE(ADDRESS(1,MATCH("Organic Traffic",'Referring domains'!$A$1:$M$1,0),4),1,"")),">1000")} -> #N/A | M5: =L5*B5 -> #N/A
A6: 0-10 | B6: 10 | C6: -1 | D6: 10 | E6: =sumifs('Referring domains'!$D:$D,'Referring domains'!B:B,"<"&D6,'Referring domains'!B:B,">"&C6,'Referring domains'!K:K,">1000") -> 0 | G6: {=COUNTIFS( INDIRECT("'Referring domains'!"&SUBSTITUTE(ADDRESS(1,MATCH("DR",'Referring domains'!$A$1:$M$1,0),4),1,"")&":"&SUBSTITUTE(ADDRESS(1,MATCH("DR",'Referring domains'!$A$1:$M$1,0),4),1,"")),"<"&D6, INDIRECT("'Referring domains'!"&SUBSTITUTE(ADDRESS(1,MATCH("DR",'Referring domains'!$A$1:$M$1,0),4),1,"")&":"&SUBSTITUTE(ADDRESS(1,MATCH("DR",'Referring domains'!$A$1:$M$1,0),4),1,"")),">"&C6 )} -> 4870 | H6: {=sumifs(INDIRECT("'Referring domains'!"&SUBSTITUTE(ADDRESS(1,MATCH("Links to target",'Referring domains'!$A$1:$M$1,0),4),1,"")&":"&SUBSTITUTE(ADDRESS(1,MATCH("Links to target",'Referring domains'!$A$1:$M$1,0),4),1,"")), INDIRECT("'Referring domains'!"&SUBSTITUTE(ADDRESS(1,MATCH("DR",'Referring domains'!$A$1:$M$1,0),4),1,"")&":"&SUBSTITUTE(ADDRESS(1,MATCH("DR",'Referring domains'!$A$1:$M$1,0),4),1,"")),"<"&D6, INDIRECT("'Referring domains'!"&SUBSTITUTE(ADDRESS(1,MATCH("DR",'Referring domains'!$A$1:$M$1,0),4),1,"")&":"&SUBSTITUTE(ADDRESS(1,MATCH("DR",'Referring domains'!$A$1:$M$1,0),4),1,"")),">"&C6)} -> 81975 | I6: =H6*B6 -> 819750 | K6: {=COUNTIFS( INDIRECT("'Referring domains'!"&SUBSTITUTE(ADDRESS(1,MATCH("Domain Rating (desc)",'Referring domains'!$A$1:$M$1,0),4),1,"")&":"&SUBSTITUTE(ADDRESS(1,MATCH("Domain Rating (desc)",'Referring domains'!$A$1:$M$1,0),4),1,"")),"<"&D6, INDIRECT("'Referring domains'!"&SUBSTITUTE(ADDRESS(1,MATCH("Domain Rating (desc)",'Referring domains'!$A$1:$M$1,0),4),1,"")&":"&SUBSTITUTE(ADDRESS(1,MATCH("Domain Rating (desc)",'Referring domains'!$A$1:$M$1,0),4),1,"")),">"&C6, INDIRECT("'Referring domains'!"&SUBSTITUTE(ADDRESS(1,MATCH("Organic Traffic",'Referring domains'!$A$1:$M$1,0),4),1,"")&":"&SUBSTITUTE(ADDRESS(1,MATCH("Organic Traffic",'Referring domains'!$A$1:$M$1,0),4),1,"")),">1000" )} -> 0 | L6: {=sumifs(INDIRECT("'Referring domains'!"&SUBSTITUTE(ADDRESS(1,MATCH("Total Backlinks",'Referring domains'!$A$1:$M$1,0),4),1,"")&":"&SUBSTITUTE(ADDRESS(1,MATCH("Total Backlinks",'Referring domains'!$A$1:$M$1,0),4),1,"")), INDIRECT("'Referring domains'!"&SUBSTITUTE(ADDRESS(1,MATCH("Domain Rating (desc)",'Referring domains'!$A$1:$M$1,0),4),1,"")&":"&SUBSTITUTE(ADDRESS(1,MATCH("Domain Rating (desc)",'Referring domains'!$A$1:$M$1,0),4),1,"")),"<"&D6, INDIRECT("'Referring domains'!"&SUBSTITUTE(ADDRESS(1,MATCH("Domain Rating (desc)",'Referring domains'!$A$1:$M$1,0),4),1,"")&":"&SUBSTITUTE(ADDRESS(1,MATCH("Domain Rating (desc)",'Referring domains'!$A$1:$M$1,0),4),1,"")),">"&C6, INDIRECT("'Referring domains'!"&SUBSTITUTE(ADDRESS(1,MATCH("Organic Traffic",'Referring domains'!$A$1:$M$1,0),4),1,"")&":"&SUBSTITUTE(ADDRESS(1,MATCH("Organic Traffic",'Referring domains'!$A$1:$M$1,0),4),1,"")),">1000")} -> #N/A | M6: =L6*B6 -> #N/A
G8: Total ref domains | H8: Total backlinks | I8: Total value | L8: Total backlinks | M8: Total value
G9: =SUM(G2:G6) -> 5497 | H9: =sum(H2:H6) -> 108971 | I9: =SUM(I2:I6) -> 8476200 | L9: =sum(L2:L6) -> #N/A | M9: =SUM(M2:M6) -> #N/A
G12: minimum traffic
G13: -1

Sheet Cost of backlinks (without low 
A1: DR range | B1: value per backlink | C1: min (not inclusive) | D1: max (not inclusive) | E1: total backlinks (wrong) | F1: with low traffic: | G1: referring domains | H1: backlinks | I1: value | J1: without low traffic: | K1: referring domains | L1: backlinks | M1: value | P1: =A2 -> 70-100 | Q1: =A3 -> 40-70 | R1: =A4 -> 30-40 | S1: =A5 -> 10-30 | T1: =A6 -> 0-10
A2: 70-100 | B2: 750 | C2: 69 | D2: 101 | E2: =sumifs('Referring domains'!$D:$D, 'Referring domains'!B:B,"<"&D2, 'Referring domains'!B:B,">"&C2, 'Referring domains'!K:K,">1000") -> 0 | G2: {=COUNTIFS( INDIRECT("'Referring domains'!"&SUBSTITUTE(ADDRESS(1,MATCH("Domain Rating (desc)",'Referring domains'!$A$1:$M$1,0),4),1,"")&":"&SUBSTITUTE(ADDRESS(1,MATCH("Domain Rating (desc)",'Referring domains'!$A$1:$M$1,0),4),1,"")),"<"&D2, INDIRECT("'Referring domains'!"&SUBSTITUTE(ADDRESS(1,MATCH("Domain Rating (desc)",'Referring domains'!$A$1:$M$1,0),4),1,"")&":"&SUBSTITUTE(ADDRESS(1,MATCH("Domain Rating (desc)",'Referring domains'!$A$1:$M$1,0),4),1,"")),">"&C2 )} -> 0 | H2: {=sumifs(INDIRECT("'Referring domains'!"&SUBSTITUTE(ADDRESS(1,MATCH("Total Backlinks",'Referring domains'!$A$1:$M$1,0),4),1,"")&":"&SUBSTITUTE(ADDRESS(1,MATCH("Total Backlinks",'Referring domains'!$A$1:$M$1,0),4),1,"")), INDIRECT("'Referring domains'!"&SUBSTITUTE(ADDRESS(1,MATCH("Domain Rating (desc)",'Referring domains'!$A$1:$M$1,0),4),1,"")&":"&SUBSTITUTE(ADDRESS(1,MATCH("Domain Rating (desc)",'Referring domains'!$A$1:$M$1,0),4),1,"")),"<"&D2, INDIRECT("'Referring domains'!"&SUBSTITUTE(ADDRESS(1,MATCH("Domain Rating (desc)",'Referring domains'!$A$1:$M$1,0),4),1,"")&":"&SUBSTITUTE(ADDRESS(1,MATCH("Domain Rating (desc)",'Referring domains'!$A$1:$M$1,0),4),1,"")),">"&C2)} -> #N/A | I2: =H2*B2 -> #N/A | K2: =COUNTA(P:P) - 1 -> 1 | L2: =IFERROR(__xludf.DUMMYFUNCTION("sum(filter('Referring domains'!G1:G788,isnumber(match('Referring domains'!A1:A788,'Cost of backlinks (without low '!P:P,0)))) "),"#N/A") -> #N/A | M2: =L2*B2 -> #N/A | P2: =IFERROR(__xludf.DUMMYFUNCTION("FILTER('Referring domains'!$A$2:$A788, 'Referring domains'!$B$2:$B788<101, 'Referring domains'!$B$2:$B788>69, 'Referring domains'!$E$2:$E788>$K$13)"),"#N/A") -> #N/A | Q2: =IFERROR(__xludf.DUMMYFUNCTION("FILTER('Referring domains'!$A$2:$A788, 'Referring domains'!$B$2:$B788<70, 'Referring domains'!$B$2:$B788>39, 'Referring domains'!$E$2:$E788>$K$13)"),"#N/A") -> #N/A | R2: =IFERROR(__xludf.DUMMYFUNCTION("FILTER('Referring domains'!$A$2:$A788, 'Referring domains'!$B$2:$B788<40, 'Referring domains'!$B$2:$B788>29, 'Referring domains'!$E$2:$E788>$K$13)"),"#N/A") -> #N/A | S2: =IFERROR(__xludf.DUMMYFUNCTION("FILTER('Referring domains'!$A$2:$A788, 'Referring domains'!$B$2:$B788<30, 'Referring domains'!$B$2:$B788>9, 'Referring domains'!$E$2:$E788>$K$13)"),"#N/A") -> #N/A | T2: =IFERROR(__xludf.DUMMYFUNCTION("FILTER('Referring domains'!$A$2:$A788, 'Referring domains'!$B$2:$B788<10, 'Referring domains'!$B$2:$B788>-1, 'Referring domains'!$E$2:$E788>$K$13)"),"#N/A") -> #N/A
A3: 40-70 | B3: 300 | C3: 39 | D3: 70 | E3: =sumifs('Referring domains'!$D:$D,'Referring domains'!B:B,"<"&D3,'Referring domains'!B:B,">"&C3,'Referring domains'!K:K,">1000") -> 0 | G3: {=COUNTIFS( INDIRECT("'Referring domains'!"&SUBSTITUTE(ADDRESS(1,MATCH("Domain Rating (desc)",'Referring domains'!$A$1:$M$1,0),4),1,"")&":"&SUBSTITUTE(ADDRESS(1,MATCH("Domain Rating (desc)",'Referring domains'!$A$1:$M$1,0),4),1,"")),"<"&D3, INDIRECT("'Referring domains'!"&SUBSTITUTE(ADDRESS(1,MATCH("Domain Rating (desc)",'Referring domains'!$A$1:$M$1,0),4),1,"")&":"&SUBSTITUTE(ADDRESS(1,MATCH("Domain Rating (desc)",'Referring domains'!$A$1:$M$1,0),4),1,"")),">"&C3 )} -> 0 | H3: {=sumifs(INDIRECT("'Referring domains'!"&SUBSTITUTE(ADDRESS(1,MATCH("Total Backlinks",'Referring domains'!$A$1:$M$1,0),4),1,"")&":"&SUBSTITUTE(ADDRESS(1,MATCH("Total Backlinks",'Referring domains'!$A$1:$M$1,0),4),1,"")), INDIRECT("'Referring domains'!"&SUBSTITUTE(ADDRESS(1,MATCH("Domain Rating (desc)",'Referring domains'!$A$1:$M$1,0),4),1,"")&":"&SUBSTITUTE(ADDRESS(1,MATCH("Domain Rating (desc)",'Referring domains'!$A$1:$M$1,0),4),1,"")),"<"&D3, INDIRECT("'Referring domains'!"&SUBSTITUTE(ADDRESS(1,MATCH("Domain Rating (desc)",'Referring domains'!$A$1:$M$1,0),4),1,"")&":"&SUBSTITUTE(ADDRESS(1,MATCH("Domain Rating (desc)",'Referring domains'!$A$1:$M$1,0),4),1,"")),">"&C3)} -> #N/A | I3: =H3*B3 -> #N/A | K3: =COUNTA(Q:Q) - 1 -> 1 | L3: =IFERROR(__xludf.DUMMYFUNCTION("sum(filter('Referring domains'!G:G,isnumber(match('Referring domains'!A:A,'Cost of backlinks (without low '!Q:Q,0)))) "),"#N/A") -> #N/A | M3: =L3*B3 -> #N/A
A4: 30-40 | B4: 100 | C4: 29 | D4: 40 | E4: =sumifs('Referring domains'!$D:$D,'Referring domains'!B:B,"<"&D4,'Referring domains'!B:B,">"&C4,'Referring domains'!K:K,">1000") -> 0 | G4: {=COUNTIFS( INDIRECT("'Referring domains'!"&SUBSTITUTE(ADDRESS(1,MATCH("Domain Rating (desc)",'Referring domains'!$A$1:$M$1,0),4),1,"")&":"&SUBSTITUTE(ADDRESS(1,MATCH("Domain Rating (desc)",'Referring domains'!$A$1:$M$1,0),4),1,"")),"<"&D4, INDIRECT("'Referring domains'!"&SUBSTITUTE(ADDRESS(1,MATCH("Domain Rating (desc)",'Referring domains'!$A$1:$M$1,0),4),1,"")&":"&SUBSTITUTE(ADDRESS(1,MATCH("Domain Rating (desc)",'Referring domains'!$A$1:$M$1,0),4),1,"")),">"&C4 )} -> 0 | H4: {=sumifs(INDIRECT("'Referring domains'!"&SUBSTITUTE(ADDRESS(1,MATCH("Total Backlinks",'Referring domains'!$A$1:$M$1,0),4),1,"")&":"&SUBSTITUTE(ADDRESS(1,MATCH("Total Backlinks",'Referring domains'!$A$1:$M$1,0),4),1,"")), INDIRECT("'Referring domains'!"&SUBSTITUTE(ADDRESS(1,MATCH("Domain Rating (desc)",'Referring domains'!$A$1:$M$1,0),4),1,"")&":"&SUBSTITUTE(ADDRESS(1,MATCH("Domain Rating (desc)",'Referring domains'!$A$1:$M$1,0),4),1,"")),"<"&D4, INDIRECT("'Referring domains'!"&SUBSTITUTE(ADDRESS(1,MATCH("Domain Rating (desc)",'Referring domains'!$A$1:$M$1,0),4),1,"")&":"&SUBSTITUTE(ADDRESS(1,MATCH("Domain Rating (desc)",'Referring domains'!$A$1:$M$1,0),4),1,"")),">"&C4)} -> #N/A | I4: =H4*B4 -> #N/A | K4: =COUNTA(R:R) - 1 -> 1 | L4: =IFERROR(__xludf.DUMMYFUNCTION("sum(filter('Referring domains'!G:G,isnumber(match('Referring domains'!A:A,'Cost of backlinks (without low '!R:R,0)))) "),"#N/A") -> #N/A | M4: =L4*B4 -> #N/A
A5: 10-30 | B5: 50 | C5: 9 | D5: 30 | E5: =sumifs('Referring domains'!$D:$D,'Referring domains'!B:B,"<"&D5,'Referring domains'!B:B,">"&C5,'Referring domains'!K:K,">1000") -> 0 | G5: {=COUNTIFS( INDIRECT("'Referring domains'!"&SUBSTITUTE(ADDRESS(1,MATCH("Domain Rating (desc)",'Referring domains'!$A$1:$M$1,0),4),1,"")&":"&SUBSTITUTE(ADDRESS(1,MATCH("Domain Rating (desc)",'Referring domains'!$A$1:$M$1,0),4),1,"")),"<"&D5, INDIRECT("'Referring domains'!"&SUBSTITUTE(ADDRESS(1,MATCH("Domain Rating (desc)",'Referring domains'!$A$1:$M$1,0),4),1,"")&":"&SUBSTITUTE(ADDRESS(1,MATCH("Domain Rating (desc)",'Referring domains'!$A$1:$M$1,0),4),1,"")),">"&C5 )} -> 0 | H5: {=sumifs(INDIRECT("'Referring domains'!"&SUBSTITUTE(ADDRESS(1,MATCH("Total Backlinks",'Referring domains'!$A$1:$M$1,0),4),1,"")&":"&SUBSTITUTE(ADDRESS(1,MATCH("Total Backlinks",'Referring domains'!$A$1:$M$1,0),4),1,"")), INDIRECT("'Referring domains'!"&SUBSTITUTE(ADDRESS(1,MATCH("Domain Rating (desc)",'Referring domains'!$A$1:$M$1,0),4),1,"")&":"&SUBSTITUTE(ADDRESS(1,MATCH("Domain Rating (desc)",'Referring domains'!$A$1:$M$1,0),4),1,"")),"<"&D5, INDIRECT("'Referring domains'!"&SUBSTITUTE(ADDRESS(1,MATCH("Domain Rating (desc)",'Referring domains'!$A$1:$M$1,0),4),1,"")&":"&SUBSTITUTE(ADDRESS(1,MATCH("Domain Rating (desc)",'Referring domains'!$A$1:$M$1,0),4),1,"")),">"&C5)} -> #N/A | I5: =H5*B5 -> #N/A | K5: =COUNTA(S:S) - 1 -> 1 | L5: =IFERROR(__xludf.DUMMYFUNCTION("sum(filter('Referring domains'!G:G,isnumber(match('Referring domains'!A:A,'Cost of backlinks (without low '!S:S,0)))) "),"#N/A") -> #N/A | M5: =L5*B5 -> #N/A
A6: 0-10 | B6: 10 | C6: -1 | D6: 10 | E6: =sumifs('Referring domains'!$D:$D,'Referring domains'!B:B,"<"&D6,'Referring domains'!B:B,">"&C6,'Referring domains'!K:K,">1000") -> 0 | G6: {=COUNTIFS( INDIRECT("'Referring domains'!"&SUBSTITUTE(ADDRESS(1,MATCH("Domain Rating (desc)",'Referring domains'!$A$1:$M$1,0),4),1,"")&":"&SUBSTITUTE(ADDRESS(1,MATCH("Domain Rating (desc)",'Referring domains'!$A$1:$M$1,0),4),1,"")),"<"&D6, INDIRECT("'Referring domains'!"&SUBSTITUTE(ADDRESS(1,MATCH("Domain Rating (desc)",'Referring domains'!$A$1:$M$1,0),4),1,"")&":"&SUBSTITUTE(ADDRESS(1,MATCH("Domain Rating (desc)",'Referring domains'!$A$1:$M$1,0),4),1,"")),">"&C6 )} -> 0 | H6: {=sumifs(INDIRECT("'Referring domains'!"&SUBSTITUTE(ADDRESS(1,MATCH("Total Backlinks",'Referring domains'!$A$1:$M$1,0),4),1,"")&":"&SUBSTITUTE(ADDRESS(1,MATCH("Total Backlinks",'Referring domains'!$A$1:$M$1,0),4),1,"")), INDIRECT("'Referring domains'!"&SUBSTITUTE(ADDRESS(1,MATCH("Domain Rating (desc)",'Referring domains'!$A$1:$M$1,0),4),1,"")&":"&SUBSTITUTE(ADDRESS(1,MATCH("Domain Rating (desc)",'Referring domains'!$A$1:$M$1,0),4),1,"")),"<"&D6, INDIRECT("'Referring domains'!"&SUBSTITUTE(ADDRESS(1,MATCH("Domain Rating (desc)",'Referring domains'!$A$1:$M$1,0),4),1,"")&":"&SUBSTITUTE(ADDRESS(1,MATCH("Domain Rating (desc)",'Referring domains'!$A$1:$M$1,0),4),1,"")),">"&C6)} -> #N/A | I6: =H6*B6 -> #N/A | K6: =COUNTA(T:T) - 1 -> 1 | L6: =IFERROR(__xludf.DUMMYFUNCTION("sum(filter('Referring domains'!G:G,isnumber(match('Referring domains'!A:A,'Cost of backlinks (without low '!T:T,0)))) "),"#N/A") -> #N/A | M6: =L6*B6 -> #N/A
H8: Total backlinks | I8: Total value | L8: Total backlinks | M8: Total value
H9: =sum(H2:H6) -> #N/A | I9: =SUM(I2:I6) -> #N/A | L9: =sum(L2:L6) -> #N/A | M9: =SUM(M2:M6) -> #N/A
K12: minimum traffic
K13: 1000
