Workbook

Sheet data
A1: Referring page title | B1: Referring page URL | C1: Language | D1: Platform | E1: Referring page HTTP code | F1: Domain rating | G1: UR | H1: Domain traffic | I1: Referring domains | J1: Linked domains | K1: External links | L1: Page traffic | M1: Keywords | N1: Target URL | O1: Left context | P1: Anchor | Q1: Right context | R1: Redirect Chain URLs | S1: Redirect Chain status codes | T1: Type | U1: Is spam | V1: Content | W1: Nofollow | X1: UGC | Y1: Sponsored | Z1: Rendered | AA1: Raw | AB1: Lost status | AC1: Drop reason | AD1: Discovered status | AE1: First seen | AF1: Last seen | AG1: Lost | AH1: Author | AI1: Page type | AJ1: Page category
A2: Organic Rank Systems — Advanced systems designed for organic rankings, qualified traffic and sustainable search growth to strengthen search presence and attract relevant visitors — I Bought Dofollow Backlinks for My Fintech Site — Full 60-Day Review of Metrics, Rankings, and Traffic Impact — Including practical implementation steps, provider evaluation criteria, and competitive search-positioning lessons | B2: https://organicranksystems.shop/5a30dd52b-web-development-took-every-keyword-page1-crypto-money-site-every-dollar-ranking-tracked-step-by-step-strategy-data-progress-and-outcomes-for-competitive-serp-results/ | C2: en | E2: 200 | F2: 25 | G2: 0 | H2: 0 | I2: 0 | J2: 6687 | K2: 7703 | L2: 0 | M2: 0 | N2: https://plumplumbers.com/ | P2: Grow plumplumbers.com with premium guest posts, high-quality backlinks, on-page SEO, local SEO, web development, SaaS tools and automation tools — real DR/DA/TF improvement for any industry. We strengthen the campaign with keyword mapping, source diversification, placement audits, performance benchmarks, and straightforward reporting. · Organic Rank Systems — Advanced systems designed for ... | T2: text | U2: TRUE | V2: FALSE | W2: TRUE | X2: FALSE | Y2: FALSE | Z2: FALSE | AA2: TRUE | AD2: pagefound | AE2: 46232.8 | AF2: 46236.864 | AI2: Article > Review | AJ2: Internet > Web services > SEO and marketing; Business > Marketing > Marketing
A3: Running a Small Business with No Web Presence Was Frustrating Until I Found SEOExpress.org. With Their Help, Daily Organic Visits Started at Zero; Now They Average 1,200 Per Month as They Helped Me Move from Page Eight to the Top Four Google Searches. This Is Truly Amazing! 🚀 ⭐★★★★ — Proven Serp Boost And Outreach Pro Services | B3: https://proven-serp-boost-and-outreach-pro-services.store/running-a-small-business-with-no-web-presence-was-frustrating-until-i-found-seoexpress-them-daily-organic-visits-started-at-zero-now-they-average-1200-per-month-as-they-helped-me | C3: en | E3: 200 | F3: 32 | G3: 0 | H3: 0 | I3: 0 | J3: 4994 | K3: 4996 | L3: 0 | M3: 0 | N3: https://plumplumbers.com/ | P3: Back when I launched plumplumbers.com, I had little understanding of SEO and no budget for hefty agency fees. Then a friend suggested SEOExpress.org for their budget-friendly services. My domain authority skyrocketed from DA 10 to DA 45 in under two months! Leads trickled in consistently after that. Seriously, go visit SEOExpress.org – it’s the best investment I've made 🚀 | T3: text | U3: TRUE | V3: FALSE | W3: TRUE | X3: FALSE | Y3: FALSE | Z3: FALSE | AA3: TRUE | AD3: linkfound | AE3: 46229.286 | AF3: 46229.286 | AI3: Article > Story | AJ3: Internet > Web services > SEO and marketing; Business > Small business > Business formation
A4: Running a Small Business with No Web Presence Was Frustrating Until I Found SEOExpress.org. With Their Help, Daily Organic Visits Started at Zero; Now They Average 1,200 Per Month as They Helped Me Move from Page Eight to the Top Four Google Searches. This Is Truly Amazing! 🚀 ⭐★★★★ — Seoexpress Organic Partners | B4: https://seoexpress-organic-partners.store/running-a-small-business-with-no-web-presence-was-frustrating-until-i-found-seoexpress-them-daily-organic-visits-started-at-zero-now-they-average-1200-per-month-as-they-helped-me | C4: en | E4: 200 | F4: 32 | G4: 0 | H4: 0 | I4: 0 | J4: 4994 | K4: 4996 | L4: 0 | M4: 0 | N4: https://plumplumbers.com/ | P4: Back when I launched plumplumbers.com, I had little understanding of SEO and no budget for hefty agency fees. Then a friend suggested SEOExpress.org for their budget-friendly services. My domain authority skyrocketed from DA 10 to DA 45 in under two months! Leads trickled in consistently after that. Seriously, go visit SEOExpress.org – it’s the best investment I've made 🚀 | T4: text | U4: TRUE | V4: FALSE | W4: TRUE | X4: FALSE | Y4: FALSE | Z4: FALSE | AA4: TRUE | AD4: pagefound | AE4: 46161.938 | AF4: 46237.09 | AI4: Article > Opinion | AJ4: Internet > Web services > SEO and marketing; Business > Marketing > Marketing; Communities
A5: How to Build an Unstoppable Law Firm SERP Presence Using Homepage Links, DR Boost Services, and Traffic — Full Playbook — Along With actionable ranking improvements, realistic outcome expectations, and durable ranking strategies — 25CB447F0 | B5: https://serpcollective.shop/25cb447f0-used-authority-link-packages-page5-to-page1-ymyl-site-month-by-month-progress-proven-optimization-process-budget-links-and-content-for-reliable-page-one-progress/ | C5: en | E5: 200 | F5: 25 | G5: 0 | H5: 0 | I5: 0 | J5: 6688 | K5: 7688 | L5: 0 | M5: 0 | N5: https://plumplumbers.com/ | P5: Power up plumplumbers.com: backlinks and guest posts, on-page SEO, local SEO, custom web development, SaaS integrations and automation tools for a strong DR/DA/TF increase in competitive markets. Every delivery follows a structured plan for content relevance, link diversity, authority checks, traffic measurement, and ongoing optimization. · 25cb447f0 | T5: text | U5: TRUE | V5: FALSE | W5: TRUE | X5: FALSE | Y5: FALSE | Z5: FALSE | AA5: TRUE | AD5: pagefound | AE5: 46227.196 | AF5: 46227.196 | AI5: Article > Guide | AJ5: Internet > Web services > SEO and marketing; Government > Legal > Services; Business
A6: Top Billion | B6: https://www.topbillion.net/domains/212225/e072dd4e2eb290be06244be2af096b9c/ | C6: en | E6: 200 | F6: 14 | G6: 0 | H6: 0 | I6: 0 | J6: 1031 | K6: 1184 | L6: 0 | M6: 0 | N6: https://www.plumplumbers.com/ | O6: plumplumb.com plumplumbers.co.za | P6: plumplumbers.com | Q6: plumplumbing.com plumplumbooks.co.uk | R6: https://plumplumbers.com/ | S6: 301 | T6: text | U6: TRUE | V6: FALSE | W6: TRUE | X6: FALSE | Y6: FALSE | Z6: FALSE | AA6: TRUE | AD6: linkfound | AE6: 46189.106 | AF6: 46219.118 | AH6: Top Billion
A7: How Traffic Services recovered lost traffic fully for My Mortgage Money Site — Every Dollar Spent, Every Ranking Gained, Tracked — Explaining a detailed execution roadmap, realistic outcome expectations, and safer scaling recommendations — 4FF1A7615 | B7: https://seolinkcentral.shop/4ff1a7615-roi-traffic-services-insurance-cost-per-link-vs-revenue-12-months-detailed-campaign-breakdown-data-progress-and-outcomes-for-stronger-domain-authority/ | C7: en | E7: 200 | F7: 25 | G7: 0 | H7: 0 | I7: 0 | J7: 6692 | K7: 7692 | L7: 0 | M7: 0 | N7: https://www.plumplumbers.com/ | P7: Boost plumplumbers.com using high-quality backlinks, guest posts, on-page and local SEO, custom web development, SaaS tools and automation tools for stronger DR, DA and TF worldwide. The complete process includes website review, competitor benchmarking, anchor-risk control, placement validation, and practical growth recommendations. · 4ff1a7615 | R7: https://plumplumbers.com/ | S7: 301 | T7: text | U7: TRUE | V7: FALSE | W7: TRUE | X7: FALSE | Y7: FALSE | Z7: FALSE | AA7: TRUE | AD7: linkfound | AE7: 46226.89 | AF7: 46226.89 | AI7: Article > Guide | AJ7: Internet > Web services > SEO and marketing; Real estate > Real estate services > Real estate agencies; Business > Marketing > Marketing; Finance
A8: Page SEO Network — A connected professional network for on-page optimization, content relevance and page-one visibility to turn search visibility into consistent website growth — How I Used Guest Posts and restored rankings after an algorithm update for My Fintech Site — Month-by-Month Progress Documentation — Along With practical implementation steps, reporting and tracking methods, and safer scaling recommendations | B8: https://pageseonetwork.shop/f0da71d90-12-month-blogroll-links-journey-healthcare-google-penalty-to-position1-long-term-seo-method-authority-traffic-and-conversions-for-scalable-seo-performance/ | C8: en | E8: 200 | F8: 25 | G8: 0 | H8: 0 | I8: 0 | J8: 6688 | K8: 7688 | L8: 0 | M8: 0 | N8: https://plumplumbers.com/ | P8: Boost plumplumbers.com using guest posts and backlinks, on-page SEO, local SEO, web development, SaaS integrations and automation tools for reliable DR/DA/TF progress built to last. Results are supported by relevant placements, sensible link velocity, documented checks, competitor comparisons, and clear evidence of progress. · Page SEO Network — A connected professional network for on-page ... | T8: text | U8: TRUE | V8: FALSE | W8: TRUE | X8: FALSE | Y8: FALSE | Z8: FALSE | AA8: TRUE | AD8: pagefound | AE8: 46227.631 | AF8: 46227.631 | AI8: Article > Guide | AJ8: Internet > Web services > SEO and marketing; Business
A9: Addurl.in | B9: https://www.addurl.in/domains/212225/31f3ccae8df226ccc146b1ca58dfe544/ | C9: en | E9: 200 | F9: 6 | G9: 0 | H9: 1 | I9: 0 | J9: 1026 | K9: 1184 | L9: 0 | M9: 0 | N9: https://plumplumbers.com/ | P9: plumplumbers.com | Q9: Other Pages | T9: text | U9: FALSE | V9: TRUE | W9: TRUE | X9: FALSE | Y9: FALSE | Z9: FALSE | AA9: TRUE | AD9: linkfound | AE9: 46164.555 | AF9: 46164.555
A10: Plumbers in Cape Town | Plumbers On Duty | B10: https://plumberonduty.co.za/city/cape-town | C10: en | E10: 200 | F10: 8 | G10: 0 | H10: 3 | I10: 0 | J10: 112 | K10: 294 | L10: 0 | M10: 0 | N10: https://www.plumplumbers.com/ | O10: WhatsApp | P10: Website | R10: https://plumplumbers.com/ | S10: 301 | T10: text | U10: TRUE | V10: TRUE | W10: FALSE | X10: FALSE | Y10: FALSE | Z10: FALSE | AA10: TRUE | AD10: linkfound | AE10: 46213.399 | AF10: 46237.395
A11: Plum Plumbers | Busy Signal | B11: https://busysignal.co.za/directory/plum-plumbers/ | C11: en | D11: ecommerce, wordpress | E11: 200 | F11: 0 | G11: 0 | H11: 33 | I11: 0 | J11: 3 | K11: 4 | L11: 0 | M11: 0 | N11: https://plumplumbers.com/ | P11: https://plumplumbers.com/ | T11: text | U11: FALSE | V11: TRUE | W11: FALSE | X11: FALSE | Y11: FALSE | Z11: FALSE | AA11: TRUE | AD11: linkfound | AE11: 46162.843 | AF11: 46225.851 | AI11: Listing collection > Business | AJ11: Home > Home improvement > Plumbing; Business > Maintenance; Real estate; Shopping
A12: 🛸 Dark Side Links – Dark/White Hat Link Building Services | SportsPrint | B12: https://sportsprint.com.au/2026/02/21/dark-side-links-dark-white-hat-link-building-1306/ | C12: en | D12: wordpress | E12: 200 | F12: 7 | G12: 0 | H12: 10 | I12: 0 | J12: 3097 | K12: 3450 | L12: 0 | M12: 0 | N12: https://plumplumbers.com/ | O12: DARK HAT AND WHITE HAT BACKLINKS | P12: JOIN OUR TELEGRAM https://t.me/s/darksidelinks | Q12: FOR CHEAP AND GOOGLE FRIENDLY BACKLINKS | T12: text | U12: TRUE | V12: FALSE | W12: TRUE | X12: FALSE | Y12: FALSE | Z12: FALSE | AA12: TRUE | AD12: pagefound | AE12: 46175.548 | AF12: 46233.202 | AI12: Site page > Services | AJ12: Internet > Web services > SEO and marketing; Business > Marketing > Marketing; Sports
A13: ???? Dark Side Links – Dark/White Hat Link Building Services Western Carolina Weddings | B13: https://westerncarolinaweddings.com/dark-side-links-dark-white-hat-link-building-1306/ | C13: en | D13: wordpress | E13: 200 | F13: 20 | G13: 0 | H13: 0 | I13: 0 | J13: 3094 | K13: 3448 | L13: 0 | M13: 0 | N13: https://plumplumbers.com/ | O13: DARK HAT AND WHITE HAT BACKLINKS | P13: JOIN OUR TELEGRAM https://t.me/s/darksidelinks | Q13: FOR CHEAP AND GOOGLE FRIENDLY BACKLINKS | T13: text | U13: TRUE | V13: TRUE | W13: TRUE | X13: FALSE | Y13: FALSE | Z13: FALSE | AA13: TRUE | AD13: pagefound | AE13: 46167.058 | AF13: 46237.684 | AI13: Listing > Service | AJ13: Internet > Web services > SEO and marketing; Business > Marketing > Marketing
A14: ✅ Website Stats 📊 | B14: https://ready.pro/stats/47784 | C14: en | E14: 200 | F14: 35 | G14: 0 | H14: 0 | I14: 0 | J14: 3677 | K14: 4111 | L14: 0 | M14: 0 | N14: https://plumplumbers.com/ | O14: Learn More | P14: plumplumbers.com | Q14: &nbsp | T14: text | U14: TRUE | V14: TRUE | W14: TRUE | X14: FALSE | Y14: FALSE | Z14: FALSE | AA14: TRUE | AD14: pagefound | AE14: 46153.975 | AF14: 46237.775 | AI14: Listing > Business | AJ14: Internet > Web services > Development; Reference > Listings > Business; Business; Communities; Travel
A15: Backlink Builders — Growth builders specializing in editorial backlinks, authority placements and off-page SEO for better keyword positions and lasting digital authority — Tiered Link Building vs PBN Backlinks for Local Business — Which One Moves Rankings Faster and Holds Longer? — Breaking Down clear planning and execution details, quality-control requirements, and practical next-step recommendations | B15: https://backlinkbuilders.shop/4aee60903-used-authority-link-packages-recovered-from-google-penalty-60-days-ecommerce-site-month-by-month-progress-proven-optimization-process-tools-tactics-and-insights-for-long-term-search-success/ | C15: en | E15: 200 | F15: 25 | G15: 0 | H15: 0 | I15: 0 | J15: 6688 | K15: 7688 | L15: 0 | M15: 0 | N15: https://www.plumplumbers.com/ | P15: For plumplumbers.com, we deliver premium guest posts, contextual backlinks, on-page and local SEO, conversion-focused web development, SaaS tools and automation tools — durable DR/DA/TF gains in competitive markets. Each campaign combines strategic research, safe anchor variation, editorial quality control, progress monitoring, and recommendations for the next stage. · Backlink Builders — ... | R15: https://plumplumbers.com/ | S15: 301 | T15: text | U15: TRUE | V15: FALSE | W15: TRUE | X15: FALSE | Y15: FALSE | Z15: FALSE | AA15: TRUE | AD15: pagefound | AE15: 46227.158 | AF15: 46227.158 | AI15: Article > Comparison | AJ15: Internet > Web services > SEO and marketing; Business > Marketing > Marketing
A16: Plumber in Cape Town, Western Cape, South Africa - Page 7 of 16 - Appliance Repair | B16: https://appliancerepair.co.za/places/category/plumber-1/south-africa/western-cape/cape-town/page/7/ | C16: en | D16: wordpress | E16: 200 | F16: 0.3 | G16: 0 | H16: 1153 | I16: 0 | J16: 15 | K16: 23 | L16: 0 | M16: 0 | N16: https://www.plumplumbers.com/ | R16: https://plumplumbers.com/ | S16: 301 | T16: text | U16: TRUE | V16: FALSE | W16: FALSE | X16: FALSE | Y16: FALSE | Z16: FALSE | AA16: TRUE | AD16: linkrestored | AE16: 45592.704 | AF16: 46233.988
A17: How Dofollow Backlinks Compares to Sidebar Links for Law Firm — Cost, Speed, Quality, and Final Ranking Outcomes — linkchest.shop | B17: https://linkchest.shop/y8insyu-serp-climb-blueprint-fintech-rank-using-contextual-backlinks-press-release-links/ | C17: en | E17: 200 | F17: 0.7 | G17: 0 | H17: 0 | I17: 6 | J17: 8227 | K17: 9711 | L17: 0 | M17: 0 | N17: https://plumplumbers.com/ | P17: Strengthen plumplumbers.com through guest posts and backlinks, on-page SEO, local SEO, web development, SaaS integrations and automation tools for long-term DR/DA/TF gains with editorial standards. | T17: text | U17: TRUE | V17: FALSE | W17: TRUE | X17: FALSE | Y17: FALSE | Z17: FALSE | AA17: TRUE | AD17: pagefound | AE17: 46196.228 | AF17: 46224.347 | AI17: Article > Comparison | AJ17: Internet > Web services > SEO and marketing; Business > Marketing > Marketing
A18: Running a Small Business with No Web Presence Was Frustrating Until I Found SEOExpress.org. With Their Help, Daily Organic Visits Started at Zero; Now They Average 1,200 Per Month as They Helped Me Move from Page Eight to the Top Four Google Searches. This Is Truly Amazing! 🚀 ⭐★★★★ — High SEO Ranking | B18: https://thehighseoranking.shop/running-a-small-business-with-no-web-presence-was-frustrating-until-i-found-seoexpress-them-daily-organic-visits-started-at-zero-now-they-average-1200-per-month-as-they-helped-me | C18: en | E18: 200 | F18: 33 | G18: 0 | H18: 0 | I18: 36 | J18: 4994 | K18: 4996 | L18: 0 | M18: 0 | N18: https://plumplumbers.com/ | P18: Back when I launched plumplumbers.com, I had little understanding of SEO and no budget for hefty agency fees. Then a friend suggested SEOExpress.org for their budget-friendly services. My domain authority skyrocketed from DA 10 to DA 45 in under two months! Leads trickled in consistently after that. Seriously, go visit SEOExpress.org – it’s the best investment I've made 🚀 | T18: text | U18: TRUE | V18: FALSE | W18: TRUE | X18: FALSE | Y18: FALSE | Z18: FALSE | AA18: TRUE | AD18: linkfound | AE18: 46141.254 | AF18: 46165.117 | AI18: Article > Story | AJ18: Internet > Web services > SEO and marketing; Business > Small business > Business formation
A19: Top Rank Company — A full-service company delivering top-position SEO, competitive visibility and ranking growth for reliable rankings, stronger authority and organic reach — From Page 5 to Page 1 in Fintech — The 45-Day Strategy Built Entirely on DR Boost Services — Breaking Down tested workflow recommendations, content and link-quality checks, and durable ranking strategies | B19: https://toprankcompany.shop/41499a846-pbn-backlinks-vs-automation-tools-health-which-moves-rankings-faster-holds-longer-complete-implementation-guide-cost-timeline-and-results-for-lasting-ranking-improvements/ | C19: en | E19: 200 | F19: 25 | G19: 0 | H19: 0 | I19: 0 | J19: 6689 | K19: 7689 | L19: 0 | M19: 0 | N19: https://plumplumbers.com/ | P19: Take plumplumbers.com to page one with guest posts and backlinks, on-page SEO, local SEO, web development, SaaS integrations and automation tools — rising DR/DA/TF scores with proven results. Campaign quality is protected through manual review, realistic pacing, diversified sources, accurate reporting, and continuous performance checks. · Top Rank Company — A full-service company delivering ... | T19: text | U19: TRUE | V19: FALSE | W19: TRUE | X19: FALSE | Y19: FALSE | Z19: FALSE | AA19: TRUE | AD19: linkfound | AE19: 46232.812 | AF19: 46232.812 | AI19: Article > Guide | AJ19: Internet > Web services > SEO and marketing; Business > Marketing > Marketing; Finance
A20: How Traffic Services recovered lost traffic fully for My Mortgage Money Site — Every Dollar Spent, Every Ranking Gained, Tracked — Explaining a detailed execution roadmap, realistic outcome expectations, and safer scaling recommendations — 4FF1A7615 | B20: https://seolinkcentral.shop/4ff1a7615-roi-traffic-services-insurance-cost-per-link-vs-revenue-12-months-detailed-campaign-breakdown-data-progress-and-outcomes-for-stronger-domain-authority/ | C20: en | E20: 200 | F20: 25 | G20: 0 | H20: 0 | I20: 0 | J20: 6692 | K20: 7692 | L20: 0 | M20: 0 | N20: https://plumplumbers.com/ | P20: Boost plumplumbers.com using high-quality backlinks, guest posts, on-page and local SEO, custom web development, SaaS tools and automation tools for stronger DR, DA and TF worldwide. The complete process includes website review, competitor benchmarking, anchor-risk control, placement validation, and practical growth recommendations. · 4ff1a7615 | T20: text | U20: TRUE | V20: FALSE | W20: TRUE | X20: FALSE | Y20: FALSE | Z20: FALSE | AA20: TRUE | AD20: linkfound | AE20: 46226.89 | AF20: 46226.89 | AI20: Article > Guide | AJ20: Internet > Web services > SEO and marketing; Real estate > Real estate services > Real estate agencies; Business > Marketing > Marketing; Finance
A21: 🛸 Dark Side Links – Dark/White Hat Link Building Services – Shop LopezExpress | B21: https://shop.lopezexpressgt.com/2026/02/21/dark-side-links-dark-white-hat-link-building-1306/ | C21: en, es | D21: ecommerce, wordpress | E21: 200 | F21: 12 | G21: 0 | H21: 2 | I21: 0 | J21: 3085 | K21: 3426 | L21: 0 | M21: 0 | N21: https://plumplumbers.com/ | O21: DARK HAT AND WHITE HAT BACKLINKS | P21: JOIN OUR TELEGRAM https://t.me/s/darksidelinks | Q21: FOR CHEAP AND GOOGLE FRIENDLY BACKLINKS | T21: text | U21: FALSE | V21: FALSE | W21: TRUE | X21: FALSE | Y21: FALSE | Z21: FALSE | AA21: TRUE | AD21: linkfound | AE21: 46129.396 | AF21: 46129.396 | AI21: Site page > Services | AJ21: Internet > Web services > SEO and marketing; Business
A22: How Homepage Links Helped My Dental Site grew domain authority past DR 30 — The Complete Case Study With Full Data Transparency — rankfinds.shop | B22: https://rankfinds.shop/a3vxds1-tiered-link-building-grew-domain-authority-past-dr30-real-estate-money-site-every-dollar-ranking-tracked/ | C22: en | E22: 200 | F22: 0.7 | G22: 0 | H22: 0 | I22: 18 | J22: 5148 | K22: 6005 | L22: 0 | M22: 0 | N22: https://plumplumbers.com/ | P22: plumplumbers.com: premium guest posts, high-quality backlinks, on-page SEO, local SEO, web development, SaaS tools and automation tools, all driving steady DR/DA/TF growth across all markets. | T22: text | U22: TRUE | V22: FALSE | W22: TRUE | X22: FALSE | Y22: FALSE | Z22: FALSE | AA22: TRUE | AD22: pagefound | AE22: 46198.332 | AF22: 46226.641 | AI22: Article > Research | AJ22: Internet > Web services > SEO and marketing; Business > Marketing > Marketing; Health > Dental care
A23: The 6-Month SERP Climb for Fintech — How I Combined Contextual Backlinks and Local SEO to Reach Position 1 — Breaking Down a detailed execution roadmap, important risk checks, and future campaign planning — E7C4EE9F8 | B23: https://linkseocollective.shop/e7c4ee9f8-120-day-blogroll-links-case-study-medical-placements-anchors-rankings-advanced-growth-framework-quality-checks-and-reporting-for-stronger-domain-authority/ | C23: en | E23: 200 | F23: 25 | G23: 0 | H23: 0 | I23: 0 | J23: 6688 | K23: 7688 | L23: 0 | M23: 0 | N23: https://plumplumbers.com/ | P23: plumplumbers.com gets premium guest posts, contextual backlinks, on-page and local SEO, conversion-focused web development, SaaS tools and automation tools, together driving a measurable DR/DA/TF boost in any language. We strengthen the campaign with keyword mapping, source diversification, placement audits, performance benchmarks, and straightforward reporting. · e7c4ee9f8 | T23: text | U23: TRUE | V23: FALSE | W23: TRUE | X23: FALSE | Y23: FALSE | Z23: FALSE | AA23: TRUE | AD23: pagefound | AE23: 46222.839 | AF23: 46222.839 | AI23: Article > Guide | AJ23: Internet > Web services > SEO and marketing; Finance > Investing > Day trading; Business > Marketing > Marketing
A24: rankgoods.shop — How Homepage Links Helped My Dental Site grew domain authority past DR 30 — The Complete Case Study With Full Data Transparency | B24: https://rankgoods.shop/a3vxds1-tiered-link-building-grew-domain-authority-past-dr30-real-estate-money-site-every-dollar-ranking-tracked/ | C24: en | E24: 200 | F24: 0.7 | G24: 0 | H24: 0 | I24: 0 | J24: 5148 | K24: 6010 | L24: 0 | M24: 0 | N24: https://plumplumbers.com/ | P24: plumplumbers.com: premium guest posts, high-quality backlinks, on-page SEO, local SEO, web development, SaaS tools and automation tools, all driving steady DR/DA/TF growth across all markets. | T24: text | U24: TRUE | V24: FALSE | W24: TRUE | X24: FALSE | Y24: FALSE | Z24: FALSE | AA24: TRUE | AD24: linkfound | AE24: 46202.025 | AF24: 46230.055 | AI24: Article > Research | AJ24: Internet > Web services > SEO and marketing; Business > Marketing > Marketing; Health > Dental care
A25: Running a Small Business with No Web Presence Was Frustrating Until I Found SEOExpress.org. With Their Help, Daily Organic Visits Started at Zero; Now They Average 1,200 Per Month as They Helped Me Move from Page Eight to the Top Four Google Searches. This Is Truly Amazing! 🚀 ⭐★★★★ — SEO Express | B25: https://master-guest-posting-and-link-velocity-studio.store/running-a-small-business-with-no-web-presence-was-frustrating-until-i-found-seoexpress-them-daily-organic-visits-started-at-zero-now-they-average-1200-per-month-as-they-helped-me | C25: en | E25: 200 | F25: 32 | G25: 0 | H25: 0 | I25: 0 | J25: 4994 | K25: 4996 | L25: 0 | M25: 0 | N25: https://plumplumbers.com/ | P25: Back when I launched plumplumbers.com, I had little understanding of SEO and no budget for hefty agency fees. Then a friend suggested SEOExpress.org for their budget-friendly services. My domain authority skyrocketed from DA 10 to DA 45 in under two months! Leads trickled in consistently after that. Seriously, go visit SEOExpress.org – it’s the best investment I've made 🚀 | T25: text | U25: TRUE | V25: FALSE | W25: TRUE | X25: FALSE | Y25: FALSE | Z25: FALSE | AA25: TRUE | AD25: linkfound | AE25: 46220.411 | AF25: 46220.411 | AI25: Article > Story | AJ25: Internet > Web services > SEO and marketing; Business > Small business > Business formation
A26: Link Growth Source — A trusted information and service source for authority link acquisition, referral visibility and ranking growth for better keyword positions and lasting digital authority — I Bought Web Development for My Financial Advisory Site — Full 45-Day Review of Metrics, Rankings, and Traffic Impact — Covering a complete cost and timeline breakdown, quality-control requirements, and sustainable search visibility recommendations | B26: https://linkgrowthsource.shop/690cb116e-ranking-stability-blueprint-finance-rank-using-guest-posts-dr-boost-services-advanced-growth-framework-cost-timeline-and-results-for-consistent-traffic-growth/ | C26: en | E26: 200 | F26: 25 | G26: 0 | H26: 0 | I26: 0 | J26: 6692 | K26: 7692 | L26: 0 | M26: 0 | N26: https://plumplumbers.com/ | P26: Boost plumplumbers.com using guest posts and backlinks, on-page SEO, local SEO, web development, SaaS integrations and automation tools for higher DR/DA/TF across the board for new or established sites. The plan remains focused on natural relevance, credible sources, balanced optimization, measurable search gains, and sustainable long-term execution. · Link Growth Source — A trusted information ... | T26: text | U26: TRUE | V26: FALSE | W26: TRUE | X26: FALSE | Y26: FALSE | Z26: FALSE | AA26: TRUE | AD26: pagefound | AE26: 46227.796 | AF26: 46227.796 | AI26: Article > Guide | AJ26: Internet > Web services > SEO and marketing; Business > Marketing > Marketing
A27: Where to buy 🚀 aged domains and backlinks 🔥 | 9301-3994 | B27: https://www.indexaward.com/9fa301e3994143cd8cb4b89b296e5cf0-l/ | C27: en | D27: wordpress | E27: 200 | F27: 5 | G27: 0 | H27: 0 | I27: 0 | J27: 9158 | K27: 9997 | L27: 0 | M27: 0 | N27: https://plumplumbers.com/ | O27: plumplumagency.com plumplumb.com | P27: plumplumbers.com | Q27: plumplumbing.com plumplumbooks.com | T27: text | U27: TRUE | V27: FALSE | W27: FALSE | X27: FALSE | Y27: FALSE | Z27: FALSE | AA27: TRUE | AD27: pagefound | AE27: 46166.792 | AF27: 46222.644 | AI27: Listing > Business | AJ27: Internet > Web services > SEO and marketing; Business > Marketing > Marketing
A28: Running a Small Business with No Web Presence Was Frustrating Until I Found SEOExpress.org. With Their Help, Daily Organic Visits Started at Zero; Now They Average 1,200 Per Month as They Helped Me Move from Page Eight to the Top Four Google Searches. This Is Truly Amazing! 🚀 ⭐★★★★ — Crawl Budget And Page Rank Expert Partners | B28: https://crawl-budget-and-page-rank-expert-partners.store/running-a-small-business-with-no-web-presence-was-frustrating-until-i-found-seoexpress-them-daily-organic-visits-started-at-zero-now-they-average-1200-per-month-as-they-helped-me | C28: en | E28: 200 | F28: 32 | G28: 0 | H28: 0 | I28: 0 | J28: 4994 | K28: 4996 | L28: 0 | M28: 0 | N28: https://plumplumbers.com/ | P28: Back when I launched plumplumbers.com, I had little understanding of SEO and no budget for hefty agency fees. Then a friend suggested SEOExpress.org for their budget-friendly services. My domain authority skyrocketed from DA 10 to DA 45 in under two months! Leads trickled in consistently after that. Seriously, go visit SEOExpress.org – it’s the best investment I've made 🚀 | T28: text | U28: TRUE | V28: FALSE | W28: TRUE | X28: FALSE | Y28: FALSE | Z28: FALSE | AA28: TRUE | AD28: linkfound | AE28: 46218.769 | AF28: 46236.649 | AI28: Article > Opinion | AJ28: Internet > Web services > SEO and marketing; Business > Marketing > Marketing; Communities
A29: Places - Page 8 of 119 - Appliance Repair | B29: https://appliancerepair.co.za/places/page/8/ | C29: en | D29: wordpress | E29: 200 | F29: 0.3 | G29: 0 | H29: 1153 | I29: 0 | J29: 29 | K29: 40 | L29: 0 | M29: 0 | N29: https://www.plumplumbers.com/ | R29: https://plumplumbers.com/ | S29: 301 | T29: text | U29: TRUE | V29: FALSE | W29: FALSE | X29: FALSE | Y29: FALSE | Z29: FALSE | AA29: TRUE | AD29: linkfound | AE29: 46066.223 | AF29: 46066.223
A30: Plumber - Page 7 of 70 - Appliance Repair | B30: https://appliancerepair.co.za/places/category/plumber-1/page/7/ | C30: en | D30: wordpress | E30: 200 | F30: 0.3 | G30: 0 | H30: 1153 | I30: 0 | J30: 15 | K30: 22 | L30: 0 | M30: 0 | N30: https://www.plumplumbers.com/ | R30: https://plumplumbers.com/ | S30: 301 | T30: text | U30: TRUE | V30: FALSE | W30: FALSE | X30: FALSE | Y30: FALSE | Z30: FALSE | AA30: TRUE | AD30: linkrestored | AE30: 45590.813 | AF30: 46234.824
A31: Places in Western Cape, South Africa - Page 14 of 48 - Appliance Repair | B31: https://appliancerepair.co.za/places/south-africa/western-cape/page/14/ | C31: en | D31: wordpress | E31: 200 | F31: 0.3 | G31: 0 | H31: 1153 | I31: 0 | J31: 16 | K31: 22 | L31: 0 | M31: 0 | N31: https://www.plumplumbers.com/ | R31: https://plumplumbers.com/ | S31: 301 | T31: text | U31: TRUE | V31: FALSE | W31: FALSE | X31: FALSE | Y31: FALSE | Z31: FALSE | AA31: TRUE | AD31: linkrestored | AE31: 45676.19 | AF31: 46237.353
A32: Where to buy 🚀 aged domains and backlinks 🔥 | 9301-3994 | B32: https://alljobs.info/9fa301e3994143cd8cb4b89b296e5cf0-l/ | C32: en | D32: wordpress | E32: 200 | F32: 13 | G32: 0 | H32: 0 | I32: 0 | J32: 9154 | K32: 9997 | L32: 0 | M32: 0 | N32: https://plumplumbers.com/ | O32: plumplumagency.com plumplumb.com | P32: plumplumbers.com | Q32: plumplumbing.com plumplumbooks.com | T32: text | U32: TRUE | V32: FALSE | W32: FALSE | X32: FALSE | Y32: FALSE | Z32: FALSE | AA32: TRUE | AD32: pagefound | AE32: 46154.449 | AF32: 46225.35 | AI32: Listing > Business | AJ32: Internet > Web services > SEO and marketing; Business > Marketing > Marketing
A33: Running a Small Business with No Web Presence Was Frustrating Until I Found SEOExpress.org. With Their Help, Daily Organic Visits Started at Zero; Now They Average 1,200 Per Month as They Helped Me Move from Page Eight to the Top Four Google Searches. This Is Truly Amazing! 🚀 ⭐★★★★ — Certified Rank Forge Anchor Text Lab | B33: https://certified-rank-forge-anchor-text-lab.store/running-a-small-business-with-no-web-presence-was-frustrating-until-i-found-seoexpress-them-daily-organic-visits-started-at-zero-now-they-average-1200-per-month-as-they-helped-me | C33: en | E33: 200 | F33: 32 | G33: 0 | H33: 0 | I33: 0 | J33: 4994 | K33: 4996 | L33: 0 | M33: 0 | N33: https://plumplumbers.com/ | P33: Back when I launched plumplumbers.com, I had little understanding of SEO and no budget for hefty agency fees. Then a friend suggested SEOExpress.org for their budget-friendly services. My domain authority skyrocketed from DA 10 to DA 45 in under two months! Leads trickled in consistently after that. Seriously, go visit SEOExpress.org – it’s the best investment I've made 🚀 | T33: text | U33: TRUE | V33: FALSE | W33: TRUE | X33: FALSE | Y33: FALSE | Z33: FALSE | AA33: TRUE | AD33: linkfound | AE33: 46189.89 | AF33: 46227.816 | AI33: Article > Review | AJ33: Internet > Web services > SEO and marketing; Business > Small business > Business formation
A34: How Homepage Links Helped My Dental Site grew domain authority past DR 30 — The Complete Case Study With Full Data Transparency — seowares.shop | B34: https://seowares.shop/a3vxds1-tiered-link-building-grew-domain-authority-past-dr30-real-estate-money-site-every-dollar-ranking-tracked/ | C34: en | E34: 200 | F34: 0.7 | G34: 0 | H34: 0 | I34: 9 | J34: 5151 | K34: 6001 | L34: 0 | M34: 0 | N34: https://www.plumplumbers.com/ | P34: plumplumbers.com: premium guest posts, high-quality backlinks, on-page SEO, local SEO, web development, SaaS tools and automation tools, all driving steady DR/DA/TF growth across all markets. | R34: https://plumplumbers.com/ | S34: 301 | T34: text | U34: TRUE | V34: FALSE | W34: TRUE | X34: FALSE | Y34: FALSE | Z34: FALSE | AA34: TRUE | AD34: pagefound | AE34: 46195.359 | AF34: 46223.863 | AI34: Article > Research | AJ34: Internet > Web services > SEO and marketing; Business > Marketing > Marketing; Health > Dental care
A35: 🛸 Dark Side Links – Dark/White Hat Link Building Services – Global Waste Commodities | B35: http://gwc.spottedcow.media/2026/02/21/dark-side-links-dark-white-hat-link-building-1306/ | C35: en | D35: wordpress | E35: 200 | F35: 14 | G35: 0 | H35: 4 | I35: 0 | J35: 3094 | K35: 3445 | L35: 0 | M35: 0 | N35: https://www.plumplumbers.com/ | O35: DARK HAT AND WHITE HAT BACKLINKS | P35: JOIN OUR TELEGRAM https://t.me/s/darksidelinks | Q35: FOR CHEAP AND GOOGLE FRIENDLY BACKLINKS | R35: https://plumplumbers.com/ | S35: 301 | T35: text | U35: TRUE | V35: FALSE | W35: TRUE | X35: FALSE | Y35: FALSE | Z35: FALSE | AA35: TRUE | AD35: pagefound | AE35: 46138.425 | AF35: 46217.108 | AI35: Site page > Services | AJ35: Internet > Web services > SEO and marketing; Business > Business services
A36: Plumber - Page 4 of 37 - Appliance Repair | B36: https://appliancerepair.co.za/places/category/plumber-1/page/4/ | C36: en | D36: wordpress | E36: 200 | F36: 0.3 | G36: 0 | H36: 1153 | I36: 0 | J36: 24 | K36: 37 | L36: 0 | M36: 0 | N36: https://plumplumbers.com/ | T36: text | U36: TRUE | V36: FALSE | W36: FALSE | X36: FALSE | Y36: FALSE | Z36: FALSE | AA36: TRUE | AD36: linkfound | AE36: 46067.22 | AF36: 46067.22
A37: ranktrove.shop — How Homepage Links Helped My Dental Site grew domain authority past DR 30 — The Complete Case Study With Full Data Transparency | B37: https://ranktrove.shop/a3vxds1-tiered-link-building-grew-domain-authority-past-dr30-real-estate-money-site-every-dollar-ranking-tracked/ | C37: en | E37: 200 | F37: 0.7 | G37: 0 | H37: 0 | I37: 0 | J37: 5149 | K37: 6007 | L37: 0 | M37: 0 | N37: https://plumplumbers.com/ | P37: plumplumbers.com: premium guest posts, high-quality backlinks, on-page SEO, local SEO, web development, SaaS tools and automation tools, all driving steady DR/DA/TF growth across all markets. | T37: text | U37: TRUE | V37: FALSE | W37: TRUE | X37: FALSE | Y37: FALSE | Z37: FALSE | AA37: TRUE | AD37: pagefound | AE37: 46202.312 | AF37: 46230.342 | AI37: Article > Research | AJ37: Internet > Web services > SEO and marketing; Business > Marketing > Marketing; Health > Dental care
A38: Running a Small Business with No Web Presence Was Frustrating Until I Found SEOExpress.org. With Their Help, Daily Organic Visits Started at Zero; Now They Average 1,200 Per Month as They Helped Me Move from Page Eight to the Top Four Google Searches. This Is Truly Amazing! 🚀 ⭐★★★★ — Master SEO Express Search Agency | B38: https://master-seoexpress-search-agency.store/running-a-small-business-with-no-web-presence-was-frustrating-until-i-found-seoexpress-them-daily-organic-visits-started-at-zero-now-they-average-1200-per-month-as-they-helped-me | C38: en | E38: 200 | F38: 32 | G38: 0 | H38: 0 | I38: 0 | J38: 4994 | K38: 4996 | L38: 0 | M38: 0 | N38: https://plumplumbers.com/ | P38: Back when I launched plumplumbers.com, I had little understanding of SEO and no budget for hefty agency fees. Then a friend suggested SEOExpress.org for their budget-friendly services. My domain authority skyrocketed from DA 10 to DA 45 in under two months! Leads trickled in consistently after that. Seriously, go visit SEOExpress.org – it’s the best investment I've made 🚀 | T38: text | U38: TRUE | V38: FALSE | W38: TRUE | X38: FALSE | Y38: FALSE | Z38: FALSE | AA38: TRUE | AD38: pagefound | AE38: 46164.236 | AF38: 46199.359 | AI38: Article > Story | AJ38: Internet > Web services > SEO and marketing; Business > Small business > Business formation
A39: Running a Small Business with No Web Presence Was Frustrating Until I Found SEOExpress.org. With Their Help, Daily Organic Visits Started at Zero; Now They Average 1,200 Per Month as They Helped Me Move from Page Eight to the Top Four Google Searches. This Is Truly Amazing! 🚀 ⭐★★★★ — Official Saas Seo Outrank Hq Collective | B39: https://official-saas-seo-outrank-hq-collective.store/running-a-small-business-with-no-web-presence-was-frustrating-until-i-found-seoexpress-them-daily-organic-visits-started-at-zero-now-they-average-1200-per-month-as-they-helped-me | C39: en | E39: 200 | F39: 32 | G39: 0 | H39: 0 | I39: 0 | J39: 4994 | K39: 4996 | L39: 0 | M39: 0 | N39: https://plumplumbers.com/ | P39: Back when I launched plumplumbers.com, I had little understanding of SEO and no budget for hefty agency fees. Then a friend suggested SEOExpress.org for their budget-friendly services. My domain authority skyrocketed from DA 10 to DA 45 in under two months! Leads trickled in consistently after that. Seriously, go visit SEOExpress.org – it’s the best investment I've made 🚀 | T39: text | U39: TRUE | V39: FALSE | W39: TRUE | X39: FALSE | Y39: FALSE | Z39: FALSE | AA39: TRUE | AD39: linkfound | AE39: 46226.022 | AF39: 46226.022 | AI39: Article > Review | AJ39: Internet > Web services > SEO and marketing; Business > Small business > Business formation
A40: Running a Small Business with No Web Presence Was Frustrating Until I Found SEOExpress.org. With Their Help, Daily Organic Visits Started at Zero; Now They Average 1,200 Per Month as They Helped Me Move from Page Eight to the Top Four Google Searches. This Is Truly Amazing! 🚀 ⭐★★★★ — My Sky Shop | B40: https://mysky-shop.shop/running-a-small-business-with-no-web-presence-was-frustrating-until-i-found-seoexpress-them-daily-organic-visits-started-at-zero-now-they-average-1200-per-month-as-they-helped-me | C40: en | E40: 200 | F40: 33 | G40: 0 | H40: 0 | I40: 17 | J40: 4994 | K40: 4996 | L40: 0 | M40: 0 | N40: https://plumplumbers.com/ | P40: Back when I launched plumplumbers.com, I had little understanding of SEO and no budget for hefty agency fees. Then a friend suggested SEOExpress.org for their budget-friendly services. My domain authority skyrocketed from DA 10 to DA 45 in under two months! Leads trickled in consistently after that. Seriously, go visit SEOExpress.org – it’s the best investment I've made 🚀 | T40: text | U40: TRUE | V40: FALSE | W40: TRUE | X40: FALSE | Y40: FALSE | Z40: FALSE | AA40: TRUE | AD40: pagefound | AE40: 46135.116 | AF40: 46206.068 | AI40: Article > Story | AJ40: Internet > Web services > SEO and marketing; Business > Small business > Business formation
...

Sheet anchors
A1: Anchor text (unique) | B1: Count
A2: Back when I launched plumplumbers.com, I had little understanding of SEO and no budget for hefty agency fees. Then a friend suggested SEOExpress.org for their budget-friendly services. My domain authority skyrocketed from DA 10 to DA 45 in under two months! Leads trickled in consistently after that. Seriously, go visit SEOExpress.org – it’s the best investment I've made 🚀 | B2: =COUNTIF(data!P3:P635,A2) -> 209
A3: plumplumbers.com: premium guest posts, high-quality backlinks, on-page SEO, local SEO, web development, SaaS tools and automation tools, all driving steady DR/DA/TF growth across all markets. | B3: =COUNTIF(data!P15:P647,A3) -> 80
A4: plumplumbers.com | B4: =COUNTIF(data!P5:P637,A4) -> 75
A5: JOIN OUR TELEGRAM https://t.me/s/darksidelinks | B5: =COUNTIF(data!P10:P642,A5) -> 25
A6: Website | B6: =COUNTIF(data!P8:P640,A6) -> 16
A7: Everything plumplumbers.com needs: high-DR backlinks, editorial guest posts, on-page SEO, local SEO, web development, SaaS tools and automation tools — DR/DA/TF that climbs steadily for any industry. | B7: =COUNTIF(data!P32:P664,A7) -> 10
A8: https://plumplumbers.com/ | B8: =COUNTIF(data!P9:P641,A8) -> 6
A9: OUR TELEGRAM CHANEL https://t.me/s/quarterlinks25 | B9: =COUNTIF(data!P36:P668,A9) -> 4
A10: Grow plumplumbers.com with premium guest posts, high-quality backlinks, on-page SEO, local SEO, web development, SaaS tools and automation tools — real DR/DA/TF improvement for any industry. We strengthen the campaign with keyword mapping, source diversification, placement audits, performance benchmarks, and straightforward reporting. · Organic Rank Systems — Advanced systems designed for ... | B10: =COUNTIF(data!P2:P634,A10) -> 2
A11: Power up plumplumbers.com: backlinks and guest posts, on-page SEO, local SEO, custom web development, SaaS integrations and automation tools for a strong DR/DA/TF increase in competitive markets. Every delivery follows a structured plan for content relevance, link diversity, authority checks, traffic measurement, and ongoing optimization. · 25cb447f0 | B11: =COUNTIF(data!P4:P636,A11) -> 2
A12: Boost plumplumbers.com using high-quality backlinks, guest posts, on-page and local SEO, custom web development, SaaS tools and automation tools for stronger DR, DA and TF worldwide. The complete process includes website review, competitor benchmarking, anchor-risk control, placement validation, and practical growth recommendations. · 4ff1a7615 | B12: =COUNTIF(data!P6:P638,A12) -> 2
A13: Boost plumplumbers.com using guest posts and backlinks, on-page SEO, local SEO, web development, SaaS integrations and automation tools for reliable DR/DA/TF progress built to last. Results are supported by relevant placements, sensible link velocity, documented checks, competitor comparisons, and clear evidence of progress. · Page SEO Network — A connected professional network for on-page ... | B13: =COUNTIF(data!P7:P639,A13) -> 2
A14: For plumplumbers.com, we deliver premium guest posts, contextual backlinks, on-page and local SEO, conversion-focused web development, SaaS tools and automation tools — durable DR/DA/TF gains in competitive markets. Each campaign combines strategic research, safe anchor variation, editorial quality control, progress monitoring, and recommendations for the next stage. · Backlink Builders — ... | B14: =COUNTIF(data!P11:P643,A14) -> 2
A15: Strengthen plumplumbers.com through guest posts and backlinks, on-page SEO, local SEO, web development, SaaS integrations and automation tools for long-term DR/DA/TF gains with editorial standards. | B15: =COUNTIF(data!P13:P645,A15) -> 2
A16: Take plumplumbers.com to page one with guest posts and backlinks, on-page SEO, local SEO, web development, SaaS integrations and automation tools — rising DR/DA/TF scores with proven results. Campaign quality is protected through manual review, realistic pacing, diversified sources, accurate reporting, and continuous performance checks. · Top Rank Company — A full-service company delivering ... | B16: =COUNTIF(data!P14:P646,A16) -> 2
A17: plumplumbers.com gets premium guest posts, contextual backlinks, on-page and local SEO, conversion-focused web development, SaaS tools and automation tools, together driving a measurable DR/DA/TF boost in any language. We strengthen the campaign with keyword mapping, source diversification, placement audits, performance benchmarks, and straightforward reporting. · e7c4ee9f8 | B17: =COUNTIF(data!P16:P648,A17) -> 2
A18: Boost plumplumbers.com using guest posts and backlinks, on-page SEO, local SEO, web development, SaaS integrations and automation tools for higher DR/DA/TF across the board for new or established sites. The plan remains focused on natural relevance, credible sources, balanced optimization, measurable search gains, and sustainable long-term execution. · Link Growth Source — A trusted information ... | B18: =COUNTIF(data!P17:P649,A18) -> 2
A19: plumplumbers.com: high-quality backlinks, guest posts, on-page and local SEO, custom web development, SaaS tools and automation tools, all driving steady DR/DA/TF growth across all markets. | B19: =COUNTIF(data!P18:P650,A19) -> 2
A20: Harness plumplumbers.com Index Power: Certified Guest Posts + Google-Indexed Dofollow Backlinks boosting Raise Ahrefs Domain Rating DR + Moz Domain Authority DA + Majestic Trust Flow TF — English + All Languages • Any Niche | B20: =COUNTIF(data!P19:P651,A20) -> 2
A21: Power up plumplumbers.com: backlinks and guest posts, on-page SEO, local SEO, custom web development, SaaS integrations and automation tools for compounding DR/DA/TF in competitive markets. The plan remains focused on natural relevance, credible sources, balanced optimization, measurable search gains, and sustainable long-term execution. · Site Rank Express — Fast, focused services for ... | B21: =COUNTIF(data!P20:P652,A21) -> 2
A22: Visit website | B22: =COUNTIF(data!P21:P653,A22) -> 2
A23: Scale plumplumbers.com with high-DR backlinks, editorial guest posts, on-page SEO, local SEO, web development, SaaS tools and automation tools, earning a measurable DR/DA/TF boost at a sustainable pace. The plan remains focused on natural relevance, credible sources, balanced optimization, measurable search gains, and sustainable long-term execution. · ad8ba9ab1 | B23: =COUNTIF(data!P22:P654,A23) -> 2
A24: Everything plumplumbers.com needs: premium guest posts, contextual backlinks, on-page and local SEO, conversion-focused web development, SaaS tools and automation tools — reliable DR/DA/TF progress for every sector. We strengthen the campaign with keyword mapping, source diversification, placement audits, performance benchmarks, and straightforward reporting. · Top Rank Academy — A learning ... | B24: =COUNTIF(data!P23:P655,A24) -> 2
A25: Achieve plumplumbers.com Authority: Targeted Guest Posts + High-DA Dofollow Backlinks raising Skyrocket Ahrefs Domain Rating DR • Moz Domain Authority DA • Majestic Trust Flow TF — Worldwide Markets • Any Industry • Any Language | B25: =COUNTIF(data!P24:P656,A25) -> 2
A26: plumplumbers.com Authority Jumps: Editorial Guest Posts + High-Authority Dofollow Backlinks fueling Raise Ahrefs Domain Rating DR + Moz Domain Authority DA + Majestic Trust Flow TF — #1 Google Ranking Achieved | B26: =COUNTIF(data!P25:P657,A26) -> 2
A27: Strengthen plumplumbers.com through premium guest posts, contextual backlinks, on-page and local SEO, conversion-focused web development, SaaS tools and automation tools for DR/DA/TF gains that hold for every sector. Campaign quality is protected through manual review, realistic pacing, diversified sources, accurate reporting, and continuous performance checks. · Link SEO Insights — Research, ... | B27: =COUNTIF(data!P26:P658,A27) -> 2
A28: All-in-one organic SEO and content-based backlinks for plumplumbers.com | RankZly.com – Your Unbeatable SEO Partner for Fast Google Rankings | B28: =COUNTIF(data!P27:P659,A28) -> 2
... A32: plumplumbers.com: guest posts, backlinks, on-page and local SEO, web development, SaaS tools and workflow automation tools, all driving steady DR/DA/TF growth with full transparency. | B32: =COUNTIF(data!P31:P663,A32) -> 2
A33: Strengthen plumplumbers.com through high-DR backlinks, editorial guest posts, on-page SEO, local SEO, web development, SaaS tools and automation tools for reliable DR/DA/TF progress across any niche. | B33: =COUNTIF(data!P33:P665,A33) -> 2
A34: Everything plumplumbers.com needs: guest posts, backlinks, on-page and local SEO, web development, SaaS tools and workflow automation tools — a noticeable DR/DA/TF rise for local or global targets. | B34: =COUNTIF(data!P34:P666,A34) -> 2
A35: Grow plumplumbers.com with guest posts and backlinks, on-page SEO, local SEO, web development, SaaS integrations and automation tools — real DR/DA/TF improvement for any industry. The strategy also covers competitor research, natural anchor distribution, quality verification, and clear monthly performance reporting. · 4f5a8d488 | B35: =COUNTIF(data!P35:P667,A35) -> 2
A36: Fast-Track plumplumbers.com to #1: Real-Site Guest Posts + Permanent Dofollow Backlinks — Ahrefs Domain Rating DR, Moz Domain Authority DA & Majestic Trust Flow TF — #1 Google Ranking Achieved | B36: =COUNTIF(data!P37:P669,A36) -> 2
A37: Zoom plumplumbers.com on Google: multilingual guest posts + backlinks; DR/DA/TF elevate — worldwide. | Visit buyseolink.com for any Query | B37: =COUNTIF(data!P38:P670,A37) -> 2
A38: Professional link campaigns for plumplumbers.com from agency delivering 600 percent ROI results | B38: =COUNTIF(data!P39:P671,A38) -> 2
A39: plumplumbers.com gets high-DR backlinks, editorial guest posts, on-page SEO, local SEO, web development, SaaS tools and automation tools, together driving sustained DR/DA/TF uplift worldwide. | B39: =COUNTIF(data!P40:P672,A39) -> 2
A40: Everything plumplumbers.com needs: high-DR backlinks, editorial guest posts, on-page SEO, local SEO, web development, SaaS tools and automation tools — a strong DR/DA/TF increase built to last. The complete process includes website review, competitor benchmarking, anchor-risk control, placement validation, and practical growth recommendations. · SEO Boost Results — A results-focused platform ... | B40: =COUNTIF(data!P41:P673,A40) -> 2
A41: Get plumplumbers.com flow backlink building with guaranteed refill and permanent links | B41: =COUNTIF(data!P42:P674,A41) -> 2
A42: Strengthen plumplumbers.com through high-DR backlinks, editorial guest posts, on-page SEO, local SEO, web development, SaaS tools and automation tools for rising DR/DA/TF scores built to last. The service also includes technical review, content alignment, backlink-quality screening, conversion considerations, and transparent milestone reporting. · Backlink Insights — Research, guidance and ... | B42: =COUNTIF(data!P43:P675,A42) -> 2
A43: plumplumbers.com gets guest posts and backlinks, on-page SEO, local SEO, web development, SaaS integrations and automation tools, together driving compounding DR/DA/TF with full transparency. | B43: =COUNTIF(data!P44:P676,A43) -> 2
...
