Workbook

Sheet images
A1: Link type | B1: Is nofollow | C1: Source URL | D1: Source HTTP status code | E1: Target URL | F1: Target HTTP status code | G1: Target no-crawl reason | H1: Image type | I1: Alt attribute | J1: Alt attribute patch content | K1: Alt attribute patch status | L1: Is source canonical | M1: Is source noindex | N1: Is target canonical | O1: Is target noindex | P1: Is link self-referencing | Q1: Target URL type | R1: Is source internal
A2: Image | B2: FALSE | C2: https://plumplumbers.com/contact-us/ | D2: 200 | E2: https://plumplumbers.com/wp-content/uploads/2023/04/ou-meul-bakkery.png | F2: 200 | H2: Content | I2: client | L2: TRUE | M2: FALSE | N2: TRUE | O2: FALSE | P2: FALSE | Q2: Resource Image Resource | R2: TRUE
A3: Image | B3: FALSE | C3: https://plumplumbers.com/project/thomas-house/ | D3: 200 | E3: https://plumplumbers.com/wp-content/uploads/2023/04/ou-meul-bakkery.png | F3: 200 | H3: Content | I3: client | L3: TRUE | M3: FALSE | N3: TRUE | O3: FALSE | P3: FALSE | Q3: Resource Image Resource | R3: TRUE
A4: Image | B4: FALSE | C4: https://plumplumbers.com/about-us/ | D4: 200 | E4: https://plumplumbers.com/wp-content/uploads/2023/04/the-renuvators.png | F4: 200 | H4: Content | I4: client | L4: TRUE | M4: FALSE | N4: TRUE | O4: FALSE | P4: FALSE | Q4: Resource Image Resource | R4: TRUE
A5: Image | B5: FALSE | C5: https://plumplumbers.com/about-us/ | D5: 200 | E5: https://plumplumbers.com/wp-content/uploads/2023/04/hartcon.png | F5: 200 | H5: Content | I5: client | L5: TRUE | M5: FALSE | N5: TRUE | O5: FALSE | P5: FALSE | Q5: Resource Image Resource | R5: TRUE
A6: Image | B6: FALSE | C6: https://plumplumbers.com/about-us/ | D6: 200 | E6: https://plumplumbers.com/wp-content/uploads/2023/04/firemans-arms.png | F6: 200 | H6: Content | I6: client | L6: TRUE | M6: FALSE | N6: TRUE | O6: FALSE | P6: FALSE | Q6: Resource Image Resource | R6: TRUE
A7: Image | B7: FALSE | C7: https://plumplumbers.com/plum-plumbers-projects/ | D7: 200 | E7: https://plumplumbers.com/wp-content/uploads/2023/04/glen-3-1024x704.jpg | F7: 200 | H7: Content | L7: TRUE | M7: FALSE | N7: TRUE | O7: FALSE | P7: FALSE | Q7: Resource Image Resource | R7: TRUE
A8: Image | B8: FALSE | C8: https://plumplumbers.com/project/thomas-house/ | D8: 200 | E8: https://plumplumbers.com/wp-content/uploads/2023/04/dimensions-tents.png | F8: 200 | H8: Content | I8: client | L8: TRUE | M8: FALSE | N8: TRUE | O8: FALSE | P8: FALSE | Q8: Resource Image Resource | R8: TRUE
A9: Image | B9: FALSE | C9: https://plumplumbers.com/project/basson-house/ | D9: 200 | E9: https://plumplumbers.com/wp-content/uploads/2023/04/open-city.png | F9: 200 | H9: Content | I9: client | L9: TRUE | M9: FALSE | N9: TRUE | O9: FALSE | P9: FALSE | Q9: Resource Image Resource | R9: TRUE
A10: Image | B10: FALSE | C10: https://plumplumbers.com/project/balfour-house/ | D10: 200 | E10: https://plumplumbers.com/wp-content/uploads/2023/04/firemans-arms.png | F10: 200 | H10: Content | I10: client | L10: TRUE | M10: FALSE | N10: TRUE | O10: FALSE | P10: FALSE | Q10: Resource Image Resource | R10: TRUE
A11: Image | B11: FALSE | C11: https://plumplumbers.com/project/glen-house/ | D11: 200 | E11: https://plumplumbers.com/wp-content/uploads/2023/04/open-city.png | F11: 200 | H11: Content | I11: client | L11: TRUE | M11: FALSE | N11: TRUE | O11: FALSE | P11: FALSE | Q11: Resource Image Resource | R11: TRUE
A12: Image | B12: FALSE | C12: https://plumplumbers.com/ | D12: 200 | E12: https://plumplumbers.com/wp-content/uploads/2023/04/glen-3-1024x704.jpg | F12: 200 | H12: Content | L12: TRUE | M12: FALSE | N12: TRUE | O12: FALSE | P12: FALSE | Q12: Resource Image Resource | R12: TRUE
A13: Image | B13: FALSE | C13: https://plumplumbers.com/project/basson-house/ | D13: 200 | E13: https://plumplumbers.com/wp-content/uploads/2023/04/logo-pp.png | F13: 200 | H13: Content | I13: Plum Plumbers | L13: TRUE | M13: FALSE | N13: TRUE | O13: FALSE | P13: FALSE | Q13: Resource Image Resource | R13: TRUE
A14: Image | B14: FALSE | C14: https://plumplumbers.com/project/gardens-apartment/ | D14: 200 | E14: https://plumplumbers.com/wp-content/uploads/2021/11/Gardens-Apartment-Plum-plumbers-1-1024x683.jpg | F14: 200 | H14: Content | L14: TRUE | M14: FALSE | N14: TRUE | O14: FALSE | P14: FALSE | Q14: Resource Image Resource | R14: TRUE
A15: Image | B15: FALSE | C15: https://plumplumbers.com/project/thomas-house/ | D15: 200 | E15: https://plumplumbers.com/wp-content/uploads/2023/04/firemans-arms.png | F15: 200 | H15: Content | I15: client | L15: TRUE | M15: FALSE | N15: TRUE | O15: FALSE | P15: FALSE | Q15: Resource Image Resource | R15: TRUE
A16: Image | B16: FALSE | C16: https://plumplumbers.com/project/basson-house/ | D16: 200 | E16: https://plumplumbers.com/wp-content/uploads/2023/04/hartcon.png | F16: 200 | H16: Content | I16: client | L16: TRUE | M16: FALSE | N16: TRUE | O16: FALSE | P16: FALSE | Q16: Resource Image Resource | R16: TRUE
A17: Image | B17: FALSE | C17: https://plumplumbers.com/project/balfour-house/ | D17: 200 | E17: https://plumplumbers.com/wp-content/uploads/2023/04/ou-meul-bakkery.png | F17: 200 | H17: Content | I17: client | L17: TRUE | M17: FALSE | N17: TRUE | O17: FALSE | P17: FALSE | Q17: Resource Image Resource | R17: TRUE
A18: Image | B18: FALSE | C18: https://plumplumbers.com/project/basson-house/ | D18: 200 | E18: https://plumplumbers.com/wp-content/uploads/2023/04/firemans-arms.png | F18: 200 | H18: Content | I18: client | L18: TRUE | M18: FALSE | N18: TRUE | O18: FALSE | P18: FALSE | Q18: Resource Image Resource | R18: TRUE
A19: Image | B19: FALSE | C19: https://plumplumbers.com/project/glen-house/ | D19: 200 | E19: https://plumplumbers.com/wp-content/uploads/2023/04/seef.png | F19: 200 | H19: Content | I19: client | L19: TRUE | M19: FALSE | N19: TRUE | O19: FALSE | P19: FALSE | Q19: Resource Image Resource | R19: TRUE
A20: Image | B20: FALSE | C20: https://plumplumbers.com/project/basson-house/ | D20: 200 | E20: https://plumplumbers.com/wp-content/uploads/2023/04/ou-meul-bakkery.png | F20: 200 | H20: Content | I20: client | L20: TRUE | M20: FALSE | N20: TRUE | O20: FALSE | P20: FALSE | Q20: Resource Image Resource | R20: TRUE
A21: Image | B21: FALSE | C21: https://plumplumbers.com/project-type/remodel/ | D21: 200 | E21: https://plumplumbers.com/wp-content/uploads/2023/04/hartcon.png | F21: 200 | H21: Content | I21: client | L21: TRUE | M21: FALSE | N21: TRUE | O21: FALSE | P21: FALSE | Q21: Resource Image Resource | R21: TRUE
A22: Image | B22: FALSE | C22: https://plumplumbers.com/project/basson-house/ | D22: 200 | E22: https://plumplumbers.com/wp-content/uploads/2023/04/bootlegger.png | F22: 200 | H22: Content | I22: client | L22: TRUE | M22: FALSE | N22: TRUE | O22: FALSE | P22: FALSE | Q22: Resource Image Resource | R22: TRUE
A23: Image | B23: FALSE | C23: https://plumplumbers.com/about-us/ | D23: 200 | E23: https://plumplumbers.com/wp-content/uploads/2021/11/balfour-2.jpg | F23: 200 | H23: Content | L23: TRUE | M23: FALSE | N23: TRUE | O23: FALSE | P23: FALSE | Q23: Resource Image Resource | R23: TRUE
A24: Image | B24: FALSE | C24: https://plumplumbers.com/project/invermark-house/ | D24: 200 | E24: https://plumplumbers.com/wp-content/uploads/2023/04/pp-retina.png | F24: 200 | H24: Content | I24: Plum Plumbers | L24: TRUE | M24: FALSE | N24: TRUE | O24: FALSE | P24: FALSE | Q24: Resource Image Resource | R24: TRUE
A25: Image | B25: FALSE | C25: https://plumplumbers.com/project/gardens-apartment/ | D25: 200 | E25: https://plumplumbers.com/wp-content/uploads/2023/04/hartcon.png | F25: 200 | H25: Content | I25: client | L25: TRUE | M25: FALSE | N25: TRUE | O25: FALSE | P25: FALSE | Q25: Resource Image Resource | R25: TRUE
A26: Image | B26: FALSE | C26: https://plumplumbers.com/plum-plumbers-projects/ | D26: 200 | E26: https://plumplumbers.com/wp-content/uploads/2021/11/Gardens-Apartment-Plum-plumbers-8-1024x683.jpg | F26: 200 | H26: Content | L26: TRUE | M26: FALSE | N26: TRUE | O26: FALSE | P26: FALSE | Q26: Resource Image Resource | R26: TRUE
A27: Image | B27: FALSE | C27: https://plumplumbers.com/project-type/remodel/ | D27: 200 | E27: https://plumplumbers.com/wp-content/uploads/2023/04/seef.png | F27: 200 | H27: Content | I27: client | L27: TRUE | M27: FALSE | N27: TRUE | O27: FALSE | P27: FALSE | Q27: Resource Image Resource | R27: TRUE
A28: Image | B28: FALSE | C28: https://plumplumbers.com/project/thomas-house/ | D28: 200 | E28: https://plumplumbers.com/wp-content/uploads/2023/04/TH-3-768x1024.jpg | F28: 200 | H28: Content | L28: TRUE | M28: FALSE | N28: TRUE | O28: FALSE | P28: FALSE | Q28: Resource Image Resource | R28: TRUE
A29: Image | B29: FALSE | C29: https://plumplumbers.com/project/gardens-apartment/ | D29: 200 | E29: https://plumplumbers.com/wp-content/uploads/2023/04/ou-meul-bakkery.png | F29: 200 | H29: Content | I29: client | L29: TRUE | M29: FALSE | N29: TRUE | O29: FALSE | P29: FALSE | Q29: Resource Image Resource | R29: TRUE
A30: Image | B30: FALSE | C30: https://plumplumbers.com/project/thomas-house/ | D30: 200 | E30: https://plumplumbers.com/wp-content/uploads/2023/04/hartcon.png | F30: 200 | H30: Content | I30: client | L30: TRUE | M30: FALSE | N30: TRUE | O30: FALSE | P30: FALSE | Q30: Resource Image Resource | R30: TRUE
A31: Image | B31: FALSE | C31: https://plumplumbers.com/about-us/ | D31: 200 | E31: https://plumplumbers.com/wp-content/uploads/2023/04/pp-retina.png | F31: 200 | H31: Content | I31: Plum Plumbers | L31: TRUE | M31: FALSE | N31: TRUE | O31: FALSE | P31: FALSE | Q31: Resource Image Resource | R31: TRUE
A32: Image | B32: FALSE | C32: https://plumplumbers.com/project-type/residential/ | D32: 200 | E32: https://plumplumbers.com/wp-content/uploads/2023/04/ou-meul-bakkery.png | F32: 200 | H32: Content | I32: client | L32: TRUE | M32: FALSE | N32: TRUE | O32: FALSE | P32: FALSE | Q32: Resource Image Resource | R32: TRUE
A33: Image | B33: FALSE | C33: https://plumplumbers.com/project/balfour-house/ | D33: 200 | E33: https://plumplumbers.com/wp-content/uploads/2021/11/balfour-1-1024x680.jpg | F33: 200 | H33: Content | L33: TRUE | M33: FALSE | N33: TRUE | O33: FALSE | P33: FALSE | Q33: Resource Image Resource | R33: TRUE
A34: Image | B34: FALSE | C34: https://plumplumbers.com/project-type/remodel/ | D34: 200 | E34: https://plumplumbers.com/wp-content/uploads/2023/04/Invermark-House-Plum-plumbers-7-600x403.jpg | F34: 200 | H34: Content | L34: TRUE | M34: FALSE | N34: TRUE | O34: FALSE | P34: FALSE | Q34: Resource Image Resource | R34: TRUE
A35: Image | B35: FALSE | C35: https://plumplumbers.com/contact-us/ | D35: 200 | E35: https://source.unsplash.com/featured/1000x1000/daily/?epic | G35: Ignored by settings | H35: Content | L35: TRUE | M35: FALSE | P35: FALSE | R35: TRUE
A36: Image | B36: FALSE | C36: https://plumplumbers.com/project/thomas-house/ | D36: 200 | E36: https://plumplumbers.com/wp-content/uploads/2023/04/logo-pp.png | F36: 200 | H36: Content | I36: Plum Plumbers | L36: TRUE | M36: FALSE | N36: TRUE | O36: FALSE | P36: FALSE | Q36: Resource Image Resource | R36: TRUE
A37: Image | B37: FALSE | C37: https://plumplumbers.com/project/glen-house/ | D37: 200 | E37: https://plumplumbers.com/wp-content/uploads/2023/04/ou-meul-bakkery.png | F37: 200 | H37: Content | I37: client | L37: TRUE | M37: FALSE | N37: TRUE | O37: FALSE | P37: FALSE | Q37: Resource Image Resource | R37: TRUE
A38: Image | B38: FALSE | C38: https://plumplumbers.com/about-us/ | D38: 200 | E38: https://plumplumbers.com/wp-content/uploads/2023/04/ou-meul-bakkery.png | F38: 200 | H38: Content | I38: client | L38: TRUE | M38: FALSE | N38: TRUE | O38: FALSE | P38: FALSE | Q38: Resource Image Resource | R38: TRUE
A39: Image | B39: FALSE | C39: https://plumplumbers.com/project/gardens-apartment/ | D39: 200 | E39: https://plumplumbers.com/wp-content/uploads/2021/11/Gardens-Apartment-Plum-plumbers-2-1024x683.jpg | F39: 200 | H39: Content | L39: TRUE | M39: FALSE | N39: TRUE | O39: FALSE | P39: FALSE | Q39: Resource Image Resource | R39: TRUE
A40: Image | B40: FALSE | C40: https://plumplumbers.com/project-type/residential/ | D40: 200 | E40: https://plumplumbers.com/wp-content/uploads/2021/11/balfour-6-600x403.jpg | F40: 200 | H40: Content | L40: TRUE | M40: FALSE | N40: TRUE | O40: FALSE | P40: FALSE | Q40: Resource Image Resource | R40: TRUE
...

Sheet missing alt text
A1: Link type | B1: Is nofollow | C1: Source URL | D1: Source HTTP status code | E1: Target URL | F1: Target HTTP status code | G1: Target no-crawl reason | H1: Image type | I1: Alt attribute | J1: Alt attribute patch content | K1: Alt attribute patch status | L1: Is source canonical | M1: Is source noindex | N1: Is target canonical | O1: Is target noindex | P1: Is link self-referencing | Q1: Target URL type | R1: Is source internal
A2: Image | B2: FALSE | C2: https://plumplumbers.com/contact-us/ | D2: 200 | E2: https://plumplumbers.com/wp-content/uploads/2023/04/ou-meul-bakkery.png | F2: 200 | H2: Content | I2: client | L2: TRUE | M2: FALSE | N2: TRUE | O2: FALSE | P2: FALSE | Q2: Resource Image Resource | R2: TRUE
A3: Image | B3: FALSE | C3: https://plumplumbers.com/project/thomas-house/ | D3: 200 | E3: https://plumplumbers.com/wp-content/uploads/2023/04/ou-meul-bakkery.png | F3: 200 | H3: Content | I3: client | L3: TRUE | M3: FALSE | N3: TRUE | O3: FALSE | P3: FALSE | Q3: Resource Image Resource | R3: TRUE
A4: Image | B4: FALSE | C4: https://plumplumbers.com/about-us/ | D4: 200 | E4: https://plumplumbers.com/wp-content/uploads/2023/04/the-renuvators.png | F4: 200 | H4: Content | I4: client | L4: TRUE | M4: FALSE | N4: TRUE | O4: FALSE | P4: FALSE | Q4: Resource Image Resource | R4: TRUE
A5: Image | B5: FALSE | C5: https://plumplumbers.com/about-us/ | D5: 200 | E5: https://plumplumbers.com/wp-content/uploads/2023/04/hartcon.png | F5: 200 | H5: Content | I5: client | L5: TRUE | M5: FALSE | N5: TRUE | O5: FALSE | P5: FALSE | Q5: Resource Image Resource | R5: TRUE
A6: Image | B6: FALSE | C6: https://plumplumbers.com/about-us/ | D6: 200 | E6: https://plumplumbers.com/wp-content/uploads/2023/04/firemans-arms.png | F6: 200 | H6: Content | I6: client | L6: TRUE | M6: FALSE | N6: TRUE | O6: FALSE | P6: FALSE | Q6: Resource Image Resource | R6: TRUE
A7: Image | B7: FALSE | C7: https://plumplumbers.com/plum-plumbers-projects/ | D7: 200 | E7: https://plumplumbers.com/wp-content/uploads/2023/04/glen-3-1024x704.jpg | F7: 200 | H7: Content | L7: TRUE | M7: FALSE | N7: TRUE | O7: FALSE | P7: FALSE | Q7: Resource Image Resource | R7: TRUE
A8: Image | B8: FALSE | C8: https://plumplumbers.com/project/thomas-house/ | D8: 200 | E8: https://plumplumbers.com/wp-content/uploads/2023/04/dimensions-tents.png | F8: 200 | H8: Content | I8: client | L8: TRUE | M8: FALSE | N8: TRUE | O8: FALSE | P8: FALSE | Q8: Resource Image Resource | R8: TRUE
A9: Image | B9: FALSE | C9: https://plumplumbers.com/project/basson-house/ | D9: 200 | E9: https://plumplumbers.com/wp-content/uploads/2023/04/open-city.png | F9: 200 | H9: Content | I9: client | L9: TRUE | M9: FALSE | N9: TRUE | O9: FALSE | P9: FALSE | Q9: Resource Image Resource | R9: TRUE
A10: Image | B10: FALSE | C10: https://plumplumbers.com/project/balfour-house/ | D10: 200 | E10: https://plumplumbers.com/wp-content/uploads/2023/04/firemans-arms.png | F10: 200 | H10: Content | I10: client | L10: TRUE | M10: FALSE | N10: TRUE | O10: FALSE | P10: FALSE | Q10: Resource Image Resource | R10: TRUE
A11: Image | B11: FALSE | C11: https://plumplumbers.com/project/glen-house/ | D11: 200 | E11: https://plumplumbers.com/wp-content/uploads/2023/04/open-city.png | F11: 200 | H11: Content | I11: client | L11: TRUE | M11: FALSE | N11: TRUE | O11: FALSE | P11: FALSE | Q11: Resource Image Resource | R11: TRUE
A12: Image | B12: FALSE | C12: https://plumplumbers.com/ | D12: 200 | E12: https://plumplumbers.com/wp-content/uploads/2023/04/glen-3-1024x704.jpg | F12: 200 | H12: Content | L12: TRUE | M12: FALSE | N12: TRUE | O12: FALSE | P12: FALSE | Q12: Resource Image Resource | R12: TRUE
A13: Image | B13: FALSE | C13: https://plumplumbers.com/project/basson-house/ | D13: 200 | E13: https://plumplumbers.com/wp-content/uploads/2023/04/logo-pp.png | F13: 200 | H13: Content | I13: Plum Plumbers | L13: TRUE | M13: FALSE | N13: TRUE | O13: FALSE | P13: FALSE | Q13: Resource Image Resource | R13: TRUE
A14: Image | B14: FALSE | C14: https://plumplumbers.com/project/gardens-apartment/ | D14: 200 | E14: https://plumplumbers.com/wp-content/uploads/2021/11/Gardens-Apartment-Plum-plumbers-1-1024x683.jpg | F14: 200 | H14: Content | L14: TRUE | M14: FALSE | N14: TRUE | O14: FALSE | P14: FALSE | Q14: Resource Image Resource | R14: TRUE
A15: Image | B15: FALSE | C15: https://plumplumbers.com/project/thomas-house/ | D15: 200 | E15: https://plumplumbers.com/wp-content/uploads/2023/04/firemans-arms.png | F15: 200 | H15: Content | I15: client | L15: TRUE | M15: FALSE | N15: TRUE | O15: FALSE | P15: FALSE | Q15: Resource Image Resource | R15: TRUE
A16: Image | B16: FALSE | C16: https://plumplumbers.com/project/basson-house/ | D16: 200 | E16: https://plumplumbers.com/wp-content/uploads/2023/04/hartcon.png | F16: 200 | H16: Content | I16: client | L16: TRUE | M16: FALSE | N16: TRUE | O16: FALSE | P16: FALSE | Q16: Resource Image Resource | R16: TRUE
A17: Image | B17: FALSE | C17: https://plumplumbers.com/project/balfour-house/ | D17: 200 | E17: https://plumplumbers.com/wp-content/uploads/2023/04/ou-meul-bakkery.png | F17: 200 | H17: Content | I17: client | L17: TRUE | M17: FALSE | N17: TRUE | O17: FALSE | P17: FALSE | Q17: Resource Image Resource | R17: TRUE
A18: Image | B18: FALSE | C18: https://plumplumbers.com/project/basson-house/ | D18: 200 | E18: https://plumplumbers.com/wp-content/uploads/2023/04/firemans-arms.png | F18: 200 | H18: Content | I18: client | L18: TRUE | M18: FALSE | N18: TRUE | O18: FALSE | P18: FALSE | Q18: Resource Image Resource | R18: TRUE
A19: Image | B19: FALSE | C19: https://plumplumbers.com/project/glen-house/ | D19: 200 | E19: https://plumplumbers.com/wp-content/uploads/2023/04/seef.png | F19: 200 | H19: Content | I19: client | L19: TRUE | M19: FALSE | N19: TRUE | O19: FALSE | P19: FALSE | Q19: Resource Image Resource | R19: TRUE
A20: Image | B20: FALSE | C20: https://plumplumbers.com/project/basson-house/ | D20: 200 | E20: https://plumplumbers.com/wp-content/uploads/2023/04/ou-meul-bakkery.png | F20: 200 | H20: Content | I20: client | L20: TRUE | M20: FALSE | N20: TRUE | O20: FALSE | P20: FALSE | Q20: Resource Image Resource | R20: TRUE
A21: Image | B21: FALSE | C21: https://plumplumbers.com/project-type/remodel/ | D21: 200 | E21: https://plumplumbers.com/wp-content/uploads/2023/04/hartcon.png | F21: 200 | H21: Content | I21: client | L21: TRUE | M21: FALSE | N21: TRUE | O21: FALSE | P21: FALSE | Q21: Resource Image Resource | R21: TRUE
A22: Image | B22: FALSE | C22: https://plumplumbers.com/project/basson-house/ | D22: 200 | E22: https://plumplumbers.com/wp-content/uploads/2023/04/bootlegger.png | F22: 200 | H22: Content | I22: client | L22: TRUE | M22: FALSE | N22: TRUE | O22: FALSE | P22: FALSE | Q22: Resource Image Resource | R22: TRUE
A23: Image | B23: FALSE | C23: https://plumplumbers.com/about-us/ | D23: 200 | E23: https://plumplumbers.com/wp-content/uploads/2021/11/balfour-2.jpg | F23: 200 | H23: Content | L23: TRUE | M23: FALSE | N23: TRUE | O23: FALSE | P23: FALSE | Q23: Resource Image Resource | R23: TRUE
A24: Image | B24: FALSE | C24: https://plumplumbers.com/project/invermark-house/ | D24: 200 | E24: https://plumplumbers.com/wp-content/uploads/2023/04/pp-retina.png | F24: 200 | H24: Content | I24: Plum Plumbers | L24: TRUE | M24: FALSE | N24: TRUE | O24: FALSE | P24: FALSE | Q24: Resource Image Resource | R24: TRUE
A25: Image | B25: FALSE | C25: https://plumplumbers.com/project/gardens-apartment/ | D25: 200 | E25: https://plumplumbers.com/wp-content/uploads/2023/04/hartcon.png | F25: 200 | H25: Content | I25: client | L25: TRUE | M25: FALSE | N25: TRUE | O25: FALSE | P25: FALSE | Q25: Resource Image Resource | R25: TRUE
A26: Image | B26: FALSE | C26: https://plumplumbers.com/plum-plumbers-projects/ | D26: 200 | E26: https://plumplumbers.com/wp-content/uploads/2021/11/Gardens-Apartment-Plum-plumbers-8-1024x683.jpg | F26: 200 | H26: Content | L26: TRUE | M26: FALSE | N26: TRUE | O26: FALSE | P26: FALSE | Q26: Resource Image Resource | R26: TRUE
A27: Image | B27: FALSE | C27: https://plumplumbers.com/project-type/remodel/ | D27: 200 | E27: https://plumplumbers.com/wp-content/uploads/2023/04/seef.png | F27: 200 | H27: Content | I27: client | L27: TRUE | M27: FALSE | N27: TRUE | O27: FALSE | P27: FALSE | Q27: Resource Image Resource | R27: TRUE
A28: Image | B28: FALSE | C28: https://plumplumbers.com/project/thomas-house/ | D28: 200 | E28: https://plumplumbers.com/wp-content/uploads/2023/04/TH-3-768x1024.jpg | F28: 200 | H28: Content | L28: TRUE | M28: FALSE | N28: TRUE | O28: FALSE | P28: FALSE | Q28: Resource Image Resource | R28: TRUE
A29: Image | B29: FALSE | C29: https://plumplumbers.com/project/gardens-apartment/ | D29: 200 | E29: https://plumplumbers.com/wp-content/uploads/2023/04/ou-meul-bakkery.png | F29: 200 | H29: Content | I29: client | L29: TRUE | M29: FALSE | N29: TRUE | O29: FALSE | P29: FALSE | Q29: Resource Image Resource | R29: TRUE
A30: Image | B30: FALSE | C30: https://plumplumbers.com/project/thomas-house/ | D30: 200 | E30: https://plumplumbers.com/wp-content/uploads/2023/04/hartcon.png | F30: 200 | H30: Content | I30: client | L30: TRUE | M30: FALSE | N30: TRUE | O30: FALSE | P30: FALSE | Q30: Resource Image Resource | R30: TRUE
A31: Image | B31: FALSE | C31: https://plumplumbers.com/about-us/ | D31: 200 | E31: https://plumplumbers.com/wp-content/uploads/2023/04/pp-retina.png | F31: 200 | H31: Content | I31: Plum Plumbers | L31: TRUE | M31: FALSE | N31: TRUE | O31: FALSE | P31: FALSE | Q31: Resource Image Resource | R31: TRUE
A32: Image | B32: FALSE | C32: https://plumplumbers.com/project-type/residential/ | D32: 200 | E32: https://plumplumbers.com/wp-content/uploads/2023/04/ou-meul-bakkery.png | F32: 200 | H32: Content | I32: client | L32: TRUE | M32: FALSE | N32: TRUE | O32: FALSE | P32: FALSE | Q32: Resource Image Resource | R32: TRUE
A33: Image | B33: FALSE | C33: https://plumplumbers.com/project/balfour-house/ | D33: 200 | E33: https://plumplumbers.com/wp-content/uploads/2021/11/balfour-1-1024x680.jpg | F33: 200 | H33: Content | L33: TRUE | M33: FALSE | N33: TRUE | O33: FALSE | P33: FALSE | Q33: Resource Image Resource | R33: TRUE
A34: Image | B34: FALSE | C34: https://plumplumbers.com/project-type/remodel/ | D34: 200 | E34: https://plumplumbers.com/wp-content/uploads/2023/04/Invermark-House-Plum-plumbers-7-600x403.jpg | F34: 200 | H34: Content | L34: TRUE | M34: FALSE | N34: TRUE | O34: FALSE | P34: FALSE | Q34: Resource Image Resource | R34: TRUE
A35: Image | B35: FALSE | C35: https://plumplumbers.com/contact-us/ | D35: 200 | E35: https://source.unsplash.com/featured/1000x1000/daily/?epic | G35: Ignored by settings | H35: Content | L35: TRUE | M35: FALSE | P35: FALSE | R35: TRUE
A36: Image | B36: FALSE | C36: https://plumplumbers.com/project/thomas-house/ | D36: 200 | E36: https://plumplumbers.com/wp-content/uploads/2023/04/logo-pp.png | F36: 200 | H36: Content | I36: Plum Plumbers | L36: TRUE | M36: FALSE | N36: TRUE | O36: FALSE | P36: FALSE | Q36: Resource Image Resource | R36: TRUE
A37: Image | B37: FALSE | C37: https://plumplumbers.com/project/glen-house/ | D37: 200 | E37: https://plumplumbers.com/wp-content/uploads/2023/04/ou-meul-bakkery.png | F37: 200 | H37: Content | I37: client | L37: TRUE | M37: FALSE | N37: TRUE | O37: FALSE | P37: FALSE | Q37: Resource Image Resource | R37: TRUE
A38: Image | B38: FALSE | C38: https://plumplumbers.com/about-us/ | D38: 200 | E38: https://plumplumbers.com/wp-content/uploads/2023/04/ou-meul-bakkery.png | F38: 200 | H38: Content | I38: client | L38: TRUE | M38: FALSE | N38: TRUE | O38: FALSE | P38: FALSE | Q38: Resource Image Resource | R38: TRUE
A39: Image | B39: FALSE | C39: https://plumplumbers.com/project/gardens-apartment/ | D39: 200 | E39: https://plumplumbers.com/wp-content/uploads/2021/11/Gardens-Apartment-Plum-plumbers-2-1024x683.jpg | F39: 200 | H39: Content | L39: TRUE | M39: FALSE | N39: TRUE | O39: FALSE | P39: FALSE | Q39: Resource Image Resource | R39: TRUE
A40: Image | B40: FALSE | C40: https://plumplumbers.com/project-type/residential/ | D40: 200 | E40: https://plumplumbers.com/wp-content/uploads/2021/11/balfour-6-600x403.jpg | F40: 200 | H40: Content | L40: TRUE | M40: FALSE | N40: TRUE | O40: FALSE | P40: FALSE | Q40: Resource Image Resource | R40: TRUE
...

Sheet unique images
A1: unique images | B1: used count
A2: {=UNIQUE(images!E2:E145)} -> https://plumplumbers.com/wp-content/uploads/2023/04/ou-meul-bakkery.png | B2: =COUNTIF(images!E2:E145,A2) -> 10
A3: https://plumplumbers.com/wp-content/uploads/2023/04/the-renuvators.png | B3: =COUNTIF(images!E3:E146,A3) -> 10
A4: https://plumplumbers.com/wp-content/uploads/2023/04/hartcon.png | B4: =COUNTIF(images!E4:E147,A4) -> 10
A5: https://plumplumbers.com/wp-content/uploads/2023/04/firemans-arms.png | B5: =COUNTIF(images!E5:E148,A5) -> 10
A6: https://plumplumbers.com/wp-content/uploads/2023/04/glen-3-1024x704.jpg | B6: =COUNTIF(images!E6:E149,A6) -> 2
A7: https://plumplumbers.com/wp-content/uploads/2023/04/dimensions-tents.png | B7: =COUNTIF(images!E7:E150,A7) -> 10
A8: https://plumplumbers.com/wp-content/uploads/2023/04/open-city.png | B8: =COUNTIF(images!E8:E151,A8) -> 10
A9: https://plumplumbers.com/wp-content/uploads/2023/04/logo-pp.png | B9: =COUNTIF(images!E9:E152,A9) -> 13
A10: https://plumplumbers.com/wp-content/uploads/2021/11/Gardens-Apartment-Plum-plumbers-1-1024x683.jpg | B10: =COUNTIF(images!E10:E153,A10) -> 1
A11: https://plumplumbers.com/wp-content/uploads/2023/04/seef.png | B11: =COUNTIF(images!E11:E154,A11) -> 10
A12: https://plumplumbers.com/wp-content/uploads/2023/04/bootlegger.png | B12: =COUNTIF(images!E12:E155,A12) -> 10
A13: https://plumplumbers.com/wp-content/uploads/2021/11/balfour-2.jpg | B13: =COUNTIF(images!E13:E156,A13) -> 1
A14: https://plumplumbers.com/wp-content/uploads/2023/04/pp-retina.png | B14: =COUNTIF(images!E14:E157,A14) -> 10
... A45: https://plumplumbers.com/wp-content/uploads/2023/04/jason2.jpeg | B45: =COUNTIF(images!E45:E188,A45) -> 1

Sheet unique alt text
A1: unique alt text | B1: used count
A2: {=UNIQUE(images!I2:I145)} -> client | B2: =COUNTIF(images!I2:I145,A2) -> 80
B3: =COUNTIF(images!I3:I146,A3) -> 0
A4: Plum Plumbers | B4: =COUNTIF(images!I4:I147,A4) -> 23
