Workbook

Sheet data
A1: URL | B1: Title | C1: Title length | D1: No. of titles | E1: No. of groups having the same title | F1: No. of pages having the same title | G1: Is page title used in SERP | H1: HTTP status code | I1: Is indexable page | J1: Content type | K1: Is rendered page
A2: https://www.pikelandpropertygroup.com/ | B2: Pikeland Property Group - Sell My House Fast - We Buy Houses for Cash | C2: 69 | D2: 1 | E2: 2 | F2: 3 | H2: 200 | I2: TRUE | J2: text/html; charset=utf-8 | K2: TRUE
A3: https://www.pikelandpropertygroup.com/privacy-policy/ | B3: Privacy Policy - Pikeland Property Group | C3: 40 | D3: 1 | E3: 1 | F3: 1 | H3: 200 | I3: TRUE | J3: text/html; charset=utf-8 | K3: TRUE
A4: https://www.pikelandpropertygroup.com/faq/ | B4: FAQ - Pikeland Property Group | C4: 29 | D4: 1 | E4: 1 | F4: 1 | H4: 200 | I4: TRUE | J4: text/html; charset=utf-8 | K4: TRUE
A5: https://www.pikelandpropertygroup.com/how-we-buy-houses/ | B5: How It Works - Pikeland Property Group | C5: 38 | D5: 1 | E5: 1 | F5: 1 | H5: 200 | I5: TRUE | J5: text/html; charset=utf-8 | K5: TRUE
A6: https://www.pikelandpropertygroup.com/contact-us/ | B6: Contact Us - Pikeland Property Group | C6: 36 | D6: 1 | E6: 1 | F6: 1 | H6: 200 | I6: TRUE | J6: text/html; charset=utf-8 | K6: TRUE
A7: https://www.pikelandpropertygroup.com/reviews/ | B7: Reviews - Pikeland Property Group | C7: 33 | D7: 1 | E7: 1 | F7: 1 | H7: 200 | I7: TRUE | J7: text/html; charset=utf-8 | K7: TRUE
A8: https://www.pikelandpropertygroup.com/our-company/ | B8: About Us - Pikeland Property Group | C8: 34 | D8: 1 | E8: 1 | F8: 1 | H8: 200 | I8: TRUE | J8: text/html; charset=utf-8 | K8: TRUE
A9: https://www.pikelandpropertygroup.com/get-your-offer/ | B9: Get Your Offer - Pikeland Property Group | C9: 40 | D9: 1 | E9: 1 | F9: 1 | H9: 200 | I9: TRUE | J9: text/html; charset=utf-8 | K9: TRUE
A10: https://www.pikelandpropertygroup.com/blog/category/sellers/ | B10: sellers Archives - Pikeland Property Group | C10: 42 | D10: 1 | E10: 1 | F10: 1 | H10: 200 | I10: TRUE | J10: text/html; charset=utf-8 | K10: TRUE
A11: https://www.pikelandpropertygroup.com/blog/author/harrisonpikelandpropertygroup-com/ | B11: Harrison Hall, Author at Pikeland Property Group | C11: 48 | D11: 1 | E11: 1 | F11: 1 | H11: 200 | I11: TRUE | J11: text/html; charset=utf-8 | K11: TRUE
A12: https://www.pikelandpropertygroup.com/blog/category/building-credibility/ | B12: building-credibility Archives - Pikeland Property Group | C12: 55 | D12: 1 | E12: 1 | F12: 1 | H12: 200 | I12: TRUE | J12: text/html; charset=utf-8 | K12: TRUE
A13: https://www.pikelandpropertygroup.com/blog/category/buying-mobile-homes/ | B13: buying-mobile-homes Archives - Pikeland Property Group | C13: 54 | D13: 1 | E13: 1 | F13: 1 | H13: 200 | I13: TRUE | J13: text/html; charset=utf-8 | K13: TRUE
... A25: https://www.pikelandpropertygroup.com/blog/2023/08/ | B25: August 2023 - Pikeland Property Group | C25: 37 | D25: 1 | E25: 1 | F25: 1 | H25: 200 | I25: FALSE | J25: text/html; charset=utf-8 | K25: TRUE
A26: https://www.pikelandpropertygroup.com/stop-foreclosure/ | D26: 0 | H26: 404 | I26: FALSE | J26: text/html; charset=utf-8 | K26: FALSE
A27: https://www.pikelandpropertygroup.com/blog/faq-items/what-if-i-dont-need-a-fast-closing/ | B27: What if I don’t need a fast closing? - Pikeland Property Group | C27: 62 | D27: 1 | E27: 1 | F27: 1 | H27: 200 | I27: TRUE | J27: text/html; charset=utf-8 | K27: TRUE
A28: https://www.pikelandpropertygroup.com/blog/selling-a-property-that-needs-repairs-in-pennsylvania/ | B28: 6 Things You Need to Know About Selling a Property That Needs Repairs in Pennsylvania - Pikeland Property Group | C28: 111 | D28: 1 | E28: 1 | F28: 1 | H28: 200 | I28: TRUE | J28: text/html; charset=utf-8 | K28: TRUE
A29: https://www.pikelandpropertygroup.com/blog/selling-your-home-to-a-direct-buyer-pennsylvania/ | B29: 5 Mistakes to Avoid When Selling Your Home to a Direct Buyer in Pennsylvania - Pikeland Property Group | C29: 102 | D29: 1 | E29: 1 | F29: 1 | H29: 200 | I29: TRUE | J29: text/html; charset=utf-8 | K29: TRUE
A30: https://www.pikelandpropertygroup.com/blog/faq-items/what-are-the-benefits-of-selling-my-house-in-pennsylvania-to-a-cash-home-buyer/ | B30: What Are the Benefits of Selling My House in Pennsylvania To A Cash Home Buyer? - Pikeland Property Group | C30: 105 | D30: 1 | E30: 1 | F30: 1 | H30: 200 | I30: TRUE | J30: text/html; charset=utf-8 | K30: TRUE
A31: https://www.pikelandpropertygroup.com/blog/faq-items/how-fast-is-a-fast-closing/ | B31: How fast is a fast closing? - Pikeland Property Group | C31: 53 | D31: 1 | E31: 1 | F31: 1 | H31: 200 | I31: TRUE | J31: text/html; charset=utf-8 | K31: TRUE
A32: https://www.pikelandpropertygroup.com/blog/low-earning-vacation-rental-in-pennsylvania/ | B32: 5 Solutions to Help You With Your Low-Earning Vacation Rental in Pennsylvania - Pikeland Property Group | C32: 103 | D32: 1 | E32: 1 | F32: 1 | H32: 200 | I32: TRUE | J32: text/html; charset=utf-8 | K32: TRUE
A33: https://www.pikelandpropertygroup.com/blog/faq-items/how-are-you-different-from-a-real-estate-agent/ | B33: How are you different from a real estate agent? - Pikeland Property Group | C33: 73 | D33: 1 | E33: 1 | F33: 1 | H33: 200 | I33: TRUE | J33: text/html; charset=utf-8 | K33: TRUE
A34: https://www.pikelandpropertygroup.com/blog/faq-items/learn-about-our-process-and-sell-your-house-today/ | B34: Learn About Our Process and Sell Your House Today! - Pikeland Property Group | C34: 76 | D34: 1 | E34: 1 | F34: 1 | H34: 200 | I34: TRUE | J34: text/html; charset=utf-8 | K34: TRUE
A35: https://www.pikelandpropertygroup.com/blog/selling-your-home-to-a-direct-buyer-in-pennsylvania-3/ | B35: 6 Advantages of Selling Your Home to a Direct Buyer in Pennsylvania That You Might Not Know About - Pikeland Property Group | C35: 123 | D35: 1 | E35: 1 | F35: 1 | H35: 200 | I35: TRUE | J35: text/html; charset=utf-8 | K35: TRUE
A36: https://www.pikelandpropertygroup.com/blog/design-elements-that-can-make-it-difficult-to-sell-your-house-pennsylvania/ | B36: Dated Design Elements That Can make it Difficult to Sell Your House in Pennsylvania - Pikeland Property Group | C36: 109 | D36: 1 | E36: 1 | F36: 1 | H36: 200 | I36: TRUE | J36: text/html; charset=utf-8 | K36: TRUE
A37: https://www.pikelandpropertygroup.com/blog/selling-mobile-homes-pennsylvania/ | B37: Maximizing ROI: How to Make the Most Profit from Buying and Selling Mobile Homes in Pennsylvania - Pikeland Property Group | C37: 122 | D37: 1 | E37: 1 | F37: 1 | H37: 200 | I37: TRUE | J37: text/html; charset=utf-8 | K37: TRUE
A38: https://www.pikelandpropertygroup.com/blog/buying-and-selling-mobile-homes-pennsylvania/ | B38: Maximizing Profits: Tips for Buying and Selling Mobile Homes in Pennsylvania - Pikeland Property Group | C38: 102 | D38: 1 | E38: 1 | F38: 1 | H38: 200 | I38: TRUE | J38: text/html; charset=utf-8 | K38: TRUE
... A90: https://www.pikelandpropertygroup.com/blog/page/3/ | B90: Blog - Pikeland Property Group | C90: 30 | D90: 1 | E90: 1 | F90: 3 | H90: 200 | I90: FALSE | J90: text/html; charset=utf-8 | K90: TRUE
A91: https://www.pikelandpropertygroup.com/blog/faq_category/general/ | D91: 0 | H91: 404 | I91: FALSE | J91: text/html; charset=utf-8 | K91: FALSE
A92: https://www.pikelandpropertygroup.com/blog/fusion_tb_category/header/ | D92: 0 | H92: 301 | I92: FALSE | J92: text/html; charset=utf-8 | K92: FALSE
A93: https://www.pikelandpropertygroup.com/blog/fusion_tb_category/content/ | D93: 0 | H93: 301 | I93: FALSE | J93: text/html; charset=utf-8 | K93: FALSE
A94: https://www.pikelandpropertygroup.com/blog/element_category/elements/ | D94: 0 | H94: 301 | I94: FALSE | J94: text/html; charset=utf-8 | K94: FALSE
A95: https://www.pikelandpropertygroup.com/blog/page/4/ | B95: Blog - Pikeland Property Group | C95: 30 | D95: 1 | H95: 200 | I95: FALSE | J95: text/html; charset=utf-8 | K95: TRUE
A96: https://www.pikelandpropertygroup.com/blog/fusion_tb_category/page_title_bar/ | D96: 0 | H96: 301 | I96: FALSE | J96: text/html; charset=utf-8 | K96: FALSE
A97: https://www.pikelandpropertygroup.com/wp-content/uploads/2023/07/How-To-Stop-Foreclosure-Guide.pdf | D97: 0 | H97: 200 | I97: FALSE | J97: application/pdf | K97: FALSE
A98: https://www.pikelandpropertygroup.com/blog/element_category/sections/ | D98: 0 | H98: 301 | I98: FALSE | J98: text/html; charset=utf-8 | K98: FALSE
A99: https://www.pikelandpropertygroup.com/blog/faq_category/how-we-buy-houses/ | D99: 0 | H99: 301 | I99: FALSE | J99: text/html; charset=utf-8 | K99: FALSE
A100: https://www.pikelandpropertygroup.com/blog/faq_category/home/ | D100: 0 | H100: 404 | I100: FALSE | J100: text/html; charset=utf-8 | K100: FALSE
A101: https://www.pikelandpropertygroup.com/blog/element_category/post_cards/ | D101: 0 | H101: 301 | I101: FALSE | J101: text/html; charset=utf-8 | K101: FALSE
A102: http://www.pikelandpropertygroup.com/ | D102: 0 | H102: 301 | I102: FALSE | J102: text/html | K102: FALSE
...

Sheet short-
A1: URL | B1: Title | C1: Title length | D1: No. of titles | E1: No. of groups having the same title | F1: No. of pages having the same title | G1: Is page title used in SERP | H1: HTTP status code | I1: Is indexable page | J1: Content type | K1: Is rendered page
A2: https://www.pikelandpropertygroup.com/ | B2: Pikeland Property Group - Sell My House Fast - We Buy Houses for Cash | C2: 69 | D2: 1 | E2: 2 | F2: 3 | H2: 200 | I2: TRUE | J2: text/html; charset=utf-8 | K2: TRUE
A3: https://www.pikelandpropertygroup.com/privacy-policy/ | B3: Privacy Policy - Pikeland Property Group | C3: 40 | D3: 1 | E3: 1 | F3: 1 | H3: 200 | I3: TRUE | J3: text/html; charset=utf-8 | K3: TRUE
A4: https://www.pikelandpropertygroup.com/faq/ | B4: FAQ - Pikeland Property Group | C4: 29 | D4: 1 | E4: 1 | F4: 1 | H4: 200 | I4: TRUE | J4: text/html; charset=utf-8 | K4: TRUE
A5: https://www.pikelandpropertygroup.com/how-we-buy-houses/ | B5: How It Works - Pikeland Property Group | C5: 38 | D5: 1 | E5: 1 | F5: 1 | H5: 200 | I5: TRUE | J5: text/html; charset=utf-8 | K5: TRUE
A6: https://www.pikelandpropertygroup.com/contact-us/ | B6: Contact Us - Pikeland Property Group | C6: 36 | D6: 1 | E6: 1 | F6: 1 | H6: 200 | I6: TRUE | J6: text/html; charset=utf-8 | K6: TRUE
A7: https://www.pikelandpropertygroup.com/reviews/ | B7: Reviews - Pikeland Property Group | C7: 33 | D7: 1 | E7: 1 | F7: 1 | H7: 200 | I7: TRUE | J7: text/html; charset=utf-8 | K7: TRUE
A8: https://www.pikelandpropertygroup.com/our-company/ | B8: About Us - Pikeland Property Group | C8: 34 | D8: 1 | E8: 1 | F8: 1 | H8: 200 | I8: TRUE | J8: text/html; charset=utf-8 | K8: TRUE
A9: https://www.pikelandpropertygroup.com/get-your-offer/ | B9: Get Your Offer - Pikeland Property Group | C9: 40 | D9: 1 | E9: 1 | F9: 1 | H9: 200 | I9: TRUE | J9: text/html; charset=utf-8 | K9: TRUE
A10: https://www.pikelandpropertygroup.com/blog/category/sellers/ | B10: sellers Archives - Pikeland Property Group | C10: 42 | D10: 1 | E10: 1 | F10: 1 | H10: 200 | I10: TRUE | J10: text/html; charset=utf-8 | K10: TRUE
A11: https://www.pikelandpropertygroup.com/blog/author/harrisonpikelandpropertygroup-com/ | B11: Harrison Hall, Author at Pikeland Property Group | C11: 48 | D11: 1 | E11: 1 | F11: 1 | H11: 200 | I11: TRUE | J11: text/html; charset=utf-8 | K11: TRUE
A12: https://www.pikelandpropertygroup.com/blog/category/building-credibility/ | B12: building-credibility Archives - Pikeland Property Group | C12: 55 | D12: 1 | E12: 1 | F12: 1 | H12: 200 | I12: TRUE | J12: text/html; charset=utf-8 | K12: TRUE
A13: https://www.pikelandpropertygroup.com/blog/category/buying-mobile-homes/ | B13: buying-mobile-homes Archives - Pikeland Property Group | C13: 54 | D13: 1 | E13: 1 | F13: 1 | H13: 200 | I13: TRUE | J13: text/html; charset=utf-8 | K13: TRUE
... A25: https://www.pikelandpropertygroup.com/blog/2023/08/ | B25: August 2023 - Pikeland Property Group | C25: 37 | D25: 1 | E25: 1 | F25: 1 | H25: 200 | I25: FALSE | J25: text/html; charset=utf-8 | K25: TRUE
A26: https://www.pikelandpropertygroup.com/stop-foreclosure/ | D26: 0 | H26: 404 | I26: FALSE | J26: text/html; charset=utf-8 | K26: FALSE
A27: https://www.pikelandpropertygroup.com/blog/faq-items/what-if-i-dont-need-a-fast-closing/ | B27: What if I don’t need a fast closing? - Pikeland Property Group | C27: 62 | D27: 1 | E27: 1 | F27: 1 | H27: 200 | I27: TRUE | J27: text/html; charset=utf-8 | K27: TRUE
A28: https://www.pikelandpropertygroup.com/blog/selling-a-property-that-needs-repairs-in-pennsylvania/ | B28: 6 Things You Need to Know About Selling a Property That Needs Repairs in Pennsylvania - Pikeland Property Group | C28: 111 | D28: 1 | E28: 1 | F28: 1 | H28: 200 | I28: TRUE | J28: text/html; charset=utf-8 | K28: TRUE
A29: https://www.pikelandpropertygroup.com/blog/selling-your-home-to-a-direct-buyer-pennsylvania/ | B29: 5 Mistakes to Avoid When Selling Your Home to a Direct Buyer in Pennsylvania - Pikeland Property Group | C29: 102 | D29: 1 | E29: 1 | F29: 1 | H29: 200 | I29: TRUE | J29: text/html; charset=utf-8 | K29: TRUE
A30: https://www.pikelandpropertygroup.com/blog/faq-items/what-are-the-benefits-of-selling-my-house-in-pennsylvania-to-a-cash-home-buyer/ | B30: What Are the Benefits of Selling My House in Pennsylvania To A Cash Home Buyer? - Pikeland Property Group | C30: 105 | D30: 1 | E30: 1 | F30: 1 | H30: 200 | I30: TRUE | J30: text/html; charset=utf-8 | K30: TRUE
A31: https://www.pikelandpropertygroup.com/blog/faq-items/how-fast-is-a-fast-closing/ | B31: How fast is a fast closing? - Pikeland Property Group | C31: 53 | D31: 1 | E31: 1 | F31: 1 | H31: 200 | I31: TRUE | J31: text/html; charset=utf-8 | K31: TRUE
A32: https://www.pikelandpropertygroup.com/blog/low-earning-vacation-rental-in-pennsylvania/ | B32: 5 Solutions to Help You With Your Low-Earning Vacation Rental in Pennsylvania - Pikeland Property Group | C32: 103 | D32: 1 | E32: 1 | F32: 1 | H32: 200 | I32: TRUE | J32: text/html; charset=utf-8 | K32: TRUE
A33: https://www.pikelandpropertygroup.com/blog/faq-items/how-are-you-different-from-a-real-estate-agent/ | B33: How are you different from a real estate agent? - Pikeland Property Group | C33: 73 | D33: 1 | E33: 1 | F33: 1 | H33: 200 | I33: TRUE | J33: text/html; charset=utf-8 | K33: TRUE
A34: https://www.pikelandpropertygroup.com/blog/faq-items/learn-about-our-process-and-sell-your-house-today/ | B34: Learn About Our Process and Sell Your House Today! - Pikeland Property Group | C34: 76 | D34: 1 | E34: 1 | F34: 1 | H34: 200 | I34: TRUE | J34: text/html; charset=utf-8 | K34: TRUE
A35: https://www.pikelandpropertygroup.com/blog/selling-your-home-to-a-direct-buyer-in-pennsylvania-3/ | B35: 6 Advantages of Selling Your Home to a Direct Buyer in Pennsylvania That You Might Not Know About - Pikeland Property Group | C35: 123 | D35: 1 | E35: 1 | F35: 1 | H35: 200 | I35: TRUE | J35: text/html; charset=utf-8 | K35: TRUE
A36: https://www.pikelandpropertygroup.com/blog/design-elements-that-can-make-it-difficult-to-sell-your-house-pennsylvania/ | B36: Dated Design Elements That Can make it Difficult to Sell Your House in Pennsylvania - Pikeland Property Group | C36: 109 | D36: 1 | E36: 1 | F36: 1 | H36: 200 | I36: TRUE | J36: text/html; charset=utf-8 | K36: TRUE
A37: https://www.pikelandpropertygroup.com/blog/selling-mobile-homes-pennsylvania/ | B37: Maximizing ROI: How to Make the Most Profit from Buying and Selling Mobile Homes in Pennsylvania - Pikeland Property Group | C37: 122 | D37: 1 | E37: 1 | F37: 1 | H37: 200 | I37: TRUE | J37: text/html; charset=utf-8 | K37: TRUE
A38: https://www.pikelandpropertygroup.com/blog/buying-and-selling-mobile-homes-pennsylvania/ | B38: Maximizing Profits: Tips for Buying and Selling Mobile Homes in Pennsylvania - Pikeland Property Group | C38: 102 | D38: 1 | E38: 1 | F38: 1 | H38: 200 | I38: TRUE | J38: text/html; charset=utf-8 | K38: TRUE
... A90: https://www.pikelandpropertygroup.com/blog/page/3/ | B90: Blog - Pikeland Property Group | C90: 30 | D90: 1 | E90: 1 | F90: 3 | H90: 200 | I90: FALSE | J90: text/html; charset=utf-8 | K90: TRUE
A91: https://www.pikelandpropertygroup.com/blog/faq_category/general/ | D91: 0 | H91: 404 | I91: FALSE | J91: text/html; charset=utf-8 | K91: FALSE
A92: https://www.pikelandpropertygroup.com/blog/fusion_tb_category/header/ | D92: 0 | H92: 301 | I92: FALSE | J92: text/html; charset=utf-8 | K92: FALSE
A93: https://www.pikelandpropertygroup.com/blog/fusion_tb_category/content/ | D93: 0 | H93: 301 | I93: FALSE | J93: text/html; charset=utf-8 | K93: FALSE
A94: https://www.pikelandpropertygroup.com/blog/element_category/elements/ | D94: 0 | H94: 301 | I94: FALSE | J94: text/html; charset=utf-8 | K94: FALSE
A95: https://www.pikelandpropertygroup.com/blog/page/4/ | B95: Blog - Pikeland Property Group | C95: 30 | D95: 1 | H95: 200 | I95: FALSE | J95: text/html; charset=utf-8 | K95: TRUE
A96: https://www.pikelandpropertygroup.com/blog/fusion_tb_category/page_title_bar/ | D96: 0 | H96: 301 | I96: FALSE | J96: text/html; charset=utf-8 | K96: FALSE
A97: https://www.pikelandpropertygroup.com/wp-content/uploads/2023/07/How-To-Stop-Foreclosure-Guide.pdf | D97: 0 | H97: 200 | I97: FALSE | J97: application/pdf | K97: FALSE
A98: https://www.pikelandpropertygroup.com/blog/element_category/sections/ | D98: 0 | H98: 301 | I98: FALSE | J98: text/html; charset=utf-8 | K98: FALSE
A99: https://www.pikelandpropertygroup.com/blog/faq_category/how-we-buy-houses/ | D99: 0 | H99: 301 | I99: FALSE | J99: text/html; charset=utf-8 | K99: FALSE
A100: https://www.pikelandpropertygroup.com/blog/faq_category/home/ | D100: 0 | H100: 404 | I100: FALSE | J100: text/html; charset=utf-8 | K100: FALSE
A101: https://www.pikelandpropertygroup.com/blog/element_category/post_cards/ | D101: 0 | H101: 301 | I101: FALSE | J101: text/html; charset=utf-8 | K101: FALSE
A102: http://www.pikelandpropertygroup.com/ | D102: 0 | H102: 301 | I102: FALSE | J102: text/html | K102: FALSE
...

Sheet long-
A1: URL | B1: Title | C1: Title length | D1: No. of titles | E1: No. of groups having the same title | F1: No. of pages having the same title | G1: Is page title used in SERP | H1: HTTP status code | I1: Is indexable page | J1: Content type | K1: Is rendered page
A2: https://www.pikelandpropertygroup.com/ | B2: Pikeland Property Group - Sell My House Fast - We Buy Houses for Cash | C2: 69 | D2: 1 | E2: 2 | F2: 3 | H2: 200 | I2: TRUE | J2: text/html; charset=utf-8 | K2: TRUE
A3: https://www.pikelandpropertygroup.com/privacy-policy/ | B3: Privacy Policy - Pikeland Property Group | C3: 40 | D3: 1 | E3: 1 | F3: 1 | H3: 200 | I3: TRUE | J3: text/html; charset=utf-8 | K3: TRUE
A4: https://www.pikelandpropertygroup.com/faq/ | B4: FAQ - Pikeland Property Group | C4: 29 | D4: 1 | E4: 1 | F4: 1 | H4: 200 | I4: TRUE | J4: text/html; charset=utf-8 | K4: TRUE
A5: https://www.pikelandpropertygroup.com/how-we-buy-houses/ | B5: How It Works - Pikeland Property Group | C5: 38 | D5: 1 | E5: 1 | F5: 1 | H5: 200 | I5: TRUE | J5: text/html; charset=utf-8 | K5: TRUE
A6: https://www.pikelandpropertygroup.com/contact-us/ | B6: Contact Us - Pikeland Property Group | C6: 36 | D6: 1 | E6: 1 | F6: 1 | H6: 200 | I6: TRUE | J6: text/html; charset=utf-8 | K6: TRUE
A7: https://www.pikelandpropertygroup.com/reviews/ | B7: Reviews - Pikeland Property Group | C7: 33 | D7: 1 | E7: 1 | F7: 1 | H7: 200 | I7: TRUE | J7: text/html; charset=utf-8 | K7: TRUE
A8: https://www.pikelandpropertygroup.com/our-company/ | B8: About Us - Pikeland Property Group | C8: 34 | D8: 1 | E8: 1 | F8: 1 | H8: 200 | I8: TRUE | J8: text/html; charset=utf-8 | K8: TRUE
A9: https://www.pikelandpropertygroup.com/get-your-offer/ | B9: Get Your Offer - Pikeland Property Group | C9: 40 | D9: 1 | E9: 1 | F9: 1 | H9: 200 | I9: TRUE | J9: text/html; charset=utf-8 | K9: TRUE
A10: https://www.pikelandpropertygroup.com/blog/category/sellers/ | B10: sellers Archives - Pikeland Property Group | C10: 42 | D10: 1 | E10: 1 | F10: 1 | H10: 200 | I10: TRUE | J10: text/html; charset=utf-8 | K10: TRUE
A11: https://www.pikelandpropertygroup.com/blog/author/harrisonpikelandpropertygroup-com/ | B11: Harrison Hall, Author at Pikeland Property Group | C11: 48 | D11: 1 | E11: 1 | F11: 1 | H11: 200 | I11: TRUE | J11: text/html; charset=utf-8 | K11: TRUE
A12: https://www.pikelandpropertygroup.com/blog/category/building-credibility/ | B12: building-credibility Archives - Pikeland Property Group | C12: 55 | D12: 1 | E12: 1 | F12: 1 | H12: 200 | I12: TRUE | J12: text/html; charset=utf-8 | K12: TRUE
A13: https://www.pikelandpropertygroup.com/blog/category/buying-mobile-homes/ | B13: buying-mobile-homes Archives - Pikeland Property Group | C13: 54 | D13: 1 | E13: 1 | F13: 1 | H13: 200 | I13: TRUE | J13: text/html; charset=utf-8 | K13: TRUE
... A25: https://www.pikelandpropertygroup.com/blog/2023/08/ | B25: August 2023 - Pikeland Property Group | C25: 37 | D25: 1 | E25: 1 | F25: 1 | H25: 200 | I25: FALSE | J25: text/html; charset=utf-8 | K25: TRUE
A26: https://www.pikelandpropertygroup.com/stop-foreclosure/ | D26: 0 | H26: 404 | I26: FALSE | J26: text/html; charset=utf-8 | K26: FALSE
A27: https://www.pikelandpropertygroup.com/blog/faq-items/what-if-i-dont-need-a-fast-closing/ | B27: What if I don’t need a fast closing? - Pikeland Property Group | C27: 62 | D27: 1 | E27: 1 | F27: 1 | H27: 200 | I27: TRUE | J27: text/html; charset=utf-8 | K27: TRUE
A28: https://www.pikelandpropertygroup.com/blog/selling-a-property-that-needs-repairs-in-pennsylvania/ | B28: 6 Things You Need to Know About Selling a Property That Needs Repairs in Pennsylvania - Pikeland Property Group | C28: 111 | D28: 1 | E28: 1 | F28: 1 | H28: 200 | I28: TRUE | J28: text/html; charset=utf-8 | K28: TRUE
A29: https://www.pikelandpropertygroup.com/blog/selling-your-home-to-a-direct-buyer-pennsylvania/ | B29: 5 Mistakes to Avoid When Selling Your Home to a Direct Buyer in Pennsylvania - Pikeland Property Group | C29: 102 | D29: 1 | E29: 1 | F29: 1 | H29: 200 | I29: TRUE | J29: text/html; charset=utf-8 | K29: TRUE
A30: https://www.pikelandpropertygroup.com/blog/faq-items/what-are-the-benefits-of-selling-my-house-in-pennsylvania-to-a-cash-home-buyer/ | B30: What Are the Benefits of Selling My House in Pennsylvania To A Cash Home Buyer? - Pikeland Property Group | C30: 105 | D30: 1 | E30: 1 | F30: 1 | H30: 200 | I30: TRUE | J30: text/html; charset=utf-8 | K30: TRUE
A31: https://www.pikelandpropertygroup.com/blog/faq-items/how-fast-is-a-fast-closing/ | B31: How fast is a fast closing? - Pikeland Property Group | C31: 53 | D31: 1 | E31: 1 | F31: 1 | H31: 200 | I31: TRUE | J31: text/html; charset=utf-8 | K31: TRUE
A32: https://www.pikelandpropertygroup.com/blog/low-earning-vacation-rental-in-pennsylvania/ | B32: 5 Solutions to Help You With Your Low-Earning Vacation Rental in Pennsylvania - Pikeland Property Group | C32: 103 | D32: 1 | E32: 1 | F32: 1 | H32: 200 | I32: TRUE | J32: text/html; charset=utf-8 | K32: TRUE
A33: https://www.pikelandpropertygroup.com/blog/faq-items/how-are-you-different-from-a-real-estate-agent/ | B33: How are you different from a real estate agent? - Pikeland Property Group | C33: 73 | D33: 1 | E33: 1 | F33: 1 | H33: 200 | I33: TRUE | J33: text/html; charset=utf-8 | K33: TRUE
A34: https://www.pikelandpropertygroup.com/blog/faq-items/learn-about-our-process-and-sell-your-house-today/ | B34: Learn About Our Process and Sell Your House Today! - Pikeland Property Group | C34: 76 | D34: 1 | E34: 1 | F34: 1 | H34: 200 | I34: TRUE | J34: text/html; charset=utf-8 | K34: TRUE
A35: https://www.pikelandpropertygroup.com/blog/selling-your-home-to-a-direct-buyer-in-pennsylvania-3/ | B35: 6 Advantages of Selling Your Home to a Direct Buyer in Pennsylvania That You Might Not Know About - Pikeland Property Group | C35: 123 | D35: 1 | E35: 1 | F35: 1 | H35: 200 | I35: TRUE | J35: text/html; charset=utf-8 | K35: TRUE
A36: https://www.pikelandpropertygroup.com/blog/design-elements-that-can-make-it-difficult-to-sell-your-house-pennsylvania/ | B36: Dated Design Elements That Can make it Difficult to Sell Your House in Pennsylvania - Pikeland Property Group | C36: 109 | D36: 1 | E36: 1 | F36: 1 | H36: 200 | I36: TRUE | J36: text/html; charset=utf-8 | K36: TRUE
A37: https://www.pikelandpropertygroup.com/blog/selling-mobile-homes-pennsylvania/ | B37: Maximizing ROI: How to Make the Most Profit from Buying and Selling Mobile Homes in Pennsylvania - Pikeland Property Group | C37: 122 | D37: 1 | E37: 1 | F37: 1 | H37: 200 | I37: TRUE | J37: text/html; charset=utf-8 | K37: TRUE
A38: https://www.pikelandpropertygroup.com/blog/buying-and-selling-mobile-homes-pennsylvania/ | B38: Maximizing Profits: Tips for Buying and Selling Mobile Homes in Pennsylvania - Pikeland Property Group | C38: 102 | D38: 1 | E38: 1 | F38: 1 | H38: 200 | I38: TRUE | J38: text/html; charset=utf-8 | K38: TRUE
... A90: https://www.pikelandpropertygroup.com/blog/page/3/ | B90: Blog - Pikeland Property Group | C90: 30 | D90: 1 | E90: 1 | F90: 3 | H90: 200 | I90: FALSE | J90: text/html; charset=utf-8 | K90: TRUE
A91: https://www.pikelandpropertygroup.com/blog/faq_category/general/ | D91: 0 | H91: 404 | I91: FALSE | J91: text/html; charset=utf-8 | K91: FALSE
A92: https://www.pikelandpropertygroup.com/blog/fusion_tb_category/header/ | D92: 0 | H92: 301 | I92: FALSE | J92: text/html; charset=utf-8 | K92: FALSE
A93: https://www.pikelandpropertygroup.com/blog/fusion_tb_category/content/ | D93: 0 | H93: 301 | I93: FALSE | J93: text/html; charset=utf-8 | K93: FALSE
A94: https://www.pikelandpropertygroup.com/blog/element_category/elements/ | D94: 0 | H94: 301 | I94: FALSE | J94: text/html; charset=utf-8 | K94: FALSE
A95: https://www.pikelandpropertygroup.com/blog/page/4/ | B95: Blog - Pikeland Property Group | C95: 30 | D95: 1 | H95: 200 | I95: FALSE | J95: text/html; charset=utf-8 | K95: TRUE
A96: https://www.pikelandpropertygroup.com/blog/fusion_tb_category/page_title_bar/ | D96: 0 | H96: 301 | I96: FALSE | J96: text/html; charset=utf-8 | K96: FALSE
A97: https://www.pikelandpropertygroup.com/wp-content/uploads/2023/07/How-To-Stop-Foreclosure-Guide.pdf | D97: 0 | H97: 200 | I97: FALSE | J97: application/pdf | K97: FALSE
A98: https://www.pikelandpropertygroup.com/blog/element_category/sections/ | D98: 0 | H98: 301 | I98: FALSE | J98: text/html; charset=utf-8 | K98: FALSE
A99: https://www.pikelandpropertygroup.com/blog/faq_category/how-we-buy-houses/ | D99: 0 | H99: 301 | I99: FALSE | J99: text/html; charset=utf-8 | K99: FALSE
A100: https://www.pikelandpropertygroup.com/blog/faq_category/home/ | D100: 0 | H100: 404 | I100: FALSE | J100: text/html; charset=utf-8 | K100: FALSE
A101: https://www.pikelandpropertygroup.com/blog/element_category/post_cards/ | D101: 0 | H101: 301 | I101: FALSE | J101: text/html; charset=utf-8 | K101: FALSE
A102: http://www.pikelandpropertygroup.com/ | D102: 0 | H102: 301 | I102: FALSE | J102: text/html | K102: FALSE
...

Sheet duplicates-
A1: URL | B1: Title | C1: Title length | D1: No. of titles | E1: No. of groups having the same title | F1: No. of pages having the same title | G1: Is page title used in SERP | H1: HTTP status code | I1: Is indexable page | J1: Content type | K1: Is rendered page
A2: https://www.pikelandpropertygroup.com/ | B2: Pikeland Property Group - Sell My House Fast - We Buy Houses for Cash | C2: 69 | D2: 1 | E2: 2 | F2: 3 | H2: 200 | I2: TRUE | J2: text/html; charset=utf-8 | K2: TRUE
A3: https://www.pikelandpropertygroup.com/privacy-policy/ | B3: Privacy Policy - Pikeland Property Group | C3: 40 | D3: 1 | E3: 1 | F3: 1 | H3: 200 | I3: TRUE | J3: text/html; charset=utf-8 | K3: TRUE
A4: https://www.pikelandpropertygroup.com/faq/ | B4: FAQ - Pikeland Property Group | C4: 29 | D4: 1 | E4: 1 | F4: 1 | H4: 200 | I4: TRUE | J4: text/html; charset=utf-8 | K4: TRUE
A5: https://www.pikelandpropertygroup.com/how-we-buy-houses/ | B5: How It Works - Pikeland Property Group | C5: 38 | D5: 1 | E5: 1 | F5: 1 | H5: 200 | I5: TRUE | J5: text/html; charset=utf-8 | K5: TRUE
A6: https://www.pikelandpropertygroup.com/contact-us/ | B6: Contact Us - Pikeland Property Group | C6: 36 | D6: 1 | E6: 1 | F6: 1 | H6: 200 | I6: TRUE | J6: text/html; charset=utf-8 | K6: TRUE
A7: https://www.pikelandpropertygroup.com/reviews/ | B7: Reviews - Pikeland Property Group | C7: 33 | D7: 1 | E7: 1 | F7: 1 | H7: 200 | I7: TRUE | J7: text/html; charset=utf-8 | K7: TRUE
A8: https://www.pikelandpropertygroup.com/our-company/ | B8: About Us - Pikeland Property Group | C8: 34 | D8: 1 | E8: 1 | F8: 1 | H8: 200 | I8: TRUE | J8: text/html; charset=utf-8 | K8: TRUE
A9: https://www.pikelandpropertygroup.com/get-your-offer/ | B9: Get Your Offer - Pikeland Property Group | C9: 40 | D9: 1 | E9: 1 | F9: 1 | H9: 200 | I9: TRUE | J9: text/html; charset=utf-8 | K9: TRUE
A10: https://www.pikelandpropertygroup.com/blog/category/sellers/ | B10: sellers Archives - Pikeland Property Group | C10: 42 | D10: 1 | E10: 1 | F10: 1 | H10: 200 | I10: TRUE | J10: text/html; charset=utf-8 | K10: TRUE
A11: https://www.pikelandpropertygroup.com/blog/author/harrisonpikelandpropertygroup-com/ | B11: Harrison Hall, Author at Pikeland Property Group | C11: 48 | D11: 1 | E11: 1 | F11: 1 | H11: 200 | I11: TRUE | J11: text/html; charset=utf-8 | K11: TRUE
A12: https://www.pikelandpropertygroup.com/blog/category/building-credibility/ | B12: building-credibility Archives - Pikeland Property Group | C12: 55 | D12: 1 | E12: 1 | F12: 1 | H12: 200 | I12: TRUE | J12: text/html; charset=utf-8 | K12: TRUE
A13: https://www.pikelandpropertygroup.com/blog/category/buying-mobile-homes/ | B13: buying-mobile-homes Archives - Pikeland Property Group | C13: 54 | D13: 1 | E13: 1 | F13: 1 | H13: 200 | I13: TRUE | J13: text/html; charset=utf-8 | K13: TRUE
... A25: https://www.pikelandpropertygroup.com/blog/2023/08/ | B25: August 2023 - Pikeland Property Group | C25: 37 | D25: 1 | E25: 1 | F25: 1 | H25: 200 | I25: FALSE | J25: text/html; charset=utf-8 | K25: TRUE
A26: https://www.pikelandpropertygroup.com/stop-foreclosure/ | D26: 0 | H26: 404 | I26: FALSE | J26: text/html; charset=utf-8 | K26: FALSE
A27: https://www.pikelandpropertygroup.com/blog/faq-items/what-if-i-dont-need-a-fast-closing/ | B27: What if I don’t need a fast closing? - Pikeland Property Group | C27: 62 | D27: 1 | E27: 1 | F27: 1 | H27: 200 | I27: TRUE | J27: text/html; charset=utf-8 | K27: TRUE
A28: https://www.pikelandpropertygroup.com/blog/selling-a-property-that-needs-repairs-in-pennsylvania/ | B28: 6 Things You Need to Know About Selling a Property That Needs Repairs in Pennsylvania - Pikeland Property Group | C28: 111 | D28: 1 | E28: 1 | F28: 1 | H28: 200 | I28: TRUE | J28: text/html; charset=utf-8 | K28: TRUE
A29: https://www.pikelandpropertygroup.com/blog/selling-your-home-to-a-direct-buyer-pennsylvania/ | B29: 5 Mistakes to Avoid When Selling Your Home to a Direct Buyer in Pennsylvania - Pikeland Property Group | C29: 102 | D29: 1 | E29: 1 | F29: 1 | H29: 200 | I29: TRUE | J29: text/html; charset=utf-8 | K29: TRUE
A30: https://www.pikelandpropertygroup.com/blog/faq-items/what-are-the-benefits-of-selling-my-house-in-pennsylvania-to-a-cash-home-buyer/ | B30: What Are the Benefits of Selling My House in Pennsylvania To A Cash Home Buyer? - Pikeland Property Group | C30: 105 | D30: 1 | E30: 1 | F30: 1 | H30: 200 | I30: TRUE | J30: text/html; charset=utf-8 | K30: TRUE
A31: https://www.pikelandpropertygroup.com/blog/faq-items/how-fast-is-a-fast-closing/ | B31: How fast is a fast closing? - Pikeland Property Group | C31: 53 | D31: 1 | E31: 1 | F31: 1 | H31: 200 | I31: TRUE | J31: text/html; charset=utf-8 | K31: TRUE
A32: https://www.pikelandpropertygroup.com/blog/low-earning-vacation-rental-in-pennsylvania/ | B32: 5 Solutions to Help You With Your Low-Earning Vacation Rental in Pennsylvania - Pikeland Property Group | C32: 103 | D32: 1 | E32: 1 | F32: 1 | H32: 200 | I32: TRUE | J32: text/html; charset=utf-8 | K32: TRUE
A33: https://www.pikelandpropertygroup.com/blog/faq-items/how-are-you-different-from-a-real-estate-agent/ | B33: How are you different from a real estate agent? - Pikeland Property Group | C33: 73 | D33: 1 | E33: 1 | F33: 1 | H33: 200 | I33: TRUE | J33: text/html; charset=utf-8 | K33: TRUE
A34: https://www.pikelandpropertygroup.com/blog/faq-items/learn-about-our-process-and-sell-your-house-today/ | B34: Learn About Our Process and Sell Your House Today! - Pikeland Property Group | C34: 76 | D34: 1 | E34: 1 | F34: 1 | H34: 200 | I34: TRUE | J34: text/html; charset=utf-8 | K34: TRUE
A35: https://www.pikelandpropertygroup.com/blog/selling-your-home-to-a-direct-buyer-in-pennsylvania-3/ | B35: 6 Advantages of Selling Your Home to a Direct Buyer in Pennsylvania That You Might Not Know About - Pikeland Property Group | C35: 123 | D35: 1 | E35: 1 | F35: 1 | H35: 200 | I35: TRUE | J35: text/html; charset=utf-8 | K35: TRUE
A36: https://www.pikelandpropertygroup.com/blog/design-elements-that-can-make-it-difficult-to-sell-your-house-pennsylvania/ | B36: Dated Design Elements That Can make it Difficult to Sell Your House in Pennsylvania - Pikeland Property Group | C36: 109 | D36: 1 | E36: 1 | F36: 1 | H36: 200 | I36: TRUE | J36: text/html; charset=utf-8 | K36: TRUE
A37: https://www.pikelandpropertygroup.com/blog/selling-mobile-homes-pennsylvania/ | B37: Maximizing ROI: How to Make the Most Profit from Buying and Selling Mobile Homes in Pennsylvania - Pikeland Property Group | C37: 122 | D37: 1 | E37: 1 | F37: 1 | H37: 200 | I37: TRUE | J37: text/html; charset=utf-8 | K37: TRUE
A38: https://www.pikelandpropertygroup.com/blog/buying-and-selling-mobile-homes-pennsylvania/ | B38: Maximizing Profits: Tips for Buying and Selling Mobile Homes in Pennsylvania - Pikeland Property Group | C38: 102 | D38: 1 | E38: 1 | F38: 1 | H38: 200 | I38: TRUE | J38: text/html; charset=utf-8 | K38: TRUE
... A90: https://www.pikelandpropertygroup.com/blog/page/3/ | B90: Blog - Pikeland Property Group | C90: 30 | D90: 1 | E90: 1 | F90: 3 | H90: 200 | I90: FALSE | J90: text/html; charset=utf-8 | K90: TRUE
A91: https://www.pikelandpropertygroup.com/blog/faq_category/general/ | D91: 0 | H91: 404 | I91: FALSE | J91: text/html; charset=utf-8 | K91: FALSE
A92: https://www.pikelandpropertygroup.com/blog/fusion_tb_category/header/ | D92: 0 | H92: 301 | I92: FALSE | J92: text/html; charset=utf-8 | K92: FALSE
A93: https://www.pikelandpropertygroup.com/blog/fusion_tb_category/content/ | D93: 0 | H93: 301 | I93: FALSE | J93: text/html; charset=utf-8 | K93: FALSE
A94: https://www.pikelandpropertygroup.com/blog/element_category/elements/ | D94: 0 | H94: 301 | I94: FALSE | J94: text/html; charset=utf-8 | K94: FALSE
A95: https://www.pikelandpropertygroup.com/blog/page/4/ | B95: Blog - Pikeland Property Group | C95: 30 | D95: 1 | H95: 200 | I95: FALSE | J95: text/html; charset=utf-8 | K95: TRUE
A96: https://www.pikelandpropertygroup.com/blog/fusion_tb_category/page_title_bar/ | D96: 0 | H96: 301 | I96: FALSE | J96: text/html; charset=utf-8 | K96: FALSE
A97: https://www.pikelandpropertygroup.com/wp-content/uploads/2023/07/How-To-Stop-Foreclosure-Guide.pdf | D97: 0 | H97: 200 | I97: FALSE | J97: application/pdf | K97: FALSE
A98: https://www.pikelandpropertygroup.com/blog/element_category/sections/ | D98: 0 | H98: 301 | I98: FALSE | J98: text/html; charset=utf-8 | K98: FALSE
A99: https://www.pikelandpropertygroup.com/blog/faq_category/how-we-buy-houses/ | D99: 0 | H99: 301 | I99: FALSE | J99: text/html; charset=utf-8 | K99: FALSE
A100: https://www.pikelandpropertygroup.com/blog/faq_category/home/ | D100: 0 | H100: 404 | I100: FALSE | J100: text/html; charset=utf-8 | K100: FALSE
A101: https://www.pikelandpropertygroup.com/blog/element_category/post_cards/ | D101: 0 | H101: 301 | I101: FALSE | J101: text/html; charset=utf-8 | K101: FALSE
A102: http://www.pikelandpropertygroup.com/ | D102: 0 | H102: 301 | I102: FALSE | J102: text/html | K102: FALSE
...

Sheet suffixes
A1: URL | B1: Title | C1: Title length | D1: No. of titles | E1: No. of groups having the same title | F1: No. of pages having the same title | G1: Is page title used in SERP | H1: HTTP status code | I1: Is indexable page | J1: Content type | K1: Is rendered page | L1: Suffixes
A2: https://www.pikelandpropertygroup.com/ | B2: Pikeland Property Group - Sell My House Fast - We Buy Houses for Cash | C2: 69 | D2: 1 | E2: 2 | F2: 3 | H2: 200 | I2: TRUE | J2: text/html; charset=utf-8 | K2: TRUE | L2: =IFERROR(__xludf.DUMMYFUNCTION("IFNA(REGEXEXTRACT(B2,""[\-|–][^–|\-]+$""))"),"- We Buy Houses for Cash") -> - We Buy Houses for Cash
A3: https://www.pikelandpropertygroup.com/privacy-policy/ | B3: Privacy Policy - Pikeland Property Group | C3: 40 | D3: 1 | E3: 1 | F3: 1 | H3: 200 | I3: TRUE | J3: text/html; charset=utf-8 | K3: TRUE | L3: =IFERROR(__xludf.DUMMYFUNCTION("IFNA(REGEXEXTRACT(B3,""[\-|–][^–|\-]+$""))"),"- Pikeland Property Group") -> - Pikeland Property Group
A4: https://www.pikelandpropertygroup.com/faq/ | B4: FAQ - Pikeland Property Group | C4: 29 | D4: 1 | E4: 1 | F4: 1 | H4: 200 | I4: TRUE | J4: text/html; charset=utf-8 | K4: TRUE | L4: =IFERROR(__xludf.DUMMYFUNCTION("IFNA(REGEXEXTRACT(B4,""[\-|–][^–|\-]+$""))"),"- Pikeland Property Group") -> - Pikeland Property Group
A5: https://www.pikelandpropertygroup.com/how-we-buy-houses/ | B5: How It Works - Pikeland Property Group | C5: 38 | D5: 1 | E5: 1 | F5: 1 | H5: 200 | I5: TRUE | J5: text/html; charset=utf-8 | K5: TRUE | L5: =IFERROR(__xludf.DUMMYFUNCTION("IFNA(REGEXEXTRACT(B5,""[\-|–][^–|\-]+$""))"),"- Pikeland Property Group") -> - Pikeland Property Group
A6: https://www.pikelandpropertygroup.com/contact-us/ | B6: Contact Us - Pikeland Property Group | C6: 36 | D6: 1 | E6: 1 | F6: 1 | H6: 200 | I6: TRUE | J6: text/html; charset=utf-8 | K6: TRUE | L6: =IFERROR(__xludf.DUMMYFUNCTION("IFNA(REGEXEXTRACT(B6,""[\-|–][^–|\-]+$""))"),"- Pikeland Property Group") -> - Pikeland Property Group
A7: https://www.pikelandpropertygroup.com/reviews/ | B7: Reviews - Pikeland Property Group | C7: 33 | D7: 1 | E7: 1 | F7: 1 | H7: 200 | I7: TRUE | J7: text/html; charset=utf-8 | K7: TRUE | L7: =IFERROR(__xludf.DUMMYFUNCTION("IFNA(REGEXEXTRACT(B7,""[\-|–][^–|\-]+$""))"),"- Pikeland Property Group") -> - Pikeland Property Group
A8: https://www.pikelandpropertygroup.com/our-company/ | B8: About Us - Pikeland Property Group | C8: 34 | D8: 1 | E8: 1 | F8: 1 | H8: 200 | I8: TRUE | J8: text/html; charset=utf-8 | K8: TRUE | L8: =IFERROR(__xludf.DUMMYFUNCTION("IFNA(REGEXEXTRACT(B8,""[\-|–][^–|\-]+$""))"),"- Pikeland Property Group") -> - Pikeland Property Group
A9: https://www.pikelandpropertygroup.com/get-your-offer/ | B9: Get Your Offer - Pikeland Property Group | C9: 40 | D9: 1 | E9: 1 | F9: 1 | H9: 200 | I9: TRUE | J9: text/html; charset=utf-8 | K9: TRUE | L9: =IFERROR(__xludf.DUMMYFUNCTION("IFNA(REGEXEXTRACT(B9,""[\-|–][^–|\-]+$""))"),"- Pikeland Property Group") -> - Pikeland Property Group
A10: https://www.pikelandpropertygroup.com/blog/category/sellers/ | B10: sellers Archives - Pikeland Property Group | C10: 42 | D10: 1 | E10: 1 | F10: 1 | H10: 200 | I10: TRUE | J10: text/html; charset=utf-8 | K10: TRUE | L10: =IFERROR(__xludf.DUMMYFUNCTION("IFNA(REGEXEXTRACT(B10,""[\-|–][^–|\-]+$""))"),"- Pikeland Property Group") -> - Pikeland Property Group
A11: https://www.pikelandpropertygroup.com/blog/author/harrisonpikelandpropertygroup-com/ | B11: Harrison Hall, Author at Pikeland Property Group | C11: 48 | D11: 1 | E11: 1 | F11: 1 | H11: 200 | I11: TRUE | J11: text/html; charset=utf-8 | K11: TRUE | L11: =IFERROR(__xludf.DUMMYFUNCTION("IFNA(REGEXEXTRACT(B11,""[\-|–][^–|\-]+$""))"),"")
A12: https://www.pikelandpropertygroup.com/blog/category/building-credibility/ | B12: building-credibility Archives - Pikeland Property Group | C12: 55 | D12: 1 | E12: 1 | F12: 1 | H12: 200 | I12: TRUE | J12: text/html; charset=utf-8 | K12: TRUE | L12: =IFERROR(__xludf.DUMMYFUNCTION("IFNA(REGEXEXTRACT(B12,""[\-|–][^–|\-]+$""))"),"- Pikeland Property Group") -> - Pikeland Property Group
A13: https://www.pikelandpropertygroup.com/blog/category/buying-mobile-homes/ | B13: buying-mobile-homes Archives - Pikeland Property Group | C13: 54 | D13: 1 | E13: 1 | F13: 1 | H13: 200 | I13: TRUE | J13: text/html; charset=utf-8 | K13: TRUE | L13: =IFERROR(__xludf.DUMMYFUNCTION("IFNA(REGEXEXTRACT(B13,""[\-|–][^–|\-]+$""))"),"- Pikeland Property Group") -> - Pikeland Property Group
A14: https://www.pikelandpropertygroup.com/blog/category/uncategorized/ | B14: Uncategorized Archives - Pikeland Property Group | C14: 48 | D14: 1 | E14: 1 | F14: 1 | H14: 200 | I14: TRUE | J14: text/html; charset=utf-8 | K14: TRUE | L14: =IFERROR(__xludf.DUMMYFUNCTION("IFNA(REGEXEXTRACT(B14,""[\-|–][^–|\-]+$""))"),"- Pikeland Property Group") -> - Pikeland Property Group
A15: https://www.pikelandpropertygroup.com/blog/category/selling-mobile-homes/ | B15: selling-mobile-homes Archives - Pikeland Property Group | C15: 55 | D15: 1 | E15: 1 | F15: 1 | H15: 200 | I15: TRUE | J15: text/html; charset=utf-8 | K15: TRUE | L15: =IFERROR(__xludf.DUMMYFUNCTION("IFNA(REGEXEXTRACT(B15,""[\-|–][^–|\-]+$""))"),"- Pikeland Property Group") -> - Pikeland Property Group
A16: https://www.pikelandpropertygroup.com/get-a-cash-offer-today/ | B16: Sell My House Fast Philadelphia - We Buy Houses for Cash - Pikeland Property Group | C16: 82 | D16: 1 | E16: 2 | F16: 2 | H16: 200 | I16: TRUE | J16: text/html; charset=utf-8 | K16: TRUE | L16: =IFERROR(__xludf.DUMMYFUNCTION("IFNA(REGEXEXTRACT(B16,""[\-|–][^–|\-]+$""))"),"- Pikeland Property Group") -> - Pikeland Property Group
A17: https://www.pikelandpropertygroup.com/blog/author/tommy/ | B17: Tommy, Author at Pikeland Property Group | C17: 40 | D17: 1 | E17: 1 | F17: 1 | H17: 200 | I17: FALSE | J17: text/html; charset=utf-8 | K17: TRUE | L17: =IFERROR(__xludf.DUMMYFUNCTION("IFNA(REGEXEXTRACT(B17,""[\-|–][^–|\-]+$""))"),"")
A18: https://www.pikelandpropertygroup.com/blog/2024/05/ | B18: May 2024 - Pikeland Property Group | C18: 34 | D18: 1 | E18: 1 | F18: 1 | H18: 200 | I18: FALSE | J18: text/html; charset=utf-8 | K18: TRUE | L18: =IFERROR(__xludf.DUMMYFUNCTION("IFNA(REGEXEXTRACT(B18,""[\-|–][^–|\-]+$""))"),"- Pikeland Property Group") -> - Pikeland Property Group
A19: https://www.pikelandpropertygroup.com/blog/2023/10/ | B19: October 2023 - Pikeland Property Group | C19: 38 | D19: 1 | E19: 1 | F19: 1 | H19: 200 | I19: FALSE | J19: text/html; charset=utf-8 | K19: TRUE | L19: =IFERROR(__xludf.DUMMYFUNCTION("IFNA(REGEXEXTRACT(B19,""[\-|–][^–|\-]+$""))"),"- Pikeland Property Group") -> - Pikeland Property Group
A20: https://www.pikelandpropertygroup.com/blog/2024/04/ | B20: April 2024 - Pikeland Property Group | C20: 36 | D20: 1 | E20: 1 | F20: 1 | H20: 200 | I20: FALSE | J20: text/html; charset=utf-8 | K20: TRUE | L20: =IFERROR(__xludf.DUMMYFUNCTION("IFNA(REGEXEXTRACT(B20,""[\-|–][^–|\-]+$""))"),"- Pikeland Property Group") -> - Pikeland Property Group
A21: https://www.pikelandpropertygroup.com/blog/2024/01/ | B21: January 2024 - Pikeland Property Group | C21: 38 | D21: 1 | E21: 1 | F21: 1 | H21: 200 | I21: FALSE | J21: text/html; charset=utf-8 | K21: TRUE | L21: =IFERROR(__xludf.DUMMYFUNCTION("IFNA(REGEXEXTRACT(B21,""[\-|–][^–|\-]+$""))"),"- Pikeland Property Group") -> - Pikeland Property Group
A22: https://www.pikelandpropertygroup.com/blog/2024/03/ | B22: March 2024 - Pikeland Property Group | C22: 36 | D22: 1 | E22: 1 | F22: 1 | H22: 200 | I22: FALSE | J22: text/html; charset=utf-8 | K22: TRUE | L22: =IFERROR(__xludf.DUMMYFUNCTION("IFNA(REGEXEXTRACT(B22,""[\-|–][^–|\-]+$""))"),"- Pikeland Property Group") -> - Pikeland Property Group
A23: https://www.pikelandpropertygroup.com/blog/2023/09/ | B23: September 2023 - Pikeland Property Group | C23: 40 | D23: 1 | E23: 1 | F23: 1 | H23: 200 | I23: FALSE | J23: text/html; charset=utf-8 | K23: TRUE | L23: =IFERROR(__xludf.DUMMYFUNCTION("IFNA(REGEXEXTRACT(B23,""[\-|–][^–|\-]+$""))"),"- Pikeland Property Group") -> - Pikeland Property Group
A24: https://www.pikelandpropertygroup.com/blog/2024/02/ | B24: February 2024 - Pikeland Property Group | C24: 39 | D24: 1 | E24: 1 | F24: 1 | H24: 200 | I24: FALSE | J24: text/html; charset=utf-8 | K24: TRUE | L24: =IFERROR(__xludf.DUMMYFUNCTION("IFNA(REGEXEXTRACT(B24,""[\-|–][^–|\-]+$""))"),"- Pikeland Property Group") -> - Pikeland Property Group
A25: https://www.pikelandpropertygroup.com/blog/2023/08/ | B25: August 2023 - Pikeland Property Group | C25: 37 | D25: 1 | E25: 1 | F25: 1 | H25: 200 | I25: FALSE | J25: text/html; charset=utf-8 | K25: TRUE | L25: =IFERROR(__xludf.DUMMYFUNCTION("IFNA(REGEXEXTRACT(B25,""[\-|–][^–|\-]+$""))"),"- Pikeland Property Group") -> - Pikeland Property Group
A26: https://www.pikelandpropertygroup.com/stop-foreclosure/ | D26: 0 | H26: 404 | I26: FALSE | J26: text/html; charset=utf-8 | K26: FALSE | L26: =IFERROR(__xludf.DUMMYFUNCTION("IFNA(REGEXEXTRACT(B26,""[\-|–][^–|\-]+$""))"),"")
A27: https://www.pikelandpropertygroup.com/blog/faq-items/what-if-i-dont-need-a-fast-closing/ | B27: What if I don’t need a fast closing? - Pikeland Property Group | C27: 62 | D27: 1 | E27: 1 | F27: 1 | H27: 200 | I27: TRUE | J27: text/html; charset=utf-8 | K27: TRUE | L27: =IFERROR(__xludf.DUMMYFUNCTION("IFNA(REGEXEXTRACT(B27,""[\-|–][^–|\-]+$""))"),"- Pikeland Property Group") -> - Pikeland Property Group
A28: https://www.pikelandpropertygroup.com/blog/selling-a-property-that-needs-repairs-in-pennsylvania/ | B28: 6 Things You Need to Know About Selling a Property That Needs Repairs in Pennsylvania - Pikeland Property Group | C28: 111 | D28: 1 | E28: 1 | F28: 1 | H28: 200 | I28: TRUE | J28: text/html; charset=utf-8 | K28: TRUE | L28: =IFERROR(__xludf.DUMMYFUNCTION("IFNA(REGEXEXTRACT(B28,""[\-|–][^–|\-]+$""))"),"- Pikeland Property Group") -> - Pikeland Property Group
A29: https://www.pikelandpropertygroup.com/blog/selling-your-home-to-a-direct-buyer-pennsylvania/ | B29: 5 Mistakes to Avoid When Selling Your Home to a Direct Buyer in Pennsylvania - Pikeland Property Group | C29: 102 | D29: 1 | E29: 1 | F29: 1 | H29: 200 | I29: TRUE | J29: text/html; charset=utf-8 | K29: TRUE | L29: =IFERROR(__xludf.DUMMYFUNCTION("IFNA(REGEXEXTRACT(B29,""[\-|–][^–|\-]+$""))"),"- Pikeland Property Group") -> - Pikeland Property Group
A30: https://www.pikelandpropertygroup.com/blog/faq-items/what-are-the-benefits-of-selling-my-house-in-pennsylvania-to-a-cash-home-buyer/ | B30: What Are the Benefits of Selling My House in Pennsylvania To A Cash Home Buyer? - Pikeland Property Group | C30: 105 | D30: 1 | E30: 1 | F30: 1 | H30: 200 | I30: TRUE | J30: text/html; charset=utf-8 | K30: TRUE | L30: =IFERROR(__xludf.DUMMYFUNCTION("IFNA(REGEXEXTRACT(B30,""[\-|–][^–|\-]+$""))"),"- Pikeland Property Group") -> - Pikeland Property Group
A31: https://www.pikelandpropertygroup.com/blog/faq-items/how-fast-is-a-fast-closing/ | B31: How fast is a fast closing? - Pikeland Property Group | C31: 53 | D31: 1 | E31: 1 | F31: 1 | H31: 200 | I31: TRUE | J31: text/html; charset=utf-8 | K31: TRUE | L31: =IFERROR(__xludf.DUMMYFUNCTION("IFNA(REGEXEXTRACT(B31,""[\-|–][^–|\-]+$""))"),"- Pikeland Property Group") -> - Pikeland Property Group
A32: https://www.pikelandpropertygroup.com/blog/low-earning-vacation-rental-in-pennsylvania/ | B32: 5 Solutions to Help You With Your Low-Earning Vacation Rental in Pennsylvania - Pikeland Property Group | C32: 103 | D32: 1 | E32: 1 | F32: 1 | H32: 200 | I32: TRUE | J32: text/html; charset=utf-8 | K32: TRUE | L32: =IFERROR(__xludf.DUMMYFUNCTION("IFNA(REGEXEXTRACT(B32,""[\-|–][^–|\-]+$""))"),"- Pikeland Property Group") -> - Pikeland Property Group
A33: https://www.pikelandpropertygroup.com/blog/faq-items/how-are-you-different-from-a-real-estate-agent/ | B33: How are you different from a real estate agent? - Pikeland Property Group | C33: 73 | D33: 1 | E33: 1 | F33: 1 | H33: 200 | I33: TRUE | J33: text/html; charset=utf-8 | K33: TRUE | L33: =IFERROR(__xludf.DUMMYFUNCTION("IFNA(REGEXEXTRACT(B33,""[\-|–][^–|\-]+$""))"),"- Pikeland Property Group") -> - Pikeland Property Group
A34: https://www.pikelandpropertygroup.com/blog/faq-items/learn-about-our-process-and-sell-your-house-today/ | B34: Learn About Our Process and Sell Your House Today! - Pikeland Property Group | C34: 76 | D34: 1 | E34: 1 | F34: 1 | H34: 200 | I34: TRUE | J34: text/html; charset=utf-8 | K34: TRUE | L34: =IFERROR(__xludf.DUMMYFUNCTION("IFNA(REGEXEXTRACT(B34,""[\-|–][^–|\-]+$""))"),"- Pikeland Property Group") -> - Pikeland Property Group
A35: https://www.pikelandpropertygroup.com/blog/selling-your-home-to-a-direct-buyer-in-pennsylvania-3/ | B35: 6 Advantages of Selling Your Home to a Direct Buyer in Pennsylvania That You Might Not Know About - Pikeland Property Group | C35: 123 | D35: 1 | E35: 1 | F35: 1 | H35: 200 | I35: TRUE | J35: text/html; charset=utf-8 | K35: TRUE | L35: =IFERROR(__xludf.DUMMYFUNCTION("IFNA(REGEXEXTRACT(B35,""[\-|–][^–|\-]+$""))"),"- Pikeland Property Group") -> - Pikeland Property Group
A36: https://www.pikelandpropertygroup.com/blog/design-elements-that-can-make-it-difficult-to-sell-your-house-pennsylvania/ | B36: Dated Design Elements That Can make it Difficult to Sell Your House in Pennsylvania - Pikeland Property Group | C36: 109 | D36: 1 | E36: 1 | F36: 1 | H36: 200 | I36: TRUE | J36: text/html; charset=utf-8 | K36: TRUE | L36: =IFERROR(__xludf.DUMMYFUNCTION("IFNA(REGEXEXTRACT(B36,""[\-|–][^–|\-]+$""))"),"- Pikeland Property Group") -> - Pikeland Property Group
A37: https://www.pikelandpropertygroup.com/blog/selling-mobile-homes-pennsylvania/ | B37: Maximizing ROI: How to Make the Most Profit from Buying and Selling Mobile Homes in Pennsylvania - Pikeland Property Group | C37: 122 | D37: 1 | E37: 1 | F37: 1 | H37: 200 | I37: TRUE | J37: text/html; charset=utf-8 | K37: TRUE | L37: =IFERROR(__xludf.DUMMYFUNCTION("IFNA(REGEXEXTRACT(B37,""[\-|–][^–|\-]+$""))"),"- Pikeland Property Group") -> - Pikeland Property Group
A38: https://www.pikelandpropertygroup.com/blog/buying-and-selling-mobile-homes-pennsylvania/ | B38: Maximizing Profits: Tips for Buying and Selling Mobile Homes in Pennsylvania - Pikeland Property Group | C38: 102 | D38: 1 | E38: 1 | F38: 1 | H38: 200 | I38: TRUE | J38: text/html; charset=utf-8 | K38: TRUE | L38: =IFERROR(__xludf.DUMMYFUNCTION("IFNA(REGEXEXTRACT(B38,""[\-|–][^–|\-]+$""))"),"- Pikeland Property Group") -> - Pikeland Property Group
A39: https://www.pikelandpropertygroup.com/blog/buying-and-selling-ranches-and-horse-properties-in-pennsylvania/ | B39: 5 Important Things You Need to Know About Buying and Selling Ranches and Horse Properties in Pennsylvania - Pikeland Property Group | C39: 131 | D39: 1 | E39: 1 | F39: 1 | H39: 200 | I39: TRUE | J39: text/html; charset=utf-8 | K39: TRUE | L39: =IFERROR(__xludf.DUMMYFUNCTION("IFNA(REGEXEXTRACT(B39,""[\-|–][^–|\-]+$""))"),"- Pikeland Property Group") -> - Pikeland Property Group
A40: https://www.pikelandpropertygroup.com/blog/sell-their-house-directly-in-pennsylvania/ | B40: 5 of the Top Reasons Homeowners Opt to Sell Their House Directly in Pennsylvania - Pikeland Property Group | C40: 106 | D40: 1 | E40: 1 | F40: 1 | H40: 200 | I40: TRUE | J40: text/html; charset=utf-8 | K40: TRUE | L40: =IFERROR(__xludf.DUMMYFUNCTION("IFNA(REGEXEXTRACT(B40,""[\-|–][^–|\-]+$""))"),"- Pikeland Property Group") -> - Pikeland Property Group
...

Sheet Sheet2
A1: FALSE
A2: FALSE
A3: FALSE
A4: FALSE
A5: FALSE
A6: FALSE
A7: FALSE
A8: FALSE
A9: FALSE
A10: FALSE
A11: FALSE
A12: FALSE
... A270: FALSE

Sheet Unique suffix
B1: Count
A2: {=UNIQUE(suffixes!L2:L107)} -> - We Buy Houses for Cash | B2: =COUNTIF(suffixes!L2:L107,"="&A2) -> 3
A3: - Pikeland Property Group | B3: =COUNTIF(suffixes!L3:L108,"="&A3) -> 84
B4: =COUNTIF(suffixes!L4:L109,"="&A4) -> 20
A5: - Page 2 of 2 | B5: =COUNTIF(suffixes!L5:L110,"="&A5) -> 1
